Workbook

Sheet Data
B2: Database
D4: Categories | AA4: Stock performance | AK4: Earnings | CT4: P/E | EP4: Calendarization
AK6: 2 | AL6: > Input 1 for GAAP earnings, 2 for Adjusted earnings | ES6: GAAP | FS6: Adjusted
F8: Categories | P8: Subcategories | AK8: IS_COMP_NET_INCOME_GAAP | AZ8: IS_COMP_NET_INCOME_ADJUST | BO8: Calendarized | BZ8: Earnings growth ($) | CD8: Earnings growth (%) | CH8: Consensus revisions (%) | CN8: Consensus revisions ($) | ES8: Fiscal | FH8: Calendar | FS8: Fiscal | GH8: Calendar
F9: =COUNTIFS(F11:F510,"yes") -> 6 | G9: =COUNTIFS(G11:G510,"yes") -> 48 | H9: =COUNTIFS(H11:H510,"yes") -> 7 | I9: =COUNTIFS(I11:I510,"yes") -> 11 | AA9: Market cap ($b) | AE9: $Δ Mkt cap | AH9: Stock returns | AK9: 2024 | AL9: 2025 | AN9: 2026 | AO9: 2026 | AP9: 2026 | AR9: 2027 | AS9: 2027 | AT9: 2027 | AV9: 2028 | AW9: 2028 | AX9: 2028 | AZ9: 2024 | BA9: 2025 | BC9: 2026 | BD9: 2026 | BE9: 2026 | BG9: 2027 | BH9: 2027 | BI9: 2027 | BK9: 2028 | BL9: 2028 | BM9: 2028 | BO9: 2024 | BP9: 2025 | BR9: 2026 | BS9: 2026 | BT9: 2026 | BV9: 2027 | BW9: 2027 | BX9: 2027 | BZ9: 2025 | CA9: =BZ9+1 -> 2026 | CB9: =CA9+1 -> 2027 | CD9: 2025 | CE9: =CD9+1 -> 2026 | CF9: =CE9+1 -> 2027 | CH9: =BS9 -> 2026 | CI9: =BT9 -> 2026 | CK9: =BW9 -> 2027 | CL9: =BX9 -> 2027 | CN9: =BS9 -> 2026 | CO9: =BT9 -> 2026 | CQ9: =BW9 -> 2027 | CR9: =BX9 -> 2027 | CT9: NTM net income estimates | DR9: Market cap | ES9: 2024 | ET9: 2025 | EX9: 2026 | FB9: 2027 | FF9: 2028 | FH9: 2024 | FI9: 2025 | FM9: 2026 | FQ9: 2027 | FS9: 2024 | FT9: 2025 | FX9: 2026 | GB9: 2027 | GF9: 2028 | GH9: 2024 | GI9: 2025 | GM9: 2026 | GQ9: 2027
B10: Tickers | C10: Name | D10: Is compounder? | F10: AI Buildout Funders | G10: AI Capex Beneficiaries | H10: Infrastructure SW | I10: Application SW | J10: Other | K10: =F10 -> AI Buildout Funders | L10: =G10 -> AI Capex Beneficiaries | M10: =H10 -> Infrastructure SW | N10: =I10 -> Application SW | P10: AI capex - Sub categories | Q10: Digital Semis | R10: Memory | S10: Semicap | T10: Analog/MCU | U10: Power | V10: Electric/Cooling | W10: Hardware/Components | X10: Design | Y10: Construction | AA10: 46023 | AB10: 46112 | AC10: 46171 | AE10: YTD | AF10: QTD | AH10: YTD | AI10: QTD | AN10: =$AA$10 -> 46023 | AO10: =$AB$10 -> 46112 | AP10: =$AC$10 -> 46171 | AR10: =$AA$10 -> 46023 | AS10: =$AB$10 -> 46112 | AT10: =$AC$10 -> 46171 | AV10: =$AA$10 -> 46023 | AW10: =$AB$10 -> 46112 | AX10: =$AC$10 -> 46171 | BC10: =$AA$10 -> 46023 | BD10: =$AB$10 -> 46112 | BE10: =$AC$10 -> 46171 | BG10: =$AA$10 -> 46023 | BH10: =$AB$10 -> 46112 | BI10: =$AC$10 -> 46171 | BK10: =$AA$10 -> 46023 | BL10: =$AB$10 -> 46112 | BM10: =$AC$10 -> 46171 | BO10: Actual | BP10: Actual | BR10: =$AA$10 -> 46023 | BS10: =$AB$10 -> 46112 | BT10: =$AC$10 -> 46171 | BV10: =$AA$10 -> 46023 | BW10: =$AB$10 -> 46112 | BX10: =$AC$10 -> 46171 | BZ10: Actual | CA10: Est. | CB10: Est. | CD10: Actual | CE10: Est. | CF10: Est. | CH10: =$BS$10 -> 46112 | CI10: =$BT$10 -> 46171 | CK10: =$BS$10 -> 46112 | CL10: =$BT$10 -> 46171 | CN10: =$BS$10 -> 46112 | CO10: =$BT$10 -> 46171 | CQ10: =$BS$10 -> 46112 | CR10: =$BT$10 -> 46171 | CT10: =$BT$10 -> 46171 | CU10: 46112 | CV10: 46022 | CW10: 45930 | CX10: 45838 | CY10: 45747 | CZ10: 45657 | DA10: 45565 | DB10: 45473 | DC10: 45382 | DD10: 45291 | DE10: 45199 | DF10: 45107 | DG10: 45016 | DH10: 44926 | DI10: 44834 | DJ10: 44742 | DK10: 44651 | DL10: 44561 | DM10: 44469 | DN10: 44377 | DO10: 44286 | DP10: 44196 | DR10: =$BT$10 -> 46171 | DS10: 46112 | DT10: 46022 | DU10: 45930 | DV10: 45838 | DW10: 45747 | DX10: 45657 | DY10: 45565 | DZ10: 45473 | EA10: 45382 | EB10: 45291 | EC10: 45199 | ED10: 45107 | EE10: 45016 | EF10: 44926 | EG10: 44834 | EH10: 44742 | EI10: 44651 | EJ10: 44561 | EK10: 44469 | EL10: 44377 | EM10: 44286 | EN10: 44196 | EP10: FYE | EQ10: factor | EV10: =$AN$10 -> 46023 | EW10: =$AO$10 -> 46112 | EX10: =$AP$10 -> 46171 | EZ10: =$AN$10 -> 46023 | FA10: =$AO$10 -> 46112 | FB10: =$AP$10 -> 46171 | FD10: =$AN$10 -> 46023 | FE10: =$AO$10 -> 46112 | FF10: =$AP$10 -> 46171 | FK10: =$AN$10 -> 46023 | FL10: =$AO$10 -> 46112 | FM10: =$AP$10 -> 46171 | FO10: =$AN$10 -> 46023 | FP10: =$AO$10 -> 46112 | FQ10: =$AP$10 -> 46171 | FV10: =$AN$10 -> 46023 | FW10: =$AO$10 -> 46112 | FX10: =$AP$10 -> 46171 | FZ10: =$AN$10 -> 46023 | GA10: =$AO$10 -> 46112 | GB10: =$AP$10 -> 46171 | GD10: =$AN$10 -> 46023 | GE10: =$AO$10 -> 46112 | GF10: =$AP$10 -> 46171 | GK10: =$AN$10 -> 46023 | GL10: =$AO$10 -> 46112 | GM10: =$AP$10 -> 46171 | GO10: =$AN$10 -> 46023 | GP10: =$AO$10 -> 46112 | GQ10: =$AP$10 -> 46171
B11: NVDA US Equity | C11: Nvidia Corp | D11: =IFERROR(IF(MATCH($B11,Compounders!$A:$A,0),"yes"),"") -> yes | G11: yes | J11: =IF(AND(F11="",G11="",H11="",I11=""),"yes","") | K11: 0 | L11: 1 | M11: 0 | N11: 0 | P11: Digital Semis | Q11: 1 | R11: 0 | S11: 0 | T11: 0 | U11: 0 | V11: 0 | W11: 0 | X11: 0 | Y11: 0 | AA11: 4531.95 | AB11: 4237.92 | AC11: {=_xll.BQL(_xll.BQL.LIST($B11:$B510), "cur_mkt_cap(dates=" & _xll.BQL.DATE(AC$10) & ", currency=USD)/1E9", "fill=prev", "showids=f","showheaders=f")} -> 5109.588 | AE11: =$AC11-AA11 -> 577.638 | AF11: =$AC11-AB11 -> 871.668 | AH11: =$AC11/AA11-1 -> 0.12745904 | AI11: =$AC11/AB11-1 -> 0.20568298 | AK11: 29759 | AL11: {=_xll.BQL(_xll.BQL.LIST($B$11:$B$510),$AK$8&"(FPT=A, FPR="&AL$9&")","currency=USD","mode=cached","showids=f","showheaders=f")/10^6} -> 72880 | AN11: 113509.76 | AO11: 120067 | AP11: {=_xll.BQL(_xll.BQL.LIST($B$11:$B$510),$AK$8&"(FPT=A, FPR="&AP$9&")","dates="&_xll.BQL.DATE(AP$10),"currency=USD","mode=cached","showids=f","showheaders=f")/10^6} -> 120067 | AR11: 177521.81 | AS11: 202198.49 | AT11: {=_xll.BQL(_xll.BQL.LIST($B$11:$B$510),$AK$8&"(FPT=A, FPR="&AT$9&")","dates="&_xll.BQL.DATE(AT$10),"currency=USD","mode=cached","showids=f","showheaders=f")/10^6} -> 222791.14 | AV11: 224130.51 | AW11: 268488.89 | AX11: {=_xll.BQL(_xll.BQL.LIST($B$11:$B$510),$AK$8&"(FPT=A, FPR="&AX$9&")","dates="&_xll.BQL.DATE(AX$10),"currency=USD","mode=cached","showids=f","showheaders=f")/10^6} -> 303130.51 | AZ11: 32312 | BA11: {=_xll.BQL(_xll.BQL.LIST($B$11:$B$510),$AZ$8&"(FPT=A, FPR="&BA$9&")","currency=USD","mode=cached","showids=f","showheaders=f")/10^6} -> 74265 | BC11: 114796.15 | BD11: 116997 | BE11: {=_xll.BQL(_xll.BQL.LIST($B$11:$B$510),$AZ$8&"(FPT=A, FPR="&BE$9&")","dates="&_xll.BQL.DATE(BE$10),"currency=USD","mode=cached","showids=f","showheaders=f")/10^6} -> 116997 | BG11: 187965.84 | BH11: 202258.14 | BI11: {=_xll.BQL(_xll.BQL.LIST($B$11:$B$510),$AZ$8&"(FPT=A, FPR="&BI$9&")","dates="&_xll.BQL.DATE(BI$10),"currency=USD","mode=cached","showids=f","showheaders=f")/10^6} -> 216781.38 | BK11: 237197.7 | BL11: 267168.51 | BM11: {=_xll.BQL(_xll.BQL.LIST($B$11:$B$510),$AZ$8&"(FPT=A, FPR="&BM$9&")","dates="&_xll.BQL.DATE(BM$10),"currency=USD","mode=cached","showids=f","showheaders=f")/10^6} -> 306303.89 | BO11: =CHOOSE($AK$6,FH11,GH11) -> 71391.507 | BP11: =CHOOSE($AK$6,FI11,GI11) -> 114070.15 | BR11: =CHOOSE($AK$6,FK11,GK11) -> 182954.22 | BS11: =CHOOSE($AK$6,FL11,GL11) -> 196418.33 | BT11: =CHOOSE($AK$6,FM11,GM11) -> 209946.84 | BV11: =CHOOSE($AK$6,FO11,GO11) -> 233825.65 | BW11: =CHOOSE($AK$6,FP11,GP11) -> 262722.59 | BX11: =CHOOSE($AK$6,FQ11,GQ11) -> 300172.22 | BZ11: =BP11-BO11 -> 42678.644 | CA11: =BT11-BP11 -> 95876.686 | CB11: =BX11-BT11 -> 90225.379 | CD11: =BP11/BO11-1 -> 0.59781122 | CE11: =BT11/BP11-1 -> 0.84050635 | CF11: =BX11/BT11-1 -> 0.42975346 | CH11: =IFERROR(BS11/$BR11-1,"") -> 0.07359282 | CI11: =IFERROR(BT11/$BR11-1,"") -> 0.14753757 | CK11: =IFERROR(BW11/$BV11-1,"") -> 0.12358328 | CL11: =IFERROR(BX11/$BV11-1,"") -> 0.28374373 | CN11: =IFERROR(BS11-$BR11,"") -> 13464.117 | CO11: =IFERROR(BT11-$BR11,"") -> 26992.62 | CQ11: =IFERROR(BW11-$BV11,"") -> 28896.942 | CR11: =IFERROR(BX11-$BV11,"") -> 66346.563 | CT11: {=IFERROR(_xll.BQL(_xll.BQL.LIST($B$11:$B$510),"IS_COMP_NET_INCOME_ADJUST(FPT=LTM, FPO=1, AE=E)","dates="&_xll.BQL.DATE(CT$10),"currency=USD","mode=cached","fill=prev","showids=f","showheaders=f")/10^6,"")} -> 239615.35 | CU11: 202258.14 | CV11: 171315.54 | CW11: 145847.73 | CX11: 119341.18 | CY11: 111470.72 | CZ11: 97583.61 | DA11: 84441.126 | DB11: 72293.671 | DC11: 60934.569 | DD11: 48496.455 | DE11: 36446.689 | DF11: 21862.547 | DG11: 10957.571 | DH11: 9559.757 | DI11: 8610.0602 | DJ11: 13845.21 | DK11: 14464.677 | DL11: 12619.391 | DM11: 10989.674 | DN11: 10233.92 | DO11: 8427.3793 | DP11: 7063.2737 | DR11: =AC11 -> 5109.588 | DS11: 4237.92 | DT11: 4531.95 | DU11: 4533.894 | DV11: 3854.956 | DW11: 2644.472 | DX11: 3288.7621 | DY11: 2978.9232 | DZ11: 3039.084 | EA11: 2258.9 | EB11: 1223.1934 | EC11: 1074.4253 | ED11: 1044.8594 | EE11: 686.0919 | EF11: 359.5044 | EG11: 302.2611 | EH11: 378.975 | EI11: 684.8786 | EJ11: 735.275 | EK11: 517.9 | EL11: 498.4623 | EM11: 331.0366 | EN11: 323.2418 | EP11: 46047 | EQ11: =(DATE(2025,12,31)-EP11)/365 -> -0.068493151 | ES11: =AK11 -> 29759 | ET11: =AL11 -> 72880 | EV11: =AN11 -> 113509.76 | EW11: =AO11 -> 120067 | EX11: =AP11 -> 120067 | EZ11: =AR11 -> 177521.81 | FA11: =AS11 -> 202198.49 | FB11: =AT11 -> 222791.14 | FD11: =AV11 -> 224130.51 | FE11: =AW11 -> 268488.89 | FF11: =AX11 -> 303130.51 | FH11: =IFERROR(IF($EQ11<0,ES11*-$EQ11+ET11*(1+$EQ11),ES11*(1-$EQ11)+ET11*$EQ11),"") -> 69926.507 | FI11: =IFERROR(IF($EQ11<0,ET11*-$EQ11+EX11*(1+$EQ11),ET11*(1-$EQ11)+EX11*$EQ11),"") -> 116835.01 | FK11: =IFERROR(IF($EQ11<0,EV11*-$EQ11+EZ11*(1+$EQ11),EV11*(1-$EQ11)+EZ11*$EQ11),"") -> 173137.43 | FL11: =IFERROR(IF($EQ11<0,EW11*-$EQ11+FA11*(1+$EQ11),EW11*(1-$EQ11)+FA11*$EQ11),"") -> 196573.04 | FM11: =IFERROR(IF($EQ11<0,EX11*-$EQ11+FB11*(1+$EQ11),EX11*(1-$EQ11)+FB11*$EQ11),"") -> 215755.24 | FO11: =IFERROR(IF($EQ11<0,EZ11*-$EQ11+FD11*(1+$EQ11),EZ11*(1-$EQ11)+FD11*$EQ11),"") -> 220938.14 | FP11: =IFERROR(IF($EQ11<0,FA11*-$EQ11+FE11*(1+$EQ11),FA11*(1-$EQ11)+FE11*$EQ11),"") -> 263948.45 | FQ11: =IFERROR(IF($EQ11<0,FB11*-$EQ11+FF11*(1+$EQ11),FB11*(1-$EQ11)+FF11*$EQ11),"") -> 297627.81 | FS11: =AZ11 -> 32312 | FT11: =BA11 -> 74265 | FV11: =BC11 -> 114796.15 | FW11: =BD11 -> 116997 | FX11: =BE11 -> 116997 | FZ11: =BG11 -> 187965.84 | GA11: =BH11 -> 202258.14 | GB11: =BI11 -> 216781.38 | GD11: =BK11 -> 237197.7 | GE11: =BL11 -> 267168.51 | GF11: =BM11 -> 306303.89 | GH11: =IFERROR(IF($EQ11<0,FS11*-$EQ11+FT11*(1+$EQ11),FS11*(1-$EQ11)+FT11*$EQ11),"") -> 71391.507 | GI11: =IFERROR(IF($EQ11<0,FT11*-$EQ11+FX11*(1+$EQ11),FT11*(1-$EQ11)+FX11*$EQ11),"") -> 114070.15 | GK11: =IFERROR(IF($EQ11<0,FV11*-$EQ11+FZ11*(1+$EQ11),FV11*(1-$EQ11)+FZ11*$EQ11),"") -> 182954.22 | GL11: =IFERROR(IF($EQ11<0,FW11*-$EQ11+GA11*(1+$EQ11),FW11*(1-$EQ11)+GA11*$EQ11),"") -> 196418.33 | GM11: =IFERROR(IF($EQ11<0,FX11*-$EQ11+GB11*(1+$EQ11),FX11*(1-$EQ11)+GB11*$EQ11),"") -> 209946.84 | GO11: =IFERROR(IF($EQ11<0,FZ11*-$EQ11+GD11*(1+$EQ11),FZ11*(1-$EQ11)+GD11*$EQ11),"") -> 233825.65 | GP11: =IFERROR(IF($EQ11<0,GA11*-$EQ11+GE11*(1+$EQ11),GA11*(1-$EQ11)+GE11*$EQ11),"") -> 262722.59 | GQ11: =IFERROR(IF($EQ11<0,GB11*-$EQ11+GF11*(1+$EQ11),GB11*(1-$EQ11)+GF11*$EQ11),"") -> 300172.22
B12: AAPL US Equity | C12: Apple Inc | D12: =IFERROR(IF(MATCH($B12,Compounders!$A:$A,0),"yes"),"") -> yes | J12: =IF(AND(F12="",G12="",H12="",I12=""),"yes","") -> yes | K12: =K11+IF(F12="yes",1) -> 0 | L12: =L11+IF(G12="yes",1) -> 1 | M12: =M11+IF(H12="yes",1) -> 0 | N12: =N11+IF(I12="yes",1) -> 0 | Q12: =Q11+IF(Q$10=$P12,1) -> 1 | R12: =R11+IF(R$10=$P12,1) -> 0 | S12: =S11+IF(S$10=$P12,1) -> 0 | T12: =T11+IF(T$10=$P12,1) -> 0 | U12: =U11+IF(U$10=$P12,1) -> 0 | V12: =V11+IF(V$10=$P12,1) -> 0 | W12: =W11+IF(W$10=$P12,1) -> 0 | X12: =X11+IF(X$10=$P12,1) -> 0 | Y12: =Y11+IF(Y$10=$P12,1) -> 0 | AA12: 4017.0993 | AB12: 3725.9265 | AC12: 4583.3363 | AE12: =$AC12-AA12 -> 566.23699 | AF12: =$AC12-AB12 -> 857.40979 | AH12: =$AC12/AA12-1 -> 0.14095668 | AI12: =$AC12/AB12-1 -> 0.23011989 | AK12: 93736 | AL12: 112010 | AN12: 120866.63 | AO12: 124825.95 | AP12: 128442.54 | AR12: 131167.1 | AS12: 134476.1 | AT12: 138910.5 | AV12: 141223.48 | AW12: 143680.41 | AX12: 150837.88 | AZ12: 103982 | BA12: 112010 | BC12: 120866.63 | BD12: 124825.95 | BE12: 128442.54 | BG12: 131167.1 | BH12: 134476.1 | BI12: 138910.5 | BK12: 141223.48 | BL12: 143680.41 | BM12: 150837.88 | BO12: =CHOOSE($AK$6,FH12,GH12) -> 106071.48 | BP12: =CHOOSE($AK$6,FI12,GI12) -> 116286.96 | BR12: =CHOOSE($AK$6,FK12,GK12) -> 123547.58 | BS12: =CHOOSE($AK$6,FL12,GL12) -> 127337.63 | BT12: =CHOOSE($AK$6,FM12,GM12) -> 131167.08 | BV12: =CHOOSE($AK$6,FO12,GO12) -> 133784.51 | BW12: =CHOOSE($AK$6,FP12,GP12) -> 136871.74 | BX12: =CHOOSE($AK$6,FQ12,GQ12) -> 142014.89 | BZ12: =BP12-BO12 -> 10215.483 | CA12: =BT12-BP12 -> 14880.116 | CB12: =BX12-BT12 -> 10847.807 | CD12: =BP12/BO12-1 -> 0.096307542 | CE12: =BT12/BP12-1 -> 0.12796031 | CF12: =BX12/BT12-1 -> 0.082702212 | CH12: =BS12/$BR12-1 -> 0.030676895 | CI12: =BT12/$BR12-1 -> 0.061672609 | CK12: =BW12/$BV12-1 -> 0.023076102 | CL12: =BX12/$BV12-1 -> 0.061519622 | CN12: =IFERROR(BS12-$BR12,"") -> 3790.0561 | CO12: =IFERROR(BT12-$BR12,"") -> 7619.5015 | CQ12: =IFERROR(BW12-$BV12,"") -> 3087.225 | CR12: =IFERROR(BX12-$BV12,"") -> 8230.3727 | CT12: 132848.75 | CU12: 126234.23 | CV12: 120866.63 | CW12: 114929.72 | CX12: 104523.71 | CY12: 111961.42 | CZ12: 110886.21 | DA12: 109999.27 | DB12: 104592.41 | DC12: 102220.56 | DD12: 101365.05 | DE12: 99340.021 | DF12: 96837.006 | DG12: 96340.415 | DH12: 99066.326 | DI12: 99466.621 | DJ12: 99503.352 | DK12: 100700.77 | DL12: 93613.718 | DM12: 91789.6 | DN12: 84592.842 | DO12: 74118.56 | DP12: 66453.844 | DR12: =AC12 -> 4583.3363 | DS12: 3725.9265 | DT12: 4017.0993 | DU12: 3778.8085 | DV12: 3064.3834 | DW12: 3336.8531 | DX12: 3785.3044 | DY12: 3542.5639 | DZ12: 3229.6644 | EA12: 2647.9738 | EB12: 2994.3713 | EC12: 2676.7369 | ED12: 3050.8963 | EE12: 2609.0389 | EF12: 2066.9418 | EG12: 2220.9779 | EH12: 2212.8379 | EI12: 2849.5376 | EJ12: 2913.2839 | EK12: 2339.0185 | EL12: 2285.5379 | EM12: 2050.6659 | EN12: 2255.9691 | EP12: 45927 | EQ12: =(DATE(2025,12,31)-EP12)/365 -> 0.26027397 | ES12: =AK12 -> 93736 | ET12: =AL12 -> 112010 | EV12: =AN12 -> 120866.63 | EW12: =AO12 -> 124825.95 | EX12: =AP12 -> 128442.54 | EZ12: =AR12 -> 131167.1 | FA12: =AS12 -> 134476.1 | FB12: =AT12 -> 138910.5 | FD12: =AV12 -> 141223.48 | FE12: =AW12 -> 143680.41 | FF12: =AX12 -> 150837.88 | FH12: =IFERROR(IF($EQ12<0,ES12*-$EQ12+ET12*(1+$EQ12),ES12*(1-$EQ12)+ET12*$EQ12),"") -> 98492.247 | FI12: =IFERROR(IF($EQ12<0,ET12*-$EQ12+EX12*(1+$EQ12),ET12*(1-$EQ12)+EX12*$EQ12),"") -> 116286.96 | FK12: =IFERROR(IF($EQ12<0,EV12*-$EQ12+EZ12*(1+$EQ12),EV12*(1-$EQ12)+EZ12*$EQ12),"") -> 123547.58 | FL12: =IFERROR(IF($EQ12<0,EW12*-$EQ12+FA12*(1+$EQ12),EW12*(1-$EQ12)+FA12*$EQ12),"") -> 127337.63 | FM12: =IFERROR(IF($EQ12<0,EX12*-$EQ12+FB12*(1+$EQ12),EX12*(1-$EQ12)+FB12*$EQ12),"") -> 131167.08 | FO12: =IFERROR(IF($EQ12<0,EZ12*-$EQ12+FD12*(1+$EQ12),EZ12*(1-$EQ12)+FD12*$EQ12),"") -> 133784.51 | FP12: =IFERROR(IF($EQ12<0,FA12*-$EQ12+FE12*(1+$EQ12),FA12*(1-$EQ12)+FE12*$EQ12),"") -> 136871.74 | FQ12: =IFERROR(IF($EQ12<0,FB12*-$EQ12+FF12*(1+$EQ12),FB12*(1-$EQ12)+FF12*$EQ12),"") -> 142014.89 | FS12: =AZ12 -> 103982 | FT12: =BA12 -> 112010 | FV12: =BC12 -> 120866.63 | FW12: =BD12 -> 124825.95 | FX12: =BE12 -> 128442.54 | FZ12: =BG12 -> 131167.1 | GA12: =BH12 -> 134476.1 | GB12: =BI12 -> 138910.5 | GD12: =BK12 -> 141223.48 | GE12: =BL12 -> 143680.41 | GF12: =BM12 -> 150837.88 | GH12: =IFERROR(IF($EQ12<0,FS12*-$EQ12+FT12*(1+$EQ12),FS12*(1-$EQ12)+FT12*$EQ12),"") -> 106071.48 | GI12: =IFERROR(IF($EQ12<0,FT12*-$EQ12+FX12*(1+$EQ12),FT12*(1-$EQ12)+FX12*$EQ12),"") -> 116286.96 | GK12: =IFERROR(IF($EQ12<0,FV12*-$EQ12+FZ12*(1+$EQ12),FV12*(1-$EQ12)+FZ12*$EQ12),"") -> 123547.58 | GL12: =IFERROR(IF($EQ12<0,FW12*-$EQ12+GA12*(1+$EQ12),FW12*(1-$EQ12)+GA12*$EQ12),"") -> 127337.63 | GM12: =IFERROR(IF($EQ12<0,FX12*-$EQ12+GB12*(1+$EQ12),FX12*(1-$EQ12)+GB12*$EQ12),"") -> 131167.08 | GO12: =IFERROR(IF($EQ12<0,FZ12*-$EQ12+GD12*(1+$EQ12),FZ12*(1-$EQ12)+GD12*$EQ12),"") -> 133784.51 | GP12: =IFERROR(IF($EQ12<0,GA12*-$EQ12+GE12*(1+$EQ12),GA12*(1-$EQ12)+GE12*$EQ12),"") -> 136871.74 | GQ12: =IFERROR(IF($EQ12<0,GB12*-$EQ12+GF12*(1+$EQ12),GB12*(1-$EQ12)+GF12*$EQ12),"") -> 142014.89
B13: MSFT US Equity | C13: Microsoft Corp | D13: =IFERROR(IF(MATCH($B13,Compounders!$A:$A,0),"yes"),"") -> yes | F13: yes | J13: =IF(AND(F13="",G13="",H13="",I13=""),"yes","") | K13: =K12+IF(F13="yes",1) -> 1 | L13: =L12+IF(G13="yes",1) -> 1 | M13: =M12+IF(H13="yes",1) -> 0 | N13: =N12+IF(I13="yes",1) -> 0 | Q13: =Q12+IF(Q$10=$P13,1) -> 1 | R13: =R12+IF(R$10=$P13,1) -> 0 | S13: =S12+IF(S$10=$P13,1) -> 0 | T13: =T12+IF(T$10=$P13,1) -> 0 | U13: =U12+IF(U$10=$P13,1) -> 0 | V13: =V12+IF(V$10=$P13,1) -> 0 | W13: =W12+IF(W$10=$P13,1) -> 0 | X13: =X12+IF(X$10=$P13,1) -> 0 | Y13: =Y12+IF(Y$10=$P13,1) -> 0 | AA13: 3594.4465 | AB13: 2748.7451 | AC13: 3344.5784 | AE13: =$AC13-AA13 -> -249.86804 | AF13: =$AC13-AB13 -> 595.83333 | AH13: =$AC13/AA13-1 -> -0.069515026 | AI13: =$AC13/AB13-1 -> 0.21676558 | AK13: 88136 | AL13: 101832 | AN13: 119088.22 | AO13: 128403.73 | AP13: 128776.85 | AR13: 140470.26 | AS13: 141189.7 | AT13: 144016.85 | AV13: 166629.97 | AW13: 164861.68 | AX13: 170192.62 | AZ13: 88136 | BA13: 101832 | BC13: 119189 | BD13: 125185.24 | BE13: 127200.65 | BG13: 140598 | BH13: 141197.09 | BI13: 144001.13 | BK13: 167060.7 | BL13: 165016.55 | BM13: 170240.37 | BO13: =CHOOSE($AK$6,FH13,GH13) -> 95040.285 | BP13: =CHOOSE($AK$6,FI13,GI13) -> 114620.58 | BR13: =CHOOSE($AK$6,FK13,GK13) -> 129981.48 | BS13: =CHOOSE($AK$6,FL13,GL13) -> 133256.97 | BT13: =CHOOSE($AK$6,FM13,GM13) -> 135669.94 | BV13: =CHOOSE($AK$6,FO13,GO13) -> 153938.1 | BW13: =CHOOSE($AK$6,FP13,GP13) -> 153204.71 | BX13: =CHOOSE($AK$6,FQ13,GQ13) -> 157228.58 | BZ13: =BP13-BO13 -> 19580.296 | CA13: =BT13-BP13 -> 21049.355 | CB13: =BX13-BT13 -> 21558.646 | CD13: =BP13/BO13-1 -> 0.20602102 | CE13: =BT13/BP13-1 -> 0.18364376 | CF13: =BX13/BT13-1 -> 0.15890511 | CH13: =BS13/$BR13-1 -> 0.025199614 | CI13: =BT13/$BR13-1 -> 0.043763573 | CK13: =BW13/$BV13-1 -> -0.0047642149 | CL13: =BX13/$BV13-1 -> 0.021375353 | CN13: =IFERROR(BS13-$BR13,"") -> 3275.4831 | CO13: =IFERROR(BT13-$BR13,"") -> 5688.4541 | CQ13: =IFERROR(BW13-$BV13,"") -> -733.39419 | CR13: =IFERROR(BX13-$BV13,"") -> 3290.4812 | CT13: 138157.57 | CU13: 130587.72 | CV13: 124007.09 | CW13: 116133.15 | CX13: 108872.7 | CY13: 103650.11 | CZ13: 98685.021 | DA13: 98820.946 | DB13: 95586.238 | DC13: 90899.335 | DD13: 84863.259 | DE13: 82460.509 | DF13: 78676.438 | DG13: 73921.291 | DH13: 73450.078 | DI13: 77005.385 | DJ13: 76230.029 | DK13: 73755.079 | DL13: 70304.021 | DM13: 65861.407 | DN13: 61023.492 | DO13: 57040.592 | DP13: 51274.555 | DR13: =AC13 -> 3344.5784 | DS13: 2748.7451 | DT13: 3594.4465 | DU13: 3850.0085 | DV13: 3697.0216 | DW13: 2790.6426 | DX13: 3133.8022 | DY13: 3198.4364 | DZ13: 3321.8691 | EA13: 3126.1331 | EB13: 2794.8279 | EC13: 2345.9479 | ED13: 2532.0809 | EE13: 2146.0486 | EF13: 1787.7317 | EG13: 1736.943 | EH13: 1920.8401 | EI13: 2311.3589 | EJ13: 2525.084 | EK13: 2118.5981 | EL13: 2040.3035 | EM13: 1778.2282 | EN13: 1681.6055 | EP13: 45838 | EQ13: =(DATE(2025,12,31)-EP13)/365 -> 0.50410959 | ES13: =AK13 -> 88136 | ET13: =AL13 -> 101832 | EV13: =AN13 -> 119088.22 | EW13: =AO13 -> 128403.73 | EX13: =AP13 -> 128776.85 | EZ13: =AR13 -> 140470.26 | FA13: =AS13 -> 141189.7 | FB13: =AT13 -> 144016.85 | FD13: =AV13 -> 166629.97 | FE13: =AW13 -> 164861.68 | FF13: =AX13 -> 170192.62 | FH13: =IFERROR(IF($EQ13<0,ES13*-$EQ13+ET13*(1+$EQ13),ES13*(1-$EQ13)+ET13*$EQ13),"") -> 95040.285 | FI13: =IFERROR(IF($EQ13<0,ET13*-$EQ13+EX13*(1+$EQ13),ET13*(1-$EQ13)+EX13*$EQ13),"") -> 115415.16 | FK13: =IFERROR(IF($EQ13<0,EV13*-$EQ13+EZ13*(1+$EQ13),EV13*(1-$EQ13)+EZ13*$EQ13),"") -> 129867.11 | FL13: =IFERROR(IF($EQ13<0,EW13*-$EQ13+FA13*(1+$EQ13),EW13*(1-$EQ13)+FA13*$EQ13),"") -> 134849.26 | FM13: =IFERROR(IF($EQ13<0,EX13*-$EQ13+FB13*(1+$EQ13),EX13*(1-$EQ13)+FB13*$EQ13),"") -> 136459.48 | FO13: =IFERROR(IF($EQ13<0,EZ13*-$EQ13+FD13*(1+$EQ13),EZ13*(1-$EQ13)+FD13*$EQ13),"") -> 153657.62 | FP13: =IFERROR(IF($EQ13<0,FA13*-$EQ13+FE13*(1+$EQ13),FA13*(1-$EQ13)+FE13*$EQ13),"") -> 153122.97 | FQ13: =IFERROR(IF($EQ13<0,FB13*-$EQ13+FF13*(1+$EQ13),FB13*(1-$EQ13)+FF13*$EQ13),"") -> 157212.31 | FS13: =AZ13 -> 88136 | FT13: =BA13 -> 101832 | FV13: =BC13 -> 119189 | FW13: =BD13 -> 125185.24 | FX13: =BE13 -> 127200.65 | FZ13: =BG13 -> 140598 | GA13: =BH13 -> 141197.09 | GB13: =BI13 -> 144001.13 | GD13: =BK13 -> 167060.7 | GE13: =BL13 -> 165016.55 | GF13: =BM13 -> 170240.37 | GH13: =IFERROR(IF($EQ13<0,FS13*-$EQ13+FT13*(1+$EQ13),FS13*(1-$EQ13)+FT13*$EQ13),"") -> 95040.285 | GI13: =IFERROR(IF($EQ13<0,FT13*-$EQ13+FX13*(1+$EQ13),FT13*(1-$EQ13)+FX13*$EQ13),"") -> 114620.58 | GK13: =IFERROR(IF($EQ13<0,FV13*-$EQ13+FZ13*(1+$EQ13),FV13*(1-$EQ13)+FZ13*$EQ13),"") -> 129981.48 | GL13: =IFERROR(IF($EQ13<0,FW13*-$EQ13+GA13*(1+$EQ13),FW13*(1-$EQ13)+GA13*$EQ13),"") -> 133256.97 | GM13: =IFERROR(IF($EQ13<0,FX13*-$EQ13+GB13*(1+$EQ13),FX13*(1-$EQ13)+GB13*$EQ13),"") -> 135669.94 | GO13: =IFERROR(IF($EQ13<0,FZ13*-$EQ13+GD13*(1+$EQ13),FZ13*(1-$EQ13)+GD13*$EQ13),"") -> 153938.1 | GP13: =IFERROR(IF($EQ13<0,GA13*-$EQ13+GE13*(1+$EQ13),GA13*(1-$EQ13)+GE13*$EQ13),"") -> 153204.71 | GQ13: =IFERROR(IF($EQ13<0,GB13*-$EQ13+GF13*(1+$EQ13),GB13*(1-$EQ13)+GF13*$EQ13),"") -> 157228.58
B14: AMZN US Equity | C14: Amazon.Com Inc | D14: =IFERROR(IF(MATCH($B14,Compounders!$A:$A,0),"yes"),"") -> yes | F14: yes | J14: =IF(AND(F14="",G14="",H14="",I14=""),"yes","") | K14: =K13+IF(F14="yes",1) -> 2 | L14: =L13+IF(G14="yes",1) -> 1 | M14: =M13+IF(H14="yes",1) -> 0 | N14: =N13+IF(I14="yes",1) -> 0 | Q14: =Q13+IF(Q$10=$P14,1) -> 1 | R14: =R13+IF(R$10=$P14,1) -> 0 | S14: =S13+IF(S$10=$P14,1) -> 0 | T14: =T13+IF(T$10=$P14,1) -> 0 | U14: =U13+IF(U$10=$P14,1) -> 0 | V14: =V13+IF(V$10=$P14,1) -> 0 | W14: =W13+IF(W$10=$P14,1) -> 0 | X14: =X13+IF(X$10=$P14,1) -> 0 | Y14: =Y13+IF(Y$10=$P14,1) -> 0 | AA14: 2467.5157 | AB14: 2235.762 | AC14: 2911.3041 | AE14: =$AC14-AA14 -> 443.78844 | AF14: =$AC14-AB14 -> 675.54213 | AH14: =$AC14/AA14-1 -> 0.17985233 | AI14: =$AC14/AB14-1 -> 0.30215297 | AK14: 59248 | AL14: 77670 | AN14: 86268.183 | AO14: 84031.143 | AP14: 95575 | AR14: 106375.83 | AS14: 102734.7 | AT14: 109348 | AV14: 127335.65 | AW14: 125690.16 | AX14: 138157.55 | AZ14: 76636.69 | BA14: 93972.3 | BC14: 106189.65 | BD14: 103190.27 | BE14: 113552.29 | BG14: 133870.8 | BH14: 123224.07 | BI14: 127455.79 | BK14: 152436 | BL14: 148298.27 | BM14: 158947.4 | BO14: =CHOOSE($AK$6,FH14,GH14) -> 76636.69 | BP14: =CHOOSE($AK$6,FI14,GI14) -> 93972.3 | BR14: =CHOOSE($AK$6,FK14,GK14) -> 106189.65 | BS14: =CHOOSE($AK$6,FL14,GL14) -> 103190.27 | BT14: =CHOOSE($AK$6,FM14,GM14) -> 113552.29 | BV14: =CHOOSE($AK$6,FO14,GO14) -> 133870.8 | BW14: =CHOOSE($AK$6,FP14,GP14) -> 123224.07 | BX14: =CHOOSE($AK$6,FQ14,GQ14) -> 127455.79 | BZ14: =BP14-BO14 -> 17335.61 | CA14: =BT14-BP14 -> 19579.986 | CB14: =BX14-BT14 -> 13903.5 | CD14: =BP14/BO14-1 -> 0.2262051 | CE14: =BT14/BP14-1 -> 0.20835912 | CF14: =BX14/BT14-1 -> 0.12244139 | CH14: =BS14/$BR14-1 -> -0.028245507 | CI14: =BT14/$BR14-1 -> 0.069334807 | CK14: =BW14/$BV14-1 -> -0.079529915 | CL14: =BX14/$BV14-1 -> -0.047919444 | CN14: =IFERROR(BS14-$BR14,"") -> -2999.3804 | CO14: =IFERROR(BT14-$BR14,"") -> 7362.6387 | CQ14: =IFERROR(BW14-$BV14,"") -> -10646.733 | CR14: =IFERROR(BX14-$BV14,"") -> -6415.0143 | CT14: 107975.04 | CU14: 103190.27 | CV14: 103574.53 | CW14: 94350.325 | CX14: 88807.312 | CY14: 85390.421 | CZ14: 81145.327 | DA14: 74743.467 | DB14: 64273.934 | DC14: 51539.4 | DD14: 51479.619 | DE14: 33734.008 | DF14: 33601.678 | DG14: 30073.944 | DH14: 30636.001 | DI14: 29539.578 | DJ14: 32961.042 | DK14: 33544.067 | DL14: 32685.14 | DM14: 38664.791 | DN14: 37878.375 | DO14: 34492.4 | DP14: 28246.54 | DR14: =AC14 -> 2911.3041 | DS14: 2235.762 | DT14: 2467.5157 | DU14: 2341.6947 | DV14: 2329.1216 | DW14: 2016.324 | DX14: 2306.8883 | DY14: 1955.639 | DZ14: 2011.0807 | EA14: 1873.6758 | EB14: 1570.1526 | EC14: 1311.5925 | ED14: 1337.5397 | EE14: 1058.4395 | EF14: 856.93895 | EG14: 1151.1937 | EH14: 1080.624 | EI14: 1658.8073 | EJ14: 1691.0026 | EK14: 1663.6774 | EL14: 1734.9543 | EM14: 1558.0696 | EN14: 1634.1685 | EP14: 46022 | EQ14: =(DATE(2025,12,31)-EP14)/365 -> 0 | ES14: =AK14 -> 59248 | ET14: =AL14 -> 77670 | EV14: =AN14 -> 86268.183 | EW14: =AO14 -> 84031.143 | EX14: =AP14 -> 95575 | EZ14: =AR14 -> 106375.83 | FA14: =AS14 -> 102734.7 | FB14: =AT14 -> 109348 | FD14: =AV14 -> 127335.65 | FE14: =AW14 -> 125690.16 | FF14: =AX14 -> 138157.55 | FH14: =IFERROR(IF($EQ14<0,ES14*-$EQ14+ET14*(1+$EQ14),ES14*(1-$EQ14)+ET14*$EQ14),"") -> 59248 | FI14: =IFERROR(IF($EQ14<0,ET14*-$EQ14+EX14*(1+$EQ14),ET14*(1-$EQ14)+EX14*$EQ14),"") -> 77670 | FK14: =IFERROR(IF($EQ14<0,EV14*-$EQ14+EZ14*(1+$EQ14),EV14*(1-$EQ14)+EZ14*$EQ14),"") -> 86268.183 | FL14: =IFERROR(IF($EQ14<0,EW14*-$EQ14+FA14*(1+$EQ14),EW14*(1-$EQ14)+FA14*$EQ14),"") -> 84031.143 | FM14: =IFERROR(IF($EQ14<0,EX14*-$EQ14+FB14*(1+$EQ14),EX14*(1-$EQ14)+FB14*$EQ14),"") -> 95575 | FO14: =IFERROR(IF($EQ14<0,EZ14*-$EQ14+FD14*(1+$EQ14),EZ14*(1-$EQ14)+FD14*$EQ14),"") -> 106375.83 | FP14: =IFERROR(IF($EQ14<0,FA14*-$EQ14+FE14*(1+$EQ14),FA14*(1-$EQ14)+FE14*$EQ14),"") -> 102734.7 | FQ14: =IFERROR(IF($EQ14<0,FB14*-$EQ14+FF14*(1+$EQ14),FB14*(1-$EQ14)+FF14*$EQ14),"") -> 109348 | FS14: =AZ14 -> 76636.69 | FT14: =BA14 -> 93972.3 | FV14: =BC14 -> 106189.65 | FW14: =BD14 -> 103190.27 | FX14: =BE14 -> 113552.29 | FZ14: =BG14 -> 133870.8 | GA14: =BH14 -> 123224.07 | GB14: =BI14 -> 127455.79 | GD14: =BK14 -> 152436 | GE14: =BL14 -> 148298.27 | GF14: =BM14 -> 158947.4 | GH14: =IFERROR(IF($EQ14<0,FS14*-$EQ14+FT14*(1+$EQ14),FS14*(1-$EQ14)+FT14*$EQ14),"") -> 76636.69 | GI14: =IFERROR(IF($EQ14<0,FT14*-$EQ14+FX14*(1+$EQ14),FT14*(1-$EQ14)+FX14*$EQ14),"") -> 93972.3 | GK14: =IFERROR(IF($EQ14<0,FV14*-$EQ14+FZ14*(1+$EQ14),FV14*(1-$EQ14)+FZ14*$EQ14),"") -> 106189.65 | GL14: =IFERROR(IF($EQ14<0,FW14*-$EQ14+GA14*(1+$EQ14),FW14*(1-$EQ14)+GA14*$EQ14),"") -> 103190.27 | GM14: =IFERROR(IF($EQ14<0,FX14*-$EQ14+GB14*(1+$EQ14),FX14*(1-$EQ14)+GB14*$EQ14),"") -> 113552.29 | GO14: =IFERROR(IF($EQ14<0,FZ14*-$EQ14+GD14*(1+$EQ14),FZ14*(1-$EQ14)+GD14*$EQ14),"") -> 133870.8 | GP14: =IFERROR(IF($EQ14<0,GA14*-$EQ14+GE14*(1+$EQ14),GA14*(1-$EQ14)+GE14*$EQ14),"") -> 123224.07 | GQ14: =IFERROR(IF($EQ14<0,GB14*-$EQ14+GF14*(1+$EQ14),GB14*(1-$EQ14)+GF14*$EQ14),"") -> 127455.79
B15: GOOGL US Equity | C15: Alphabet Inc | D15: =IFERROR(IF(MATCH($B15,Compounders!$A:$A,0),"yes"),"") -> yes | F15: yes | J15: =IF(AND(F15="",G15="",H15="",I15=""),"yes","") | K15: =K14+IF(F15="yes",1) -> 3 | L15: =L14+IF(G15="yes",1) -> 1 | M15: =M14+IF(H15="yes",1) -> 0 | N15: =N14+IF(I15="yes",1) -> 0 | Q15: =Q14+IF(Q$10=$P15,1) -> 1 | R15: =R14+IF(R$10=$P15,1) -> 0 | S15: =S14+IF(S$10=$P15,1) -> 0 | T15: =T14+IF(T$10=$P15,1) -> 0 | U15: =U14+IF(U$10=$P15,1) -> 0 | V15: =V14+IF(V$10=$P15,1) -> 0 | W15: =W14+IF(W$10=$P15,1) -> 0 | X15: =X14+IF(X$10=$P15,1) -> 0 | Y15: =Y14+IF(Y$10=$P15,1) -> 0 | AA15: 3781.6334 | AB15: 3474.5138 | AC15: 4585.2321 | AE15: =$AC15-AA15 -> 803.5987 | AF15: =$AC15-AB15 -> 1110.7183 | AH15: =$AC15/AA15-1 -> 0.21250042 | AI15: =$AC15/AB15-1 -> 0.3196759 | AK15: 100118 | AL15: 132170 | AN15: 134313.87 | AO15: 140944.13 | AP15: 174690.25 | AR15: 156264.17 | AS15: 163481.46 | AT15: 180500.41 | AV15: 165369.81 | AW15: 188231.75 | AX15: 213237.58 | AZ15: 122903 | BA15: 157123 | BC15: 140407.26 | BD15: 148404.62 | BE15: 176123.76 | BG15: 166577.44 | BH15: 169467.22 | BI15: 182331.38 | BK15: 178076.43 | BL15: 195729 | BM15: 216381.81 | BO15: =CHOOSE($AK$6,FH15,GH15) -> 122903 | BP15: =CHOOSE($AK$6,FI15,GI15) -> 157123 | BR15: =CHOOSE($AK$6,FK15,GK15) -> 140407.26 | BS15: =CHOOSE($AK$6,FL15,GL15) -> 148404.62 | BT15: =CHOOSE($AK$6,FM15,GM15) -> 176123.76 | BV15: =CHOOSE($AK$6,FO15,GO15) -> 166577.44 | BW15: =CHOOSE($AK$6,FP15,GP15) -> 169467.22 | BX15: =CHOOSE($AK$6,FQ15,GQ15) -> 182331.38 | BZ15: =BP15-BO15 -> 34220 | CA15: =BT15-BP15 -> 19000.759 | CB15: =BX15-BT15 -> 6207.626 | CD15: =BP15/BO15-1 -> 0.27843096 | CE15: =BT15/BP15-1 -> 0.1209292 | CF15: =BX15/BT15-1 -> 0.035245818 | CH15: =BS15/$BR15-1 -> 0.056958297 | CI15: =BT15/$BR15-1 -> 0.25437789 | CK15: =BW15/$BV15-1 -> 0.017347933 | CL15: =BX15/$BV15-1 -> 0.09457427 | CN15: =IFERROR(BS15-$BR15,"") -> 7997.3582 | CO15: =IFERROR(BT15-$BR15,"") -> 35716.501 | CQ15: =IFERROR(BW15-$BV15,"") -> 2889.7743 | CR15: =IFERROR(BX15-$BV15,"") -> 15753.94 | CT15: 159738.18 | CU15: 148404.62 | CV15: 134524.28 | CW15: 135612.46 | CX15: 127953.88 | CY15: 113094.22 | CZ15: 112104.11 | DA15: 106537.99 | DB15: 100912.33 | DC15: 88458.514 | DD15: 86185.605 | DE15: 87765.62 | DF15: 77350.356 | DG15: 73546.135 | DH15: 76218.174 | DI15: 76973.7 | DJ15: 85616.052 | DK15: 81188.194 | DL15: 80842.917 | DM15: 82743.714 | DN15: 65481.369 | DO15: 54600.3 | DP15: 46104.5 | DR15: =AC15 -> 4585.2321 | DS15: 3474.5138 | DT15: 3781.6334 | DU15: 2942.6855 | DV15: 2145.38 | DW15: 1894.4855 | DX15: 2324.0225 | DY15: 2049.6776 | DZ15: 2258.6938 | EA15: 1884.633 | EB15: 1756.0003 | EC15: 1656.1899 | ED15: 1527.851 | EE15: 1330.2007 | EF15: 1145.2249 | EG15: 1250.9614 | EH15: 1437.7906 | EI15: 1842.3261 | EJ15: 1921.7766 | EK15: 1779.7672 | EL15: 1658.7588 | EM15: 1392.5618 | EN15: 1185.2636 | EP15: 46022 | EQ15: =(DATE(2025,12,31)-EP15)/365 -> 0 | ES15: =AK15 -> 100118 | ET15: =AL15 -> 132170 | EV15: =AN15 -> 134313.87 | EW15: =AO15 -> 140944.13 | EX15: =AP15 -> 174690.25 | EZ15: =AR15 -> 156264.17 | FA15: =AS15 -> 163481.46 | FB15: =AT15 -> 180500.41 | FD15: =AV15 -> 165369.81 | FE15: =AW15 -> 188231.75 | FF15: =AX15 -> 213237.58 | FH15: =IFERROR(IF($EQ15<0,ES15*-$EQ15+ET15*(1+$EQ15),ES15*(1-$EQ15)+ET15*$EQ15),"") -> 100118 | FI15: =IFERROR(IF($EQ15<0,ET15*-$EQ15+EX15*(1+$EQ15),ET15*(1-$EQ15)+EX15*$EQ15),"") -> 132170 | FK15: =IFERROR(IF($EQ15<0,EV15*-$EQ15+EZ15*(1+$EQ15),EV15*(1-$EQ15)+EZ15*$EQ15),"") -> 134313.87 | FL15: =IFERROR(IF($EQ15<0,EW15*-$EQ15+FA15*(1+$EQ15),EW15*(1-$EQ15)+FA15*$EQ15),"") -> 140944.13 | FM15: =IFERROR(IF($EQ15<0,EX15*-$EQ15+FB15*(1+$EQ15),EX15*(1-$EQ15)+FB15*$EQ15),"") -> 174690.25 | FO15: =IFERROR(IF($EQ15<0,EZ15*-$EQ15+FD15*(1+$EQ15),EZ15*(1-$EQ15)+FD15*$EQ15),"") -> 156264.17 | FP15: =IFERROR(IF($EQ15<0,FA15*-$EQ15+FE15*(1+$EQ15),FA15*(1-$EQ15)+FE15*$EQ15),"") -> 163481.46 | FQ15: =IFERROR(IF($EQ15<0,FB15*-$EQ15+FF15*(1+$EQ15),FB15*(1-$EQ15)+FF15*$EQ15),"") -> 180500.41 | FS15: =AZ15 -> 122903 | FT15: =BA15 -> 157123 | FV15: =BC15 -> 140407.26 | FW15: =BD15 -> 148404.62 | FX15: =BE15 -> 176123.76 | FZ15: =BG15 -> 166577.44 | GA15: =BH15 -> 169467.22 | GB15: =BI15 -> 182331.38 | GD15: =BK15 -> 178076.43 | GE15: =BL15 -> 195729 | GF15: =BM15 -> 216381.81 | GH15: =IFERROR(IF($EQ15<0,FS15*-$EQ15+FT15*(1+$EQ15),FS15*(1-$EQ15)+FT15*$EQ15),"") -> 122903 | GI15: =IFERROR(IF($EQ15<0,FT15*-$EQ15+FX15*(1+$EQ15),FT15*(1-$EQ15)+FX15*$EQ15),"") -> 157123 | GK15: =IFERROR(IF($EQ15<0,FV15*-$EQ15+FZ15*(1+$EQ15),FV15*(1-$EQ15)+FZ15*$EQ15),"") -> 140407.26 | GL15: =IFERROR(IF($EQ15<0,FW15*-$EQ15+GA15*(1+$EQ15),FW15*(1-$EQ15)+GA15*$EQ15),"") -> 148404.62 | GM15: =IFERROR(IF($EQ15<0,FX15*-$EQ15+GB15*(1+$EQ15),FX15*(1-$EQ15)+GB15*$EQ15),"") -> 176123.76 | GO15: =IFERROR(IF($EQ15<0,FZ15*-$EQ15+GD15*(1+$EQ15),FZ15*(1-$EQ15)+GD15*$EQ15),"") -> 166577.44 | GP15: =IFERROR(IF($EQ15<0,GA15*-$EQ15+GE15*(1+$EQ15),GA15*(1-$EQ15)+GE15*$EQ15),"") -> 169467.22 | GQ15: =IFERROR(IF($EQ15<0,GB15*-$EQ15+GF15*(1+$EQ15),GB15*(1-$EQ15)+GF15*$EQ15),"") -> 182331.38
B16: AVGO US Equity | C16: Broadcom Inc | D16: =IFERROR(IF(MATCH($B16,Compounders!$A:$A,0),"yes"),"") -> yes | G16: yes | J16: =IF(AND(F16="",G16="",H16="",I16=""),"yes","") | K16: =K15+IF(F16="yes",1) -> 3 | L16: =L15+IF(G16="yes",1) -> 2 | M16: =M15+IF(H16="yes",1) -> 0 | N16: =N15+IF(I16="yes",1) -> 0 | P16: Digital Semis | Q16: =Q15+IF(Q$10=$P16,1) -> 2 | R16: =R15+IF(R$10=$P16,1) -> 0 | S16: =S15+IF(S$10=$P16,1) -> 0 | T16: =T15+IF(T$10=$P16,1) -> 0 | U16: =U15+IF(U$10=$P16,1) -> 0 | V16: =V15+IF(V$10=$P16,1) -> 0 | W16: =W15+IF(W$10=$P16,1) -> 0 | X16: =X15+IF(X$10=$P16,1) -> 0 | Y16: =Y15+IF(Y$10=$P16,1) -> 0 | AA16: 1640.9549 | AB16: 1465.4271 | AC16: 2115.3077 | AE16: =$AC16-AA16 -> 474.35284 | AF16: =$AC16-AB16 -> 649.88055 | AH16: =$AC16/AA16-1 -> 0.28907123 | AI16: =$AC16/AB16-1 -> 0.44347517 | AK16: 5895 | AL16: 23126 | AN16: 37937.353 | AO16: 42675.886 | AP16: 43342.545 | AR16: 56828.931 | AS16: 72032.361 | AT16: 76026.03 | AV16: 72664.429 | AW16: 89805.167 | AX16: 93675.294 | AZ16: 23733 | BA16: 33728 | BC16: 50148.479 | BD16: 55036.87 | BE16: 55262.696 | BG16: 68076.952 | BH16: 83854.17 | BI16: 88346.042 | BK16: 82167.167 | BL16: 104316.38 | BM16: 111746.96 | BO16: =CHOOSE($AK$6,FH16,GH16) -> 25348.63 | BP16: =CHOOSE($AK$6,FI16,GI16) -> 37208.951 | BR16: =CHOOSE($AK$6,FK16,GK16) -> 53046.506 | BS16: =CHOOSE($AK$6,FL16,GL16) -> 59695.009 | BT16: =CHOOSE($AK$6,FM16,GM16) -> 60610.415 | BV16: =CHOOSE($AK$6,FO16,GO16) -> 70354.549 | BW16: =CHOOSE($AK$6,FP16,GP16) -> 87161.759 | BX16: =CHOOSE($AK$6,FQ16,GQ16) -> 92128.656 | BZ16: =BP16-BO16 -> 11860.321 | CA16: =BT16-BP16 -> 23401.464 | CB16: =BX16-BT16 -> 31518.241 | CD16: =BP16/BO16-1 -> 0.46788803 | CE16: =BT16/BP16-1 -> 0.62892028 | CF16: =BX16/BT16-1 -> 0.52001362 | CH16: =BS16/$BR16-1 -> 0.12533346 | CI16: =BT16/$BR16-1 -> 0.14259013 | CK16: =BW16/$BV16-1 -> 0.23889302 | CL16: =BX16/$BV16-1 -> 0.30949111 | CN16: =IFERROR(BS16-$BR16,"") -> 6648.5022 | CO16: =IFERROR(BT16-$BR16,"") -> 7563.9083 | CQ16: =IFERROR(BW16-$BV16,"") -> 16807.211 | CR16: =IFERROR(BX16-$BV16,"") -> 21774.107 | CT16: 64947.006 | CU16: 64630.735 | CV16: 50148.479 | CW16: 41535.531 | CX16: 36155.309 | CY16: 33767.324 | CZ16: 30887.114 | DA16: 29109.507 | DB16: 26971.011 | DC16: 24623.019 | DD16: 22632.923 | DE16: 19354.542 | DF16: 18678.145 | DG16: 18040.917 | DH16: 17555.778 | DI16: 17424.329 | DJ16: 17060.588 | DK16: 16152.939 | DL16: 14632.538 | DM16: 13626.427 | DN16: 12901.609 | DO16: 12292.605 | DP16: 11781.481 | DR16: =AC16 -> 2115.3077 | DS16: 1465.4271 | DT16: 1640.9549 | DU16: 1557.9554 | DV16: 1296.5118 | DW16: 787.24727 | DX16: 1086.7167 | DY16: 805.67437 | DZ16: 747.35555 | EA16: 614.22314 | EB16: 522.56191 | EC16: 342.80985 | ED16: 357.9757 | EE16: 267.47321 | EF16: 233.65268 | EG16: 179.8247 | EH16: 196.17868 | EI16: 257.08649 | EJ16: 274.73047 | EK16: 199.60509 | EL16: 195.62865 | EM16: 189.31346 | EN16: 178.07934 | EP16: 45963 | EQ16: =(DATE(2025,12,31)-EP16)/365 -> 0.16164384 | ES16: =AK16 -> 5895 | ET16: =AL16 -> 23126 | EV16: =AN16 -> 37937.353 | EW16: =AO16 -> 42675.886 | EX16: =AP16 -> 43342.545 | EZ16: =AR16 -> 56828.931 | FA16: =AS16 -> 72032.361 | FB16: =AT16 -> 76026.03 | FD16: =AV16 -> 72664.429 | FE16: =AW16 -> 89805.167 | FF16: =AX16 -> 93675.294 | FH16: =IFERROR(IF($EQ16<0,ES16*-$EQ16+ET16*(1+$EQ16),ES16*(1-$EQ16)+ET16*$EQ16),"") -> 8680.2849 | FI16: =IFERROR(IF($EQ16<0,ET16*-$EQ16+EX16*(1+$EQ16),ET16*(1-$EQ16)+EX16*$EQ16),"") -> 26393.88 | FK16: =IFERROR(IF($EQ16<0,EV16*-$EQ16+EZ16*(1+$EQ16),EV16*(1-$EQ16)+EZ16*$EQ16),"") -> 40991.06 | FL16: =IFERROR(IF($EQ16<0,EW16*-$EQ16+FA16*(1+$EQ16),EW16*(1-$EQ16)+FA16*$EQ16),"") -> 47421.179 | FM16: =IFERROR(IF($EQ16<0,EX16*-$EQ16+FB16*(1+$EQ16),EX16*(1-$EQ16)+FB16*$EQ16),"") -> 48625.629 | FO16: =IFERROR(IF($EQ16<0,EZ16*-$EQ16+FD16*(1+$EQ16),EZ16*(1-$EQ16)+FD16*$EQ16),"") -> 59388.642 | FP16: =IFERROR(IF($EQ16<0,FA16*-$EQ16+FE16*(1+$EQ16),FA16*(1-$EQ16)+FE16*$EQ16),"") -> 74905.226 | FQ16: =IFERROR(IF($EQ16<0,FB16*-$EQ16+FF16*(1+$EQ16),FB16*(1-$EQ16)+FF16*$EQ16),"") -> 78878.925 | FS16: =AZ16 -> 23733 | FT16: =BA16 -> 33728 | FV16: =BC16 -> 50148.479 | FW16: =BD16 -> 55036.87 | FX16: =BE16 -> 55262.696 | FZ16: =BG16 -> 68076.952 | GA16: =BH16 -> 83854.17 | GB16: =BI16 -> 88346.042 | GD16: =BK16 -> 82167.167 | GE16: =BL16 -> 104316.38 | GF16: =BM16 -> 111746.96 | GH16: =IFERROR(IF($EQ16<0,FS16*-$EQ16+FT16*(1+$EQ16),FS16*(1-$EQ16)+FT16*$EQ16),"") -> 25348.63 | GI16: =IFERROR(IF($EQ16<0,FT16*-$EQ16+FX16*(1+$EQ16),FT16*(1-$EQ16)+FX16*$EQ16),"") -> 37208.951 | GK16: =IFERROR(IF($EQ16<0,FV16*-$EQ16+FZ16*(1+$EQ16),FV16*(1-$EQ16)+FZ16*$EQ16),"") -> 53046.506 | GL16: =IFERROR(IF($EQ16<0,FW16*-$EQ16+GA16*(1+$EQ16),FW16*(1-$EQ16)+GA16*$EQ16),"") -> 59695.009 | GM16: =IFERROR(IF($EQ16<0,FX16*-$EQ16+GB16*(1+$EQ16),FX16*(1-$EQ16)+GB16*$EQ16),"") -> 60610.415 | GO16: =IFERROR(IF($EQ16<0,FZ16*-$EQ16+GD16*(1+$EQ16),FZ16*(1-$EQ16)+GD16*$EQ16),"") -> 70354.549 | GP16: =IFERROR(IF($EQ16<0,GA16*-$EQ16+GE16*(1+$EQ16),GA16*(1-$EQ16)+GE16*$EQ16),"") -> 87161.759 | GQ16: =IFERROR(IF($EQ16<0,GB16*-$EQ16+GF16*(1+$EQ16),GB16*(1-$EQ16)+GF16*$EQ16),"") -> 92128.656
B17: META US Equity | C17: Meta Platforms Inc | D17: =IFERROR(IF(MATCH($B17,Compounders!$A:$A,0),"yes"),"") -> yes | F17: yes | J17: =IF(AND(F17="",G17="",H17="",I17=""),"yes","") | K17: =K16+IF(F17="yes",1) -> 4 | L17: =L16+IF(G17="yes",1) -> 2 | M17: =M16+IF(H17="yes",1) -> 0 | N17: =N16+IF(I17="yes",1) -> 0 | Q17: =Q16+IF(Q$10=$P17,1) -> 2 | R17: =R16+IF(R$10=$P17,1) -> 0 | S17: =S16+IF(S$10=$P17,1) -> 0 | T17: =T16+IF(T$10=$P17,1) -> 0 | U17: =U16+IF(U$10=$P17,1) -> 0 | V17: =V16+IF(V$10=$P17,1) -> 0 | W17: =W16+IF(W$10=$P17,1) -> 0 | X17: =X16+IF(X$10=$P17,1) -> 0 | Y17: =Y16+IF(Y$10=$P17,1) -> 0 | AA17: 1664.132 | AB17: 1447.693 | AC17: 1605.5781 | AE17: =$AC17-AA17 -> -58.553826 | AF17: =$AC17-AB17 -> 157.88512 | AH17: =$AC17/AA17-1 -> -0.035185807 | AI17: =$AC17/AB17-1 -> 0.10905981 | AK17: 62360 | AL17: 60458 | AN17: 76025.673 | AO17: 76328.537 | AP17: 83865.738 | AR17: 85650.977 | AS17: 89154.84 | AT17: 89680.345 | AV17: 99493 | AW17: 104596.97 | AX17: 105220.19 | AZ17: 79050 | BA17: 80885 | BC17: 84822.5 | BD17: 86334.538 | BE17: 95659.929 | BG17: 95313.357 | BH17: 102975.08 | BI17: 105391.31 | BK17: 112790.8 | BL17: 124769 | BM17: 126084.78 | BO17: =CHOOSE($AK$6,FH17,GH17) -> 79050 | BP17: =CHOOSE($AK$6,FI17,GI17) -> 80885 | BR17: =CHOOSE($AK$6,FK17,GK17) -> 84822.5 | BS17: =CHOOSE($AK$6,FL17,GL17) -> 86334.538 | BT17: =CHOOSE($AK$6,FM17,GM17) -> 95659.929 | BV17: =CHOOSE($AK$6,FO17,GO17) -> 95313.357 | BW17: =CHOOSE($AK$6,FP17,GP17) -> 102975.08 | BX17: =CHOOSE($AK$6,FQ17,GQ17) -> 105391.31 | BZ17: =BP17-BO17 -> 1835 | CA17: =BT17-BP17 -> 14774.929 | CB17: =BX17-BT17 -> 9731.3791 | CD17: =BP17/BO17-1 -> 0.023213156 | CE17: =BT17/BP17-1 -> 0.18266587 | CF17: =BX17/BT17-1 -> 0.1017289 | CH17: =BS17/$BR17-1 -> 0.017825912 | CI17: =BT17/$BR17-1 -> 0.12776597 | CK17: =BW17/$BV17-1 -> 0.080384534 | CL17: =BX17/$BV17-1 -> 0.10573492 | CN17: =IFERROR(BS17-$BR17,"") -> 1512.0385 | CO17: =IFERROR(BT17-$BR17,"") -> 10837.429 | CQ17: =IFERROR(BW17-$BV17,"") -> 7661.7198 | CR17: =IFERROR(BX17-$BV17,"") -> 10077.951 | CT17: 92405.9 | CU17: 86334.538 | CV17: 82786.014 | CW17: 86423.917 | CX17: 82310.6 | CY17: 66606.158 | CZ17: 64595.788 | DA17: 59763.442 | DB17: 56288.146 | DC17: 54561.822 | DD17: 45566.67 | DE17: 40590.422 | DF17: 33983.011 | DG17: 27552.944 | DH17: 20620.242 | DI17: 26394.287 | DJ17: 33960.975 | DK17: 36131.476 | DL17: 40959.825 | DM17: 44898.027 | DN17: 44267.964 | DO17: 36349.417 | DP17: 30837.143 | DR17: =AC17 -> 1605.5781 | DS17: 1447.693 | DT17: 1664.132 | DU17: 1844.8665 | DV17: 1855.7998 | DW17: 1460.2999 | DX17: 1478.6429 | DY17: 1448.3425 | DZ17: 1279.1247 | EA17: 1237.9401 | EB17: 909.62861 | EC17: 772.48878 | ED17: 735.45284 | EE17: 549.48403 | EF17: 315.55519 | EG17: 364.64658 | EH17: 436.39465 | EI17: 605.25101 | EJ17: 935.64481 | EK17: 956.89127 | EL17: 985.91948 | EM17: 838.72423 | EN17: 778.03963 | EP17: 46022 | EQ17: =(DATE(2025,12,31)-EP17)/365 -> 0 | ES17: =AK17 -> 62360 | ET17: =AL17 -> 60458 | EV17: =AN17 -> 76025.673 | EW17: =AO17 -> 76328.537 | EX17: =AP17 -> 83865.738 | EZ17: =AR17 -> 85650.977 | FA17: =AS17 -> 89154.84 | FB17: =AT17 -> 89680.345 | FD17: =AV17 -> 99493 | FE17: =AW17 -> 104596.97 | FF17: =AX17 -> 105220.19 | FH17: =IFERROR(IF($EQ17<0,ES17*-$EQ17+ET17*(1+$EQ17),ES17*(1-$EQ17)+ET17*$EQ17),"") -> 62360 | FI17: =IFERROR(IF($EQ17<0,ET17*-$EQ17+EX17*(1+$EQ17),ET17*(1-$EQ17)+EX17*$EQ17),"") -> 60458 | FK17: =IFERROR(IF($EQ17<0,EV17*-$EQ17+EZ17*(1+$EQ17),EV17*(1-$EQ17)+EZ17*$EQ17),"") -> 76025.673 | FL17: =IFERROR(IF($EQ17<0,EW17*-$EQ17+FA17*(1+$EQ17),EW17*(1-$EQ17)+FA17*$EQ17),"") -> 76328.537 | FM17: =IFERROR(IF($EQ17<0,EX17*-$EQ17+FB17*(1+$EQ17),EX17*(1-$EQ17)+FB17*$EQ17),"") -> 83865.738 | FO17: =IFERROR(IF($EQ17<0,EZ17*-$EQ17+FD17*(1+$EQ17),EZ17*(1-$EQ17)+FD17*$EQ17),"") -> 85650.977 | FP17: =IFERROR(IF($EQ17<0,FA17*-$EQ17+FE17*(1+$EQ17),FA17*(1-$EQ17)+FE17*$EQ17),"") -> 89154.84 | FQ17: =IFERROR(IF($EQ17<0,FB17*-$EQ17+FF17*(1+$EQ17),FB17*(1-$EQ17)+FF17*$EQ17),"") -> 89680.345 | FS17: =AZ17 -> 79050 | FT17: =BA17 -> 80885 | FV17: =BC17 -> 84822.5 | FW17: =BD17 -> 86334.538 | FX17: =BE17 -> 95659.929 | FZ17: =BG17 -> 95313.357 | GA17: =BH17 -> 102975.08 | GB17: =BI17 -> 105391.31 | GD17: =BK17 -> 112790.8 | GE17: =BL17 -> 124769 | GF17: =BM17 -> 126084.78 | GH17: =IFERROR(IF($EQ17<0,FS17*-$EQ17+FT17*(1+$EQ17),FS17*(1-$EQ17)+FT17*$EQ17),"") -> 79050 | GI17: =IFERROR(IF($EQ17<0,FT17*-$EQ17+FX17*(1+$EQ17),FT17*(1-$EQ17)+FX17*$EQ17),"") -> 80885 | GK17: =IFERROR(IF($EQ17<0,FV17*-$EQ17+FZ17*(1+$EQ17),FV17*(1-$EQ17)+FZ17*$EQ17),"") -> 84822.5 | GL17: =IFERROR(IF($EQ17<0,FW17*-$EQ17+GA17*(1+$EQ17),FW17*(1-$EQ17)+GA17*$EQ17),"") -> 86334.538 | GM17: =IFERROR(IF($EQ17<0,FX17*-$EQ17+GB17*(1+$EQ17),FX17*(1-$EQ17)+GB17*$EQ17),"") -> 95659.929 | GO17: =IFERROR(IF($EQ17<0,FZ17*-$EQ17+GD17*(1+$EQ17),FZ17*(1-$EQ17)+GD17*$EQ17),"") -> 95313.357 | GP17: =IFERROR(IF($EQ17<0,GA17*-$EQ17+GE17*(1+$EQ17),GA17*(1-$EQ17)+GE17*$EQ17),"") -> 102975.08 | GQ17: =IFERROR(IF($EQ17<0,GB17*-$EQ17+GF17*(1+$EQ17),GB17*(1-$EQ17)+GF17*$EQ17),"") -> 105391.31
B18: TSLA US Equity | C18: Tesla Inc | D18: =IFERROR(IF(MATCH($B18,Compounders!$A:$A,0),"yes"),"") | F18: yes | J18: =IF(AND(F18="",G18="",H18="",I18=""),"yes","") | K18: =K17+IF(F18="yes",1) -> 5 | L18: =L17+IF(G18="yes",1) -> 2 | M18: =M17+IF(H18="yes",1) -> 0 | N18: =N17+IF(I18="yes",1) -> 0 | Q18: =Q17+IF(Q$10=$P18,1) -> 2 | R18: =R17+IF(R$10=$P18,1) -> 0 | S18: =S17+IF(S$10=$P18,1) -> 0 | T18: =T17+IF(T$10=$P18,1) -> 0 | U18: =U17+IF(U$10=$P18,1) -> 0 | V18: =V17+IF(V$10=$P18,1) -> 0 | W18: =W17+IF(W$10=$P18,1) -> 0 | X18: =X17+IF(X$10=$P18,1) -> 0 | Y18: =Y17+IF(Y$10=$P18,1) -> 0 | AA18: 1495.6874 | AB18: 1394.9666 | AC18: 1636.7069 | AE18: =$AC18-AA18 -> 141.01951 | AF18: =$AC18-AB18 -> 241.74032 | AH18: =$AC18/AA18-1 -> 0.09428408 | AI18: =$AC18/AB18-1 -> 0.1732947 | AK18: 7091 | AL18: 3794 | AN18: 6329.1053 | AO18: 5006.9744 | AP18: 4488.8947 | AR18: 9150.8929 | AS18: 7352.4054 | AT18: 6355.8056 | AV18: 13435 | AW18: 11110.24 | AX18: 9246.96 | AZ18: 8419 | BA18: 5858 | BC18: 7489.7895 | BD18: 6622.8696 | BE18: 6602.8605 | BG18: 10429.065 | BH18: 9207.9773 | BI18: 8636.6429 | BK18: 15791.133 | BL18: 12747.448 | BM18: 11892.5 | BO18: =CHOOSE($AK$6,FH18,GH18) -> 8419 | BP18: =CHOOSE($AK$6,FI18,GI18) -> 5858 | BR18: =CHOOSE($AK$6,FK18,GK18) -> 7489.7895 | BS18: =CHOOSE($AK$6,FL18,GL18) -> 6622.8696 | BT18: =CHOOSE($AK$6,FM18,GM18) -> 6602.8605 | BV18: =CHOOSE($AK$6,FO18,GO18) -> 10429.065 | BW18: =CHOOSE($AK$6,FP18,GP18) -> 9207.9773 | BX18: =CHOOSE($AK$6,FQ18,GQ18) -> 8636.6429 | BZ18: =BP18-BO18 -> -2561 | CA18: =BT18-BP18 -> 744.86047 | CB18: =BX18-BT18 -> 2033.7824 | CD18: =BP18/BO18-1 -> -0.3041929 | CE18: =BT18/BP18-1 -> 0.12715269 | CF18: =BX18/BT18-1 -> 0.30801535 | CH18: =BS18/$BR18-1 -> -0.1157469 | CI18: =BT18/$BR18-1 -> -0.11841842 | CK18: =BW18/$BV18-1 -> -0.11708502 | CL18: =BX18/$BV18-1 -> -0.17186792 | CN18: =IFERROR(BS18-$BR18,"") -> -866.91991 | CO18: =IFERROR(BT18-$BR18,"") -> -886.92901 | CQ18: =IFERROR(BW18-$BV18,"") -> -1221.0872 | CR18: =IFERROR(BX18-$BV18,"") -> -1792.4217 | CT18: 7187.1524 | CU18: 6622.8696 | CV18: 7046.0337 | CW18: 7026.4972 | CX18: 7497.767 | CY18: 9490.7755 | CZ18: 11197.672 | DA18: 9566.3201 | DB18: 9453.3492 | DC18: 10159.711 | DD18: 12503.858 | DE18: 13398.492 | DF18: 13084.688 | DG18: 14521.105 | DH18: 17887.471 | DI18: 17738.26 | DJ18: 15025.146 | DK18: 12067.156 | DL18: 9871.2105 | DM18: 7451.139 | DN18: 5601.1429 | DO18: 4692.4762 | DP18: 4358.375 | DR18: =AC18 -> 1636.7069 | DS18: 1394.9666 | DT18: 1495.6874 | DU18: 1478.7611 | DV18: 1023.1689 | DW18: 833.59256 | DX18: 1296.3505 | DY18: 835.81377 | DZ18: 631.07814 | EA18: 559.85431 | EB18: 789.89839 | EC18: 794.1969 | ED18: 829.68114 | EE18: 656.42475 | EF18: 388.97195 | EG18: 831.15293 | EH18: 697.92614 | EI18: 1113.7078 | EJ18: 1061.287 | EK18: 776.85053 | EL18: 654.77571 | EM18: 641.11495 | EN18: 668.90511 | EP18: 46022 | EQ18: =(DATE(2025,12,31)-EP18)/365 -> 0 | ES18: =AK18 -> 7091 | ET18: =AL18 -> 3794 | EV18: =AN18 -> 6329.1053 | EW18: =AO18 -> 5006.9744 | EX18: =AP18 -> 4488.8947 | EZ18: =AR18 -> 9150.8929 | FA18: =AS18 -> 7352.4054 | FB18: =AT18 -> 6355.8056 | FD18: =AV18 -> 13435 | FE18: =AW18 -> 11110.24 | FF18: =AX18 -> 9246.96 | FH18: =IFERROR(IF($EQ18<0,ES18*-$EQ18+ET18*(1+$EQ18),ES18*(1-$EQ18)+ET18*$EQ18),"") -> 7091 | FI18: =IFERROR(IF($EQ18<0,ET18*-$EQ18+EX18*(1+$EQ18),ET18*(1-$EQ18)+EX18*$EQ18),"") -> 3794 | FK18: =IFERROR(IF($EQ18<0,EV18*-$EQ18+EZ18*(1+$EQ18),EV18*(1-$EQ18)+EZ18*$EQ18),"") -> 6329.1053 | FL18: =IFERROR(IF($EQ18<0,EW18*-$EQ18+FA18*(1+$EQ18),EW18*(1-$EQ18)+FA18*$EQ18),"") -> 5006.9744 | FM18: =IFERROR(IF($EQ18<0,EX18*-$EQ18+FB18*(1+$EQ18),EX18*(1-$EQ18)+FB18*$EQ18),"") -> 4488.8947 | FO18: =IFERROR(IF($EQ18<0,EZ18*-$EQ18+FD18*(1+$EQ18),EZ18*(1-$EQ18)+FD18*$EQ18),"") -> 9150.8929 | FP18: =IFERROR(IF($EQ18<0,FA18*-$EQ18+FE18*(1+$EQ18),FA18*(1-$EQ18)+FE18*$EQ18),"") -> 7352.4054 | FQ18: =IFERROR(IF($EQ18<0,FB18*-$EQ18+FF18*(1+$EQ18),FB18*(1-$EQ18)+FF18*$EQ18),"") -> 6355.8056 | FS18: =AZ18 -> 8419 | FT18: =BA18 -> 5858 | FV18: =BC18 -> 7489.7895 | FW18: =BD18 -> 6622.8696 | FX18: =BE18 -> 6602.8605 | FZ18: =BG18 -> 10429.065 | GA18: =BH18 -> 9207.9773 | GB18: =BI18 -> 8636.6429 | GD18: =BK18 -> 15791.133 | GE18: =BL18 -> 12747.448 | GF18: =BM18 -> 11892.5 | GH18: =IFERROR(IF($EQ18<0,FS18*-$EQ18+FT18*(1+$EQ18),FS18*(1-$EQ18)+FT18*$EQ18),"") -> 8419 | GI18: =IFERROR(IF($EQ18<0,FT18*-$EQ18+FX18*(1+$EQ18),FT18*(1-$EQ18)+FX18*$EQ18),"") -> 5858 | GK18: =IFERROR(IF($EQ18<0,FV18*-$EQ18+FZ18*(1+$EQ18),FV18*(1-$EQ18)+FZ18*$EQ18),"") -> 7489.7895 | GL18: =IFERROR(IF($EQ18<0,FW18*-$EQ18+GA18*(1+$EQ18),FW18*(1-$EQ18)+GA18*$EQ18),"") -> 6622.8696 | GM18: =IFERROR(IF($EQ18<0,FX18*-$EQ18+GB18*(1+$EQ18),FX18*(1-$EQ18)+GB18*$EQ18),"") -> 6602.8605 | GO18: =IFERROR(IF($EQ18<0,FZ18*-$EQ18+GD18*(1+$EQ18),FZ18*(1-$EQ18)+GD18*$EQ18),"") -> 10429.065 | GP18: =IFERROR(IF($EQ18<0,GA18*-$EQ18+GE18*(1+$EQ18),GA18*(1-$EQ18)+GE18*$EQ18),"") -> 9207.9773 | GQ18: =IFERROR(IF($EQ18<0,GB18*-$EQ18+GF18*(1+$EQ18),GB18*(1-$EQ18)+GF18*$EQ18),"") -> 8636.6429
B19: MU US Equity | C19: Micron Technology Inc | D19: =IFERROR(IF(MATCH($B19,Compounders!$A:$A,0),"yes"),"") | G19: yes | J19: =IF(AND(F19="",G19="",H19="",I19=""),"yes","") | K19: =K18+IF(F19="yes",1) -> 5 | L19: =L18+IF(G19="yes",1) -> 3 | M19: =M18+IF(H19="yes",1) -> 0 | N19: =N18+IF(I19="yes",1) -> 0 | P19: Memory | Q19: =Q18+IF(Q$10=$P19,1) -> 2 | R19: =R18+IF(R$10=$P19,1) -> 1 | S19: =S18+IF(S$10=$P19,1) -> 0 | T19: =T18+IF(T$10=$P19,1) -> 0 | U19: =U18+IF(U$10=$P19,1) -> 0 | V19: =V18+IF(V$10=$P19,1) -> 0 | W19: =W18+IF(W$10=$P19,1) -> 0 | X19: =X18+IF(X$10=$P19,1) -> 0 | Y19: =Y18+IF(Y$10=$P19,1) -> 0 | AA19: 321.2316 | AB19: 380.99367 | AC19: 1095.0298 | AE19: =$AC19-AA19 -> 773.79817 | AF19: =$AC19-AB19 -> 714.03609 | AH19: =$AC19/AA19-1 -> 2.4088482 | AI19: =$AC19/AB19-1 -> 1.8741416 | AK19: 778 | AL19: 8539 | AN19: 34331.692 | AO19: 62546.485 | AP19: 66943.176 | AR19: 45438.458 | AS19: 104754.9 | AT19: 119493.25 | AV19: 40920.917 | AW19: 89387.056 | AX19: 116308.33 | AZ19: 1472 | BA19: 9470 | BC19: 35433.114 | BD19: 63338.41 | BE19: 68166.553 | BG19: 45249.697 | BH19: 103395.43 | BI19: 121897.62 | BK19: 41320.375 | BL19: 82777.087 | BM19: 115571.86 | BO19: =CHOOSE($AK$6,FH19,GH19) -> 4211.0411 | BP19: =CHOOSE($AK$6,FI19,GI19) -> 29571.559 | BR19: =CHOOSE($AK$6,FK19,GK19) -> 38794.958 | BS19: =CHOOSE($AK$6,FL19,GL19) -> 77056.569 | BT19: =CHOOSE($AK$6,FM19,GM19) -> 86567.604 | BV19: =CHOOSE($AK$6,FO19,GO19) -> 43904.039 | BW19: =CHOOSE($AK$6,FP19,GP19) -> 96334.355 | BX19: =CHOOSE($AK$6,FQ19,GQ19) -> 119731.26 | BZ19: =BP19-BO19 -> 25360.518 | CA19: =BT19-BP19 -> 56996.045 | CB19: =BX19-BT19 -> 33163.66 | CD19: =BP19/BO19-1 -> 6.0223867 | CE19: =BT19/BP19-1 -> 1.927394 | CF19: =BX19/BT19-1 -> 0.38309551 | CH19: =BS19/$BR19-1 -> 0.98625216 | CI19: =BT19/$BR19-1 -> 1.2314138 | CK19: =BW19/$BV19-1 -> 1.1942026 | CL19: =BX19/$BV19-1 -> 1.7271128 | CN19: =IFERROR(BS19-$BR19,"") -> 38261.611 | CO19: =IFERROR(BT19-$BR19,"") -> 47772.646 | CQ19: =IFERROR(BW19-$BV19,"") -> 52430.316 | CR19: =IFERROR(BX19-$BV19,"") -> 75827.225 | CT19: 110653.52 | CU19: 104059.25 | CV19: 40271.475 | CW19: 17651.816 | CX19: 12980.255 | CY19: 10221.453 | CZ19: 9157.2081 | DA19: 10042.839 | DB19: 8539.5695 | DC19: 5131.4486 | DD19: 1867.9303 | DE19: -1644.8485 | DF19: -2757.2481 | DG19: -3290.4008 | DH19: -1434.6076 | DI19: 1768.9133 | DJ19: 9912.6121 | DK19: 13190.749 | DL19: 11098.994 | DM19: 10332.045 | DN19: 12370.204 | DO19: 9452.1016 | DP19: 4187 | DR19: =AC19 -> 1095.0298 | DS19: 380.99367 | DT19: 321.2316 | DU19: 187.25201 | DV19: 137.93217 | DW19: 97.10579 | DX19: 93.76871 | DY19: 114.99793 | DZ19: 145.8459 | EA19: 130.54763 | EB19: 94.207584 | EC19: 74.513368 | ED19: 69.124484 | EE19: 66.035755 | EF19: 54.537004 | EG19: 55.26757 | EH19: 61.729344 | EI19: 86.977181 | EJ19: 104.34381 | EK19: 79.905988 | EL19: 95.297894 | EM19: 98.678012 | EN19: 83.969196 | EP19: 45897 | EQ19: =(DATE(2025,12,31)-EP19)/365 -> 0.34246575 | ES19: =AK19 -> 778 | ET19: =AL19 -> 8539 | EV19: =AN19 -> 34331.692 | EW19: =AO19 -> 62546.485 | EX19: =AP19 -> 66943.176 | EZ19: =AR19 -> 45438.458 | FA19: =AS19 -> 104754.9 | FB19: =AT19 -> 119493.25 | FD19: =AV19 -> 40920.917 | FE19: =AW19 -> 89387.056 | FF19: =AX19 -> 116308.33 | FH19: =IFERROR(IF($EQ19<0,ES19*-$EQ19+ET19*(1+$EQ19),ES19*(1-$EQ19)+ET19*$EQ19),"") -> 3435.8767 | FI19: =IFERROR(IF($EQ19<0,ET19*-$EQ19+EX19*(1+$EQ19),ET19*(1-$EQ19)+EX19*$EQ19),"") -> 28540.43 | FK19: =IFERROR(IF($EQ19<0,EV19*-$EQ19+EZ19*(1+$EQ19),EV19*(1-$EQ19)+EZ19*$EQ19),"") -> 38135.379 | FL19: =IFERROR(IF($EQ19<0,EW19*-$EQ19+FA19*(1+$EQ19),EW19*(1-$EQ19)+FA19*$EQ19),"") -> 77001.423 | FM19: =IFERROR(IF($EQ19<0,EX19*-$EQ19+FB19*(1+$EQ19),EX19*(1-$EQ19)+FB19*$EQ19),"") -> 84939.777 | FO19: =IFERROR(IF($EQ19<0,EZ19*-$EQ19+FD19*(1+$EQ19),EZ19*(1-$EQ19)+FD19*$EQ19),"") -> 43891.355 | FP19: =IFERROR(IF($EQ19<0,FA19*-$EQ19+FE19*(1+$EQ19),FA19*(1-$EQ19)+FE19*$EQ19),"") -> 99491.942 | FQ19: =IFERROR(IF($EQ19<0,FB19*-$EQ19+FF19*(1+$EQ19),FB19*(1-$EQ19)+FF19*$EQ19),"") -> 118402.53 | FS19: =AZ19 -> 1472 | FT19: =BA19 -> 9470 | FV19: =BC19 -> 35433.114 | FW19: =BD19 -> 63338.41 | FX19: =BE19 -> 68166.553 | FZ19: =BG19 -> 45249.697 | GA19: =BH19 -> 103395.43 | GB19: =BI19 -> 121897.62 | GD19: =BK19 -> 41320.375 | GE19: =BL19 -> 82777.087 | GF19: =BM19 -> 115571.86 | GH19: =IFERROR(IF($EQ19<0,FS19*-$EQ19+FT19*(1+$EQ19),FS19*(1-$EQ19)+FT19*$EQ19),"") -> 4211.0411 | GI19: =IFERROR(IF($EQ19<0,FT19*-$EQ19+FX19*(1+$EQ19),FT19*(1-$EQ19)+FX19*$EQ19),"") -> 29571.559 | GK19: =IFERROR(IF($EQ19<0,FV19*-$EQ19+FZ19*(1+$EQ19),FV19*(1-$EQ19)+FZ19*$EQ19),"") -> 38794.958 | GL19: =IFERROR(IF($EQ19<0,FW19*-$EQ19+GA19*(1+$EQ19),FW19*(1-$EQ19)+GA19*$EQ19),"") -> 77056.569 | GM19: =IFERROR(IF($EQ19<0,FX19*-$EQ19+GB19*(1+$EQ19),FX19*(1-$EQ19)+GB19*$EQ19),"") -> 86567.604 | GO19: =IFERROR(IF($EQ19<0,FZ19*-$EQ19+GD19*(1+$EQ19),FZ19*(1-$EQ19)+GD19*$EQ19),"") -> 43904.039 | GP19: =IFERROR(IF($EQ19<0,GA19*-$EQ19+GE19*(1+$EQ19),GA19*(1-$EQ19)+GE19*$EQ19),"") -> 96334.355 | GQ19: =IFERROR(IF($EQ19<0,GB19*-$EQ19+GF19*(1+$EQ19),GB19*(1-$EQ19)+GF19*$EQ19),"") -> 119731.26
B20: BRK/B US Equity | C20: Berkshire Hathaway Inc | D20: =IFERROR(IF(MATCH($B20,Compounders!$A:$A,0),"yes"),"") | J20: =IF(AND(F20="",G20="",H20="",I20=""),"yes","") -> yes | K20: =K19+IF(F20="yes",1) -> 5 | L20: =L19+IF(G20="yes",1) -> 3 | M20: =M19+IF(H20="yes",1) -> 0 | N20: =N19+IF(I20="yes",1) -> 0 | Q20: =Q19+IF(Q$10=$P20,1) -> 2 | R20: =R19+IF(R$10=$P20,1) -> 1 | S20: =S19+IF(S$10=$P20,1) -> 0 | T20: =T19+IF(T$10=$P20,1) -> 0 | U20: =U19+IF(U$10=$P20,1) -> 0 | V20: =V19+IF(V$10=$P20,1) -> 0 | W20: =W19+IF(W$10=$P20,1) -> 0 | X20: =X19+IF(X$10=$P20,1) -> 0 | Y20: =Y19+IF(Y$10=$P20,1) -> 0 | AA20: 1084.816 | AB20: 1033.2357 | AC20: 1022.9695 | AE20: =$AC20-AA20 -> -61.846493 | AF20: =$AC20-AB20 -> -10.266173 | AH20: =$AC20/AA20-1 -> -0.057011044 | AI20: =$AC20/AB20-1 -> -0.0099359451 | AK20: 88995 | AL20: 66968 | AN20: 49656.25 | AO20: 46032 | AP20: 47298.5 | AR20: 48339 | AS20: 50020.25 | AT20: 49076.25 | AV20: 54469 | AW20: 52118 | AX20: 46286 | AZ20: 47437 | BA20: 44486 | BC20: 46396 | BD20: 45160.25 | BE20: 45521.5 | BG20: 48339 | BH20: 46648.25 | BI20: 45720.5 | BK20: 54469 | BL20: 52118 | BM20: 46286 | BO20: =CHOOSE($AK$6,FH20,GH20) -> 47437 | BP20: =CHOOSE($AK$6,FI20,GI20) -> 44486 | BR20: =CHOOSE($AK$6,FK20,GK20) -> 46396 | BS20: =CHOOSE($AK$6,FL20,GL20) -> 45160.25 | BT20: =CHOOSE($AK$6,FM20,GM20) -> 45521.5 | BV20: =CHOOSE($AK$6,FO20,GO20) -> 48339 | BW20: =CHOOSE($AK$6,FP20,GP20) -> 46648.25 | BX20: =CHOOSE($AK$6,FQ20,GQ20) -> 45720.5 | BZ20: =BP20-BO20 -> -2951 | CA20: =BT20-BP20 -> 1035.5 | CB20: =BX20-BT20 -> 199 | CD20: =BP20/BO20-1 -> -0.062208824 | CE20: =BT20/BP20-1 -> 0.023276986 | CF20: =BX20/BT20-1 -> 0.0043715607 | CH20: =BS20/$BR20-1 -> -0.026634839 | CI20: =BT20/$BR20-1 -> -0.018848608 | CK20: =BW20/$BV20-1 -> -0.034976934 | CL20: =BX20/$BV20-1 -> -0.054169511 | CN20: =IFERROR(BS20-$BR20,"") -> -1235.75 | CO20: =IFERROR(BT20-$BR20,"") -> -874.5 | CQ20: =IFERROR(BW20-$BV20,"") -> -1690.75 | CR20: =IFERROR(BX20-$BV20,"") -> -2618.5 | CT20: 43498.5 | CU20: 45160.25 | CV20: 45079 | CW20: 45472.5 | CX20: 45437 | CY20: 44377.667 | CZ20: 41445.167 | DA20: 41289 | DB20: 39005 | DC20: 38688 | DD20: 36360 | DE20: 35669.5 | DF20: 33116.5 | DG20: 28574 | DH20: 33564 | DI20: 30463.667 | DJ20: 28622.5 | DK20: 28591 | DL20: 27266.5 | DM20: 26969 | DN20: 25650 | DO20: 23561 | DP20: 22937 | DR20: =AC20 -> 1022.9695 | DS20: 1033.2357 | DT20: 1084.816 | DU20: 1084.6254 | DV20: 1048.0477 | DW20: 1148.7201 | DX20: 978.01042 | DY20: 992.31738 | DZ20: 877.88081 | EA20: 908.91949 | EB20: 776.89179 | EC20: 763.98636 | ED20: 745.28402 | EE20: 675.65699 | EF20: 681.92096 | EG20: 591.27787 | EH20: 602.01131 | EI20: 779.54232 | EJ20: 669.12203 | EK20: 618.22815 | EL20: 635.74418 | EM20: 587.82314 | EN20: 543.67851 | EP20: 46022 | EQ20: =(DATE(2025,12,31)-EP20)/365 -> 0 | ES20: =AK20 -> 88995 | ET20: =AL20 -> 66968 | EV20: =AN20 -> 49656.25 | EW20: =AO20 -> 46032 | EX20: =AP20 -> 47298.5 | EZ20: =AR20 -> 48339 | FA20: =AS20 -> 50020.25 | FB20: =AT20 -> 49076.25 | FD20: =AV20 -> 54469 | FE20: =AW20 -> 52118 | FF20: =AX20 -> 46286 | FH20: =IFERROR(IF($EQ20<0,ES20*-$EQ20+ET20*(1+$EQ20),ES20*(1-$EQ20)+ET20*$EQ20),"") -> 88995 | FI20: =IFERROR(IF($EQ20<0,ET20*-$EQ20+EX20*(1+$EQ20),ET20*(1-$EQ20)+EX20*$EQ20),"") -> 66968 | FK20: =IFERROR(IF($EQ20<0,EV20*-$EQ20+EZ20*(1+$EQ20),EV20*(1-$EQ20)+EZ20*$EQ20),"") -> 49656.25 | FL20: =IFERROR(IF($EQ20<0,EW20*-$EQ20+FA20*(1+$EQ20),EW20*(1-$EQ20)+FA20*$EQ20),"") -> 46032 | FM20: =IFERROR(IF($EQ20<0,EX20*-$EQ20+FB20*(1+$EQ20),EX20*(1-$EQ20)+FB20*$EQ20),"") -> 47298.5 | FO20: =IFERROR(IF($EQ20<0,EZ20*-$EQ20+FD20*(1+$EQ20),EZ20*(1-$EQ20)+FD20*$EQ20),"") -> 48339 | FP20: =IFERROR(IF($EQ20<0,FA20*-$EQ20+FE20*(1+$EQ20),FA20*(1-$EQ20)+FE20*$EQ20),"") -> 50020.25 | FQ20: =IFERROR(IF($EQ20<0,FB20*-$EQ20+FF20*(1+$EQ20),FB20*(1-$EQ20)+FF20*$EQ20),"") -> 49076.25 | FS20: =AZ20 -> 47437 | FT20: =BA20 -> 44486 | FV20: =BC20 -> 46396 | FW20: =BD20 -> 45160.25 | FX20: =BE20 -> 45521.5 | FZ20: =BG20 -> 48339 | GA20: =BH20 -> 46648.25 | GB20: =BI20 -> 45720.5 | GD20: =BK20 -> 54469 | GE20: =BL20 -> 52118 | GF20: =BM20 -> 46286 | GH20: =IFERROR(IF($EQ20<0,FS20*-$EQ20+FT20*(1+$EQ20),FS20*(1-$EQ20)+FT20*$EQ20),"") -> 47437 | GI20: =IFERROR(IF($EQ20<0,FT20*-$EQ20+FX20*(1+$EQ20),FT20*(1-$EQ20)+FX20*$EQ20),"") -> 44486 | GK20: =IFERROR(IF($EQ20<0,FV20*-$EQ20+FZ20*(1+$EQ20),FV20*(1-$EQ20)+FZ20*$EQ20),"") -> 46396 | GL20: =IFERROR(IF($EQ20<0,FW20*-$EQ20+GA20*(1+$EQ20),FW20*(1-$EQ20)+GA20*$EQ20),"") -> 45160.25 | GM20: =IFERROR(IF($EQ20<0,FX20*-$EQ20+GB20*(1+$EQ20),FX20*(1-$EQ20)+GB20*$EQ20),"") -> 45521.5 | GO20: =IFERROR(IF($EQ20<0,FZ20*-$EQ20+GD20*(1+$EQ20),FZ20*(1-$EQ20)+GD20*$EQ20),"") -> 48339 | GP20: =IFERROR(IF($EQ20<0,GA20*-$EQ20+GE20*(1+$EQ20),GA20*(1-$EQ20)+GE20*$EQ20),"") -> 46648.25 | GQ20: =IFERROR(IF($EQ20<0,GB20*-$EQ20+GF20*(1+$EQ20),GB20*(1-$EQ20)+GF20*$EQ20),"") -> 45720.5
