Workbook

Sheet Summary
D1: IRR yrs: | CM1: =TODAY() -> 46183 | DT1: 46387 | DU1: =DT1+365 -> 46752 | DV1: =DU1+365 -> 47117 | DW1: =DV1+365 -> 47482
B2: =IFERROR($D$4:$ED$55,"--> select table 1") -> --> select table 1 | D2: =TODAY() -> 46183 | DT2: =(DT1-$D$2)/365 -> 0.55890411 | DU2: =(DU1-$D$2)/365 -> 1.5589041 | DV2: =(DV1-$D$2)/365 -> 2.5589041 | DW2: =(DW1-$D$2)/365 -> 3.5589041 | FF2: WORK IN PROGRESS
B3: =IFERROR($D$4:$EM$44,"--> select table 2") -> --> select table 2
D4: =$D$2 -> 46183 | O4: Revs | X4: GM | AG4: Adj GP | AP4: Adj EPS | AY4: Mendo EPS | BH4: EV / Revs | BO4: EV / GP | BT4: P/E (Adj, Ex SBC) | BY4: Mendo P/E | CD4: x | CE4: Target Mult (GP or P/E) | CI4: Target Px (old, hardcoded) | CN4: Derived Target Px for IRR calc | CS4: Net Cash per Share | CX4: EV | DC4: WADSO | DH4: Net Debt | DO4: DPS | DT4: IRR | DU4: IRR | DX4: MoM | EB4: Recent Performance | EE4: NTM - YE28 IRR Decomp | EL4: '26-'29 CAGR | EN4: Key details | EX4: Consensus key metric | FB4: Mendo vs Consensus | FF4: Earnings | FI4: Valuation | FL4: 3yr Net | FN4: Up/Down | FT4: Val up/down
D5: Company | E5: Port | F5: Update | G5: Update by | H5: Px | I5: Shares | J5: Cash | K5: Debt | L5: Min Int | M5: Net Debt | N5: EV | O5: 2022 | P5: =O5+1 -> 2023 | Q5: =P5+1 -> 2024 | R5: =Q5+1 -> 2025 | S5: =R5+1 -> 2026 | T5: 2027 | U5: 2028 | V5: 2029 | W5: 2030 | X5: 2022 | Y5: =X5+1 -> 2023 | Z5: =Y5+1 -> 2024 | AA5: =Z5+1 -> 2025 | AB5: =AA5+1 -> 2026 | AC5: 2027 | AD5: 2028 | AE5: 2029 | AF5: 2030 | AG5: 2022 | AH5: =AG5+1 -> 2023 | AI5: =AH5+1 -> 2024 | AJ5: =AI5+1 -> 2025 | AK5: =AJ5+1 -> 2026 | AL5: 2027 | AM5: 2028 | AN5: 2029 | AO5: 2030 | AP5: 2022 | AQ5: =AP5+1 -> 2023 | AR5: =AQ5+1 -> 2024 | AS5: =AR5+1 -> 2025 | AT5: =AS5+1 -> 2026 | AU5: 2027 | AV5: 2028 | AW5: 2029 | AX5: 2030 | AY5: 2022 | AZ5: =AY5+1 -> 2023 | BA5: =AZ5+1 -> 2024 | BB5: =BA5+1 -> 2025 | BC5: =BB5+1 -> 2026 | BD5: 2027 | BE5: 2028 | BF5: 2029 | BG5: 2030 | BH5: 2024 | BI5: 2025 | BJ5: 2026 | BK5: 2027 | BL5: 2028 | BM5: =BL5+1 -> 2029 | BN5: =BM5+1 -> 2030 | BO5: 2026 | BP5: 2027 | BQ5: 2028 | BR5: 2029 | BS5: 2030 | BT5: 2026 | BU5: 2027 | BV5: 2028 | BW5: 2029 | BX5: 2030 | BY5: 2026 | BZ5: 2027 | CA5: 2028 | CB5: 2029 | CC5: 2030 | CD5: 2026 | CE5: 2027 | CF5: 2028 | CG5: 2029 | CH5: 2030 | CI5: 2026 | CJ5: 2027 | CK5: 2028 | CL5: 2029 | CM5: 2030 | CN5: 2026 | CO5: 2027 | CP5: 2028 | CQ5: 2029 | CR5: 2030 | CS5: 2026 | CT5: 2027 | CU5: 2028 | CV5: 2029 | CW5: 2030 | CX5: 2026 | CY5: 2027 | CZ5: 2028 | DA5: 2029 | DB5: 2030 | DC5: 2026 | DD5: 2027 | DE5: 2028 | DF5: 2029 | DG5: 2030 | DH5: 2026 | DI5: 2027 | DJ5: 2028 | DK5: 2029 | DL5: 2030 | DO5: 2026 | DP5: 2027 | DQ5: 2028 | DR5: 2029 | DS5: 2030 | DT5: 2026 | DU5: 2027 | DV5: 2028 | DW5: 2029 | DX5: 2026 | DY5: 2027 | DZ5: 2028 | EA5: 2029 | EB5: 1M | EC5: 3M | ED5: 6M | EE5: Revs | EF5: Margin | EG5: Mendo NI | EH5: Yield | EI5: EPS + Divs | EJ5: Multiple | EK5: Return | EL5: GP | EM5: mEPS | EN5: 3Mo ADV ($m) | EQ5: Div yield | ER5: Mendo EPS CAGR | ES5: Total Yield | EU5: Multiple CAGR | EX5: 2026 | EY5: =EX5+1 -> 2027 | EZ5: =EY5+1 -> 2028 | FA5: =EZ5+1 -> 2029 | FB5: 2026 | FC5: =FB5+1 -> 2027 | FD5: =FC5+1 -> 2028 | FE5: =FD5+1 -> 2029 | FF5: Convex | FG5: Risk | FH5: Range | FI5: Convex | FJ5: Risk | FK5: Range | FL5: Earnings | FM5: Val | FN5: Up | FO5: Down | FP5: Net | FQ5: Base | FR5: Skew | FS5: Range | FT5: up | FU5: down | FV5: Notes
D6: Big Tech
B7: WDAY US EQUITY | D7: WDAY | E7: 1 | F7: 45991 | H7: {=_xll.BQL($B7, "px_last", "dates=" & _xll.BQL.DATE($D$2))} -> #N/A Connection | I7: {=_xll.BQL(""&B7&"", "CB_IS_ADJ_DILUTED_AVG_SHS/1M", "FPT=Q", "FPO=0Q", "ACT_EST_MAPPING=PRECISE", "FS=MRC", "CURRENCY=USD", "XLFILL=b")} -> 254.313 | J7: -8017 | K7: 2984 | M7: =K7+J7 -> -5033 | N7: =I7*H7+M7+L7 -> #VALUE! | O7: 6215.818 | P7: 7258.753 | Q7: 8446 | R7: 9552 | S7: 10723.337 | T7: 11959.266 | U7: 13226.36 | V7: 14542.97 | W7: 15876.671 | X7: =AG7/O7 -> 0.76955632 | Y7: =AH7/P7 -> 0.79683535 | Z7: =AI7/Q7 -> 0.78886878 | AA7: =AJ7/R7 -> 0.79169571 | AB7: =AK7/S7 -> 0.80060817 | AC7: =AL7/T7 -> 0.80656338 | AD7: =AM7/U7 -> 0.81225976 | AE7: =AN7/V7 -> 0.81644821 | AF7: =AO7/W7 -> 0.82046166 | AG7: 4783.422 | AH7: 5784.031 | AI7: 6662.7857 | AJ7: 7562.2774 | AK7: 8585.1913 | AL7: 9645.9061 | AM7: 10743.24 | AN7: 11873.582 | AO7: 13026.2 | AQ7: 5.6577043 | AR7: 7.13432 | AS7: 9.0770109 | AT7: 10.410325 | AU7: 13.111934 | AV7: 15.687176 | AW7: 18.590369 | AX7: 21.987373 | AZ7: 1.3596545 | BA7: 2.6061784 | BB7: 4.2675468 | BC7: 5.5610566 | BD7: 7.7961783 | BE7: 9.9297272 | BF7: 12.341413 | BG7: 15.25191 | BH7: =$N7/Q7 -> #VALUE! | BI7: =$N7/R7 -> #VALUE! | BJ7: =$N7/S7 -> #VALUE! | BK7: =$N7/T7 -> #VALUE! | BL7: =$N7/U7 -> #VALUE! | BM7: =$N7/V7 -> #VALUE! | BN7: =$N7/W7 -> #VALUE! | BO7: =$N7/AK7 -> #VALUE! | BP7: =$N7/AL7 -> #VALUE! | BQ7: =$N7/AM7 -> #VALUE! | BR7: =$N7/AN7 -> #VALUE! | BS7: =$N7/AO7 -> #VALUE! | BT7: =$H7/AT7 -> #VALUE! | BU7: =$H7/AU7 -> #VALUE! | BV7: =$H7/AV7 -> #VALUE! | BW7: =$H7/AW7 -> #VALUE! | BX7: =$H7/AX7 -> #VALUE! | BY7: =$H7/BC7 -> #VALUE! | BZ7: =$H7/BD7 -> #VALUE! | CA7: =$H7/BE7 -> #VALUE! | CB7: =$H7/BF7 -> #VALUE! | CC7: =$H7/BG7 -> #VALUE! | CD7: 22 | CE7: 22 | CF7: 22 | CG7: 22 | CH7: 20 | CN7: =CD7*BD7+CS7 -> 180.93166 | CO7: =CE7*BE7+CT7 -> 228.34968 | CP7: =CF7*BF7+CU7 -> 281.87397 | CQ7: =CG7*BG7+CV7 -> 346.43357 | CS7: 9.4157415 | CT7: 9.8956805 | CU7: 10.362889 | CV7: 10.891539 | CW7: 11.486062 | CX7: =CN7*DC7+DH7 -> 46054.855 | CY7: =CO7*DD7+DI7 -> 57106.681 | CZ7: =CP7*DE7+DJ7 -> 67502.046 | DA7: =CQ7*DF7+DK7 -> 79648.601 | DC7: 268.117 | DD7: 260.83979 | DE7: 248.1891 | DF7: 236.99955 | DG7: 225.49614 | DH7: -2456 | DI7: -2456 | DJ7: -2456 | DK7: -2456 | DL7: -2456 | DT7: =_xlfn.RRI(DT$2,$H7,CN7+$DO7*$DT$2) -> #VALUE! | DU7: =_xlfn.RRI(DU$2,$H7,CO7+$DO7*$DT$2+SUM($DP7:DP7)) -> #VALUE! | DV7: =_xlfn.RRI(DV$2,$H7,CP7+$DO7*$DT$2+SUM($DP7:DQ7)) -> #VALUE! | DW7: =_xlfn.RRI(DW$2,$H7,CQ7+$DO7*$DT$2+SUM($DP7:DR7)) -> #VALUE! | DX7: =SUM(CN7,$DO7:DO7)/$H7 -> #VALUE! | DY7: =SUM(CO7,$DO7:DP7)/$H7 -> #VALUE! | DZ7: =SUM(CP7,$DO7:DQ7)/$H7 -> #VALUE! | EA7: =SUM(CQ7,$DO7:DR7)/$H7 -> #VALUE! | EB7: {=_xll.BDP(""&$B7&"","CHG_PCT_1M")/100} -> 0.1284518 | EC7: {=_xll.BDP(""&$B7&"","CHG_PCT_3M")/100} -> -0.04495494 | ED7: {=_xll.BDP(""&$B7&"","CHG_PCT_6M")/100} -> -0.3472851 | EE7: =_xlfn.RRI(2+$DT$2,$DT$2*S7+(1-$DT$2)*T7,V7) -> 0.10482808 | EF7: =EG7-EE7 -> 0.12287853 | EG7: =_xlfn.RRI(2+$DT$2,$DT$2*(BC7*DC7)+(1-$DT$2)*(BD7*DD7),(BF7*DF7)) -> 0.2277066 | EH7: =EI7-EG7 -> #VALUE! | EI7: =ER7+EQ7 -> #VALUE! | EJ7: =EK7-EI7 -> #VALUE! | EK7: =DV7 -> #VALUE! | EL7: =_xlfn.RRI(3,AK7,AN7) -> 0.11415067 | EM7: =_xlfn.RRI(3,BC7,BF7) -> 0.30437516 | EN7: {=_xll.BDP(B7,"AVG_DAILY_VALUE_TRADED_3M")/10^6} -> 667.04992 | EQ7: =CU7/H7/$DV$2 -> #VALUE! | ER7: =_xlfn.RRI(2+$DT$2,$DT$2*(BC7)+(1-$DT$2)*(BD7),(BF7)) -> 0.28113523 | ES7: =ER7-EG7+EQ7 -> #VALUE! | EU7: =_xlfn.RRI(2+$DT$2,($DT$2*BY7+(1-$DT$2)*BZ7),CF7) -> #VALUE! | EV7: =EJ7-EU7 -> #VALUE! | FF7: 0.2 | FG7: -0.2 | FH7: =FF7-FG7 -> 0.4 | FI7: =FT7/CF7-1 -> 0.090909091 | FJ7: =FU7/CF7-1 -> -0.36363636 | FK7: =FI7-FJ7 -> 0.45454545 | FL7: =FF7+FG7 -> 0 | FM7: =FJ7+FI7 -> -0.27272727 | FN7: =EK7+FF7/3+FI7/3 -> #VALUE! | FO7: =EK7+FG7/3+FJ7/3 -> #VALUE! | FP7: =EK7+FL7/3+FM7/3 -> #VALUE! | FQ7: =EK7 -> #VALUE! | FR7: =FP7-FQ7 -> #VALUE! | FS7: =FN7-FO7 -> #VALUE! | FT7: 24 | FU7: 14
B8: MSFT US EQUITY | D8: MSFT | E8: 1 | F8: 46119 | H8: {=_xll.BQL($B8, "px_last", "dates=" & _xll.BQL.DATE($D$2))} -> #N/A Connection | I8: 7460 | J8: -89462 | K8: =40262+22865 -> 63127 | M8: =K8+J8 -> -26335 | N8: =I8*H8+M8+L8 -> #VALUE! | O8: 204094 | P8: 227582 | Q8: 261803 | R8: 305440 | S8: 356800.78 | T8: 418430.46 | U8: 491728.15 | V8: 575920.69 | W8: 670017.49 | X8: 0.6815977 | Y8: 0.69748486 | Z8: 0.69409059 | AA8: 0.68589248 | AB8: =AA8-0.25% -> 0.68339248 | AC8: =AB8-0.25% -> 0.68089248 | AD8: =AC8-0.25% -> 0.67839248 | AE8: =AD8-0.25% -> 0.67589248 | AF8: =AE8-0.25% -> 0.67339248 | AG8: =X8*O8 -> 139110 | AH8: =Y8*P8 -> 158735 | AI8: =Z8*Q8 -> 181715 | AJ8: =AA8*R8 -> 209499 | AK8: =AB8*S8 -> 243834.97 | AL8: =AC8*T8 -> 284906.16 | AM8: =AD8*U8 -> 333584.68 | AN8: =AE8*V8 -> 389260.47 | AO8: =AF8*W8 -> 451184.74 | AP8: 9.1199413 | AQ8: 11.056696 | AR8: 12.415501 | AS8: 15.949195 | AT8: 18.277836 | AU8: 21.13818 | AV8: 24.860954 | AW8: 30.196774 | AX8: 36.555023 | AY8: =AP8 -> 9.1199413 | AZ8: =AQ8 -> 11.056696 | BA8: =AR8 -> 12.415501 | BB8: =AS8 -> 15.949195 | BC8: =AT8 -> 18.277836 | BD8: =AU8 -> 21.13818 | BE8: =AV8 -> 24.860954 | BF8: =AW8 -> 30.196774 | BG8: =AX8 -> 36.555023 | BH8: =$N8/Q8 -> #VALUE! | BI8: =$N8/R8 -> #VALUE! | BJ8: =$N8/S8 -> #VALUE! | BK8: =$N8/T8 -> #VALUE! | BL8: =$N8/U8 -> #VALUE! | BM8: =$N8/V8 -> #VALUE! | BN8: =$N8/W8 -> #VALUE! | BO8: =$N8/AK8 -> #VALUE! | BP8: =$N8/AL8 -> #VALUE! | BQ8: =$N8/AM8 -> #VALUE! | BR8: =$N8/AN8 -> #VALUE! | BS8: =$N8/AO8 -> #VALUE! | BT8: =$H8/AT8 -> #VALUE! | BU8: =$H8/AU8 -> #VALUE! | BV8: =$H8/AV8 -> #VALUE! | BW8: =$H8/AW8 -> #VALUE! | BX8: =$H8/AX8 -> #VALUE! | BY8: =$H8/BC8 -> #VALUE! | BZ8: =$H8/BD8 -> #VALUE! | CA8: =$H8/BE8 -> #VALUE! | CB8: =$H8/BF8 -> #VALUE! | CC8: =$H8/BG8 -> #VALUE! | CD8: 24 | CE8: =CD8 -> 24 | CF8: =CE8 -> 24 | CG8: =CF8 -> 24 | CH8: =CG8 -> 24 | CN8: =CD8*BD8+CS8 -> 543.48941 | CO8: =CE8*BE8+CT8 -> 632.905 | CP8: =CF8*BF8+CU8 -> 761.24215 | CQ8: =CG8*BG8+CV8 -> 914.51529 | CS8: 36.173085 | CT8: 36.24212 | CU8: 36.51958 | CV8: 37.194743 | CW8: 38.054831 | DC8: 7464.1132 | DD8: 7449.8954 | DE8: 7393.2942 | DF8: 7259.0903 | DG8: 7095.0257 | DH8: -26335 | DI8: -26335 | DJ8: -26335 | DK8: -26335 | DL8: -26335 | DO8: 3.828 | DP8: 4.2108 | DQ8: 4.63188 | DR8: 5.095068 | DS8: 5.6045748 | DT8: =_xlfn.RRI(DT$2,$H8,CN8+$DO8*$DT$2) -> #VALUE! | DU8: =_xlfn.RRI(DU$2,$H8,CO8+$DO8*$DT$2+SUM($DP8:DP8)) -> #VALUE! | DV8: =_xlfn.RRI(DV$2,$H8,CP8+$DO8*$DT$2+SUM($DP8:DQ8)) -> #VALUE! | DW8: =_xlfn.RRI(DW$2,$H8,CQ8+$DO8*$DT$2+SUM($DP8:DR8)) -> #VALUE! | DX8: =SUM(CN8,$DO8:DO8)/$H8 -> #VALUE! | DY8: =SUM(CO8,$DO8:DP8)/$H8 -> #VALUE! | DZ8: =SUM(CP8,$DO8:DQ8)/$H8 -> #VALUE! | EA8: =SUM(CQ8,$DO8:DR8)/$H8 -> #VALUE! | EB8: {=_xll.BDP(""&$B8&"","CHG_PCT_1M")/100} -> -0.004974454 | EC8: {=_xll.BDP(""&$B8&"","CHG_PCT_3M")/100} -> 0.01001323 | ED8: {=_xll.BDP(""&$B8&"","CHG_PCT_6M")/100} -> -0.1587817 | EE8: =_xlfn.RRI(2+$DT$2,$DT$2*S8+(1-$DT$2)*T8,V8) -> 0.17165081 | EF8: =EG8-EE8 -> 0.0013687749 | EG8: =_xlfn.RRI(2+$DT$2,$DT$2*(BC8*DC8)+(1-$DT$2)*(BD8*DD8),(BF8*DF8)) -> 0.17301959 | EH8: =EI8-EG8 -> #VALUE! | EI8: =EK8-EJ8 -> #VALUE! | EJ8: =EU8 -> #VALUE! | EK8: =DV8 -> #VALUE! | EL8: =_xlfn.RRI(3,AK8,AN8) -> 0.16873155 | EM8: =_xlfn.RRI(3,BC8,BF8) -> 0.18216635 | EN8: {=_xll.BDP(B8,"AVG_DAILY_VALUE_TRADED_3M")/10^6} -> 14042.203 | EQ8: =IFERROR(AVERAGE(DP8:DQ8)/H8,0) -> 0 | ER8: =_xlfn.RRI(2+$DT$2,$DT$2*(BC8)+(1-$DT$2)*(BD8),(BF8)) -> 0.18543558 | ES8: =ER8-EG8+EQ8 -> 0.012415992 | EU8: =_xlfn.RRI(2+$DT$2,($DT$2*BY8+(1-$DT$2)*BZ8),CF8) -> #VALUE! | EV8: =EJ8-EU8 -> #VALUE! | FF8: 0.3 | FG8: -0.2 | FH8: =FF8-FG8 -> 0.5 | FI8: =FT8/CF8-1 -> 0.25 | FJ8: =FU8/CF8-1 -> -0.25 | FK8: =FI8-FJ8 -> 0.5 | FL8: =FF8+FG8 -> 0.1 | FM8: =FJ8+FI8 -> 0 | FN8: =EK8+FF8/3+FI8/3 -> #VALUE! | FO8: =EK8+FG8/3+FJ8/3 -> #VALUE! | FP8: =EK8+FL8/3+FM8/3 -> #VALUE! | FQ8: =EK8 -> #VALUE! | FR8: =FP8-FQ8 -> #VALUE! | FS8: =FN8-FO8 -> #VALUE! | FT8: 30 | FU8: 18
B9: SAP GY EQUITY | D9: SAP | E9: 1 | F9: 45688 | H9: {=_xll.BQL($B9, "px_last", "dates=" & _xll.BQL.DATE($D$2))} -> #N/A Connection | I9: 1169 | J9: -9609 | K9: =7169+4277 -> 11446 | M9: =K9+J9 -> 1837 | N9: =I9*H9+M9+L9 -> #VALUE! | O9: 29520 | P9: 31207 | Q9: 34176 | R9: 36800 | S9: 40273.14 | T9: 45307.135 | U9: 50851.13 | V9: 56381.116 | W9: 62355.58 | X9: =AG9/O9 -> 0.74261518 | Y9: =AH9/P9 -> 0.72429263 | Z9: =AI9/Q9 -> 0.73182935 | AA9: =AJ9/R9 -> 0.73764946 | AB9: =AK9/S9 -> 0.7380271 | AC9: =AL9/T9 -> 0.73982573 | AD9: =AM9/U9 -> 0.74211568 | AE9: =AN9/V9 -> 0.74533219 | AF9: =AO9/W9 -> 0.74935858 | AG9: 21922 | AH9: 22603 | AI9: 25011 | AJ9: 27145.5 | AK9: 29722.669 | AL9: 33519.384 | AM9: 37737.421 | AN9: 42022.661 | AO9: 46726.689 | AP9: 4.0161702 | AQ9: 3.6754237 | AR9: 4.479661 | AS9: 6.0991489 | AT9: 7.1545717 | AU9: 8.5750357 | AV9: 10.465866 | AW9: 12.432473 | AX9: 14.872587 | AY9: =AP9 -> 4.0161702 | AZ9: =AQ9 -> 3.6754237 | BA9: =AR9 -> 4.479661 | BB9: =AS9 -> 6.0991489 | BC9: =AT9 -> 7.1545717 | BD9: =AU9 -> 8.5750357 | BE9: =AV9 -> 10.465866 | BF9: =AW9 -> 12.432473 | BG9: =AX9 -> 14.872587 | BH9: =$N9/Q9 -> #VALUE! | BI9: =$N9/R9 -> #VALUE! | BJ9: =$N9/S9 -> #VALUE! | BK9: =$N9/T9 -> #VALUE! | BL9: =$N9/U9 -> #VALUE! | BM9: =$N9/V9 -> #VALUE! | BN9: =$N9/W9 -> #VALUE! | BO9: =$N9/AK9 -> #VALUE! | BP9: =$N9/AL9 -> #VALUE! | BQ9: =$N9/AM9 -> #VALUE! | BR9: =$N9/AN9 -> #VALUE! | BS9: =$N9/AO9 -> #VALUE! | BT9: =$H9/AT9 -> #VALUE! | BU9: =$H9/AU9 -> #VALUE! | BV9: =$H9/AV9 -> #VALUE! | BW9: =$H9/AW9 -> #VALUE! | BX9: =$H9/AX9 -> #VALUE! | BY9: =$H9/BC9 -> #VALUE! | BZ9: =$H9/BD9 -> #VALUE! | CA9: =$H9/BE9 -> #VALUE! | CB9: =$H9/BF9 -> #VALUE! | CC9: =$H9/BG9 -> #VALUE! | CD9: 22 | CE9: 22 | CF9: 22 | CG9: 22 | CH9: 24 | CN9: =CD9*BD9 -> 188.65079 | CO9: =CE9*BE9 -> 230.24906 | CP9: =CF9*BF9 -> 273.5144 | CQ9: =CG9*BG9 -> 327.19691 | CX9: =CN9*DC9+DH9 -> 220789.28 | CY9: =CO9*DD9+DI9 -> 263601.12 | CZ9: =CP9*DE9+DJ9 -> 305681.97 | DA9: =CQ9*DF9+DK9 -> 356154.29 | DC9: 1160.6221 | DD9: 1136.8738 | DE9: 1110.892 | DF9: 1082.887 | DG9: 1053.2432 | DH9: =$M$9 -> 1837 | DI9: =$M$9 -> 1837 | DJ9: =$M$9 -> 1837 | DK9: =$M$9 -> 1837 | DL9: =$M$9 -> 1837 | DO9: 2.8618287 | DP9: 3.4300143 | DQ9: 4.1863466 | DR9: 4.9729891 | DS9: 5.9490347 | DT9: =_xlfn.RRI(DT$2,$H9,CN9+$DO9*$DT$2) -> #VALUE! | DU9: =_xlfn.RRI(DU$2,$H9,CO9+$DO9*$DT$2+SUM($DP9:DP9)) -> #VALUE! | DV9: =_xlfn.RRI(DV$2,$H9,CP9+$DO9*$DT$2+SUM($DP9:DQ9)) -> #VALUE! | DW9: =_xlfn.RRI(DW$2,$H9,CQ9+$DO9*$DT$2+SUM($DP9:DR9)) -> #VALUE! | DX9: =SUM(CN9,$DO9:DO9)/$H9 -> #VALUE! | DY9: =SUM(CO9,$DO9:DP9)/$H9 -> #VALUE! | DZ9: =SUM(CP9,$DO9:DQ9)/$H9 -> #VALUE! | EA9: =SUM(CQ9,$DO9:DR9)/$H9 -> #VALUE! | EB9: {=_xll.BDP(""&$B9&"","CHG_PCT_1M")/100} -> 0.08454175 | EC9: {=_xll.BDP(""&$B9&"","CHG_PCT_3M")/100} -> -0.08208872 | ED9: {=_xll.BDP(""&$B9&"","CHG_PCT_6M")/100} -> -0.2453118 | EE9: =_xlfn.RRI(2+$DT$2,$DT$2*S9+(1-$DT$2)*T9,V9) -> 0.11684576 | EF9: =EG9-EE9 -> 0.056599069 | EG9: =_xlfn.RRI(2+$DT$2,$DT$2*(BC9*DC9)+(1-$DT$2)*(BD9*DD9),(BF9*DF9)) -> 0.17344483 | EH9: =EI9-EG9 -> 0.027524659 | EI9: =ER9+EQ9 -> 0.20096949 | EJ9: =EK9-EI9 -> #VALUE! | EK9: =DV9 -> #VALUE! | EL9: =_xlfn.RRI(3,AK9,AN9) -> 0.12235932 | EM9: =_xlfn.RRI(3,BC9,BF9) -> 0.20224032 | EN9: {=_xll.BDP(B9,"AVG_DAILY_VALUE_TRADED_3M")/10^6} -> 476.4628 | EQ9: =IFERROR(AVERAGE(DP9:DQ9)/H9,0) -> 0 | ER9: =_xlfn.RRI(2+$DT$2,$DT$2*(BC9)+(1-$DT$2)*(BD9),(BF9)) -> 0.20096949 | ES9: =ER9-EG9+EQ9 -> 0.027524659 | EU9: =_xlfn.RRI(2+$DT$2,($DT$2*BY9+(1-$DT$2)*BZ9),CF9) -> #VALUE! | EV9: =EJ9-EU9 -> #VALUE! | FF9: 0.1 | FG9: -0.1 | FH9: =FF9-FG9 -> 0.2 | FI9: =FT9/CF9-1 -> 0.27272727 | FJ9: =FU9/CF9-1 -> -0.27272727 | FK9: =FI9-FJ9 -> 0.54545455 | FL9: =FF9+FG9 -> 0 | FM9: =FJ9+FI9 -> 0 | FN9: =EK9+FF9/3+FI9/3 -> #VALUE! | FO9: =EK9+FG9/3+FJ9/3 -> #VALUE! | FP9: =EK9+FL9/3+FM9/3 -> #VALUE! | FQ9: =EK9 -> #VALUE! | FR9: =FP9-FQ9 -> #VALUE! | FS9: =FN9-FO9 -> #VALUE! | FT9: 28 | FU9: 16 | FV9: Set Mendo EPS = adj EPS (SBC ~5% revs)
B10: META US EQUITY | D10: META | E10: 1 | F10: 46163 | H10: {=_xll.BQL($B10, "px_last", "dates=" & _xll.BQL.DATE($D$2))} -> #N/A Connection | I10: 2573.7761 | J10: -84819 | K10: 85081 | M10: =K10+J10 -> 262 | N10: =I10*H10+M10+L10 -> #VALUE! | O10: 116608 | P10: 134902 | Q10: 164500 | R10: 200965 | S10: 245901.56 | T10: 290756.51 | U10: 334809.81 | V10: 378121.6 | W10: 419230.59 | AG10: =X10*O10 -> 0 | AH10: =Y10*P10 -> 0 | AI10: =Z10*Q10 -> 0 | AJ10: =AA10*R10 -> 0 | AK10: =AB10*S10 -> 0 | AL10: =AC10*T10 -> 0 | AM10: =AD10*U10 -> 0 | AN10: =AE10*V10 -> 0 | AO10: =AF10*W10 -> 0 | AP10: 10.440785 | AQ10: 16.379135 | AR10: 24.207034 | AS10: 29.015803 | AT10: 28.213866 | AU10: 33.053023 | AV10: 42.085773 | AW10: 52.931226 | AX10: 63.198373 | AY10: 10.440785 | AZ10: 16.379135 | BA10: 24.207034 | BB10: 29.015803 | BC10: 28.213866 | BD10: 33.053023 | BE10: 42.085773 | BF10: 52.931226 | BG10: 63.198373 | BH10: =$N10/Q10 -> #VALUE! | BI10: =$N10/R10 -> #VALUE! | BJ10: =$N10/S10 -> #VALUE! | BK10: =$N10/T10 -> #VALUE! | BL10: =$N10/U10 -> #VALUE! | BM10: =$N10/V10 -> #VALUE! | BN10: =$N10/W10 -> #VALUE! | BO10: =IFERROR($N10/AK10,"n/a") -> n/a | BP10: =IFERROR($N10/AL10,"n/a") -> n/a | BQ10: =IFERROR($N10/AM10,"n/a") -> n/a | BR10: =IFERROR($N10/AN10,"n/a") -> n/a | BS10: =IFERROR($N10/AO10,"n/a") -> n/a | BT10: =$H10/AT10 -> #VALUE! | BU10: =$H10/AU10 -> #VALUE! | BV10: =$H10/AV10 -> #VALUE! | BW10: =$H10/AW10 -> #VALUE! | BX10: =$H10/AX10 -> #VALUE! | BY10: =$H10/BC10 -> #VALUE! | BZ10: =$H10/BD10 -> #VALUE! | CA10: =$H10/BE10 -> #VALUE! | CB10: =$H10/BF10 -> #VALUE! | CC10: =$H10/BG10 -> #VALUE! | CD10: 19 | CE10: 19 | CF10: 19 | CG10: 19 | CH10: 20 | CN10: =CD10*BD10 -> 628.00744 | CO10: =CE10*BE10 -> 799.62969 | CP10: =CF10*BF10 -> 1005.6933 | CQ10: =CG10*BG10 -> 1200.7691 | DC10: 2573.7761 | DD10: 2573.7761 | DE10: 2508.1621 | DF10: 2422.9536 | DG10: 2332.756 | DO10: 2.205 | DP10: 2.31525 | DQ10: 2.4310125 | DR10: 2.5525631 | DS10: 2.6801913 | DT10: =_xlfn.RRI(DT$2,$H10,CN10+$DO10*$DT$2) -> #VALUE! | DU10: =_xlfn.RRI(DU$2,$H10,CO10+$DO10*$DT$2+SUM($DP10:DP10)) -> #VALUE! | DV10: =_xlfn.RRI(DV$2,$H10,CP10+$DO10*$DT$2+SUM($DP10:DQ10)) -> #VALUE! | DW10: =_xlfn.RRI(DW$2,$H10,CQ10+$DO10*$DT$2+SUM($DP10:DR10)) -> #VALUE! | DX10: =SUM(CN10,$DO10:DO10)/$H10 -> #VALUE! | DY10: =SUM(CO10,$DO10:DP10)/$H10 -> #VALUE! | DZ10: =SUM(CP10,$DO10:DQ10)/$H10 -> #VALUE! | EA10: =SUM(CQ10,$DO10:DR10)/$H10 -> #VALUE! | EB10: {=_xll.BDP(""&$B10&"","CHG_PCT_1M")/100} -> -0.03228188 | EC10: {=_xll.BDP(""&$B10&"","CHG_PCT_3M")/100} -> -0.08515024 | ED10: {=_xll.BDP(""&$B10&"","CHG_PCT_6M")/100} -> -0.1152519 | EE10: =_xlfn.RRI(2+$DT$2,$DT$2*S10+(1-$DT$2)*T10,V10) -> 0.14787172 | EF10: =EG10-EE10 -> 0.065956756 | EG10: =_xlfn.RRI(2+$DT$2,$DT$2*(BC10*DC10)+(1-$DT$2)*(BD10*DD10),(BF10*DF10)) -> 0.21382847 | EH10: =EI10-EG10 -> 0.028985448 | EI10: =ER10+EQ10 -> 0.24281392 | EJ10: =EK10-EI10 -> #VALUE! | EK10: =DV10 -> #VALUE! | EL10: =_xlfn.RRI(3,AK10,AN10) -> 0 | EM10: =_xlfn.RRI(3,BC10,BF10) -> 0.23334085 | EN10: {=_xll.BDP(B10,"AVG_DAILY_VALUE_TRADED_3M")/10^6} -> 10224.256 | EQ10: =IFERROR(AVERAGE(DP10:DQ10)/H10,0) -> 0 | ER10: =_xlfn.RRI(2+$DT$2,$DT$2*(BC10)+(1-$DT$2)*(BD10),(BF10)) -> 0.24281392 | ES10: =ER10-EG10+EQ10 -> 0.028985448 | EU10: =_xlfn.RRI(2+$DT$2,($DT$2*BY10+(1-$DT$2)*BZ10),CF10) -> #VALUE! | EV10: =EJ10-EU10 -> #VALUE! | FF10: 0.25 | FG10: -0.25 | FN10: x | FO10: x | FP10: x | FQ10: x | FR10: x | FS10: x | FV10: Core EPS Only
B11: AMZN US EQUITY | D11: AMZN | E11: 1 | F11: 46120 | H11: {=_xll.BQL($B11, "px_last", "dates=" & _xll.BQL.DATE($D$2))} -> #N/A Connection | I11: 10827 | J11: -123329 | K11: 178547 | M11: =K11+J11 -> 55218 | N11: =I11*H11+M11+L11 -> #VALUE! | O11: 513983 | P11: 574785 | Q11: 637959 | R11: 716924 | S11: 817469.18 | T11: 928320.74 | U11: 1044416 | V11: 1153879.7 | W11: 1265801 | X11: =AG11/O11 -> 0.4380534 | Y11: =AH11/P11 -> 0.46982089 | Z11: =AI11/Q11 -> 0.48854393 | AA11: =AJ11/R11 -> 0.50285665 | AB11: =AK11/S11 -> 0.52586233 | AC11: =AL11/T11 -> 0.54940611 | AD11: =AM11/U11 -> 0.56879977 | AE11: =AN11/V11 -> 0.58047854 | AF11: =AO11/W11 -> 0.58999333 | AG11: 225152 | AH11: 270046 | AI11: 311671 | AJ11: 360510 | AK11: 429876.24 | AL11: 510025.09 | AM11: 594063.59 | AN11: 669802.4 | AO11: 746814.14 | AP11: -0.26715085 | AQ11: 2.8998284 | AR11: 5.5263502 | AS11: 7.1737323 | AT11: 7.3680359 | AU11: 9.512152 | AV11: 12.252122 | AW11: 15.255782 | AX11: 19.175997 | AY11: 1.3825694 | AZ11: 2.8115707 | BA11: 5.7456394 | BB11: 5.8183246 | BC11: 7.3680359 | BD11: 9.512152 | BE11: 12.252122 | BF11: 15.255782 | BG11: 19.175997 | BH11: =$N11/Q11 -> #VALUE! | BI11: =$N11/R11 -> #VALUE! | BJ11: =$N11/S11 -> #VALUE! | BK11: =$N11/T11 -> #VALUE! | BL11: =$N11/U11 -> #VALUE! | BM11: =$N11/V11 -> #VALUE! | BN11: =$N11/W11 -> #VALUE! | BO11: =$N11/AK11 -> #VALUE! | BP11: =$N11/AL11 -> #VALUE! | BQ11: =$N11/AM11 -> #VALUE! | BR11: =$N11/AN11 -> #VALUE! | BS11: =$N11/AO11 -> #VALUE! | BT11: =$H11/AT11 -> #VALUE! | BU11: =$H11/AU11 -> #VALUE! | BV11: =$H11/AV11 -> #VALUE! | BW11: =$H11/AW11 -> #VALUE! | BX11: =$H11/AX11 -> #VALUE! | BY11: =$H11/BC11 -> #VALUE! | BZ11: =$H11/BD11 -> #VALUE! | CA11: =$H11/BE11 -> #VALUE! | CB11: =$H11/BF11 -> #VALUE! | CC11: =$H11/BG11 -> #VALUE! | CD11: 26 | CE11: 26 | CF11: 26 | CG11: 26 | CH11: 24 | CN11: =CD11*BD11 -> 247.31595 | CO11: =CE11*BE11 -> 318.55518 | CP11: =CF11*BF11 -> 396.65032 | CQ11: =CG11*BG11 -> 498.57591 | DC11: 10827 | DD11: 10788.313 | DE11: 10587.029 | DF11: 10192.759 | DG11: 9738.2353 | DT11: =_xlfn.RRI(DT$2,$H11,CN11+$DO11*$DT$2) -> #VALUE! | DU11: =_xlfn.RRI(DU$2,$H11,CO11+$DO11*$DT$2+SUM($DP11:DP11)) -> #VALUE! | DV11: =_xlfn.RRI(DV$2,$H11,CP11+$DO11*$DT$2+SUM($DP11:DQ11)) -> #VALUE! | DW11: =_xlfn.RRI(DW$2,$H11,CQ11+$DO11*$DT$2+SUM($DP11:DR11)) -> #VALUE! | DX11: =SUM(CN11,$DO11:DO11)/$H11 -> #VALUE! | DY11: =SUM(CO11,$DO11:DP11)/$H11 -> #VALUE! | DZ11: =SUM(CP11,$DO11:DQ11)/$H11 -> #VALUE! | EA11: =SUM(CQ11,$DO11:DR11)/$H11 -> #VALUE! | EB11: {=_xll.BDP(""&$B11&"","CHG_PCT_1M")/100} -> -0.0941763 | EC11: {=_xll.BDP(""&$B11&"","CHG_PCT_3M")/100} -> 0.1584822 | ED11: {=_xll.BDP(""&$B11&"","CHG_PCT_6M")/100} -> 0.08863326 | EE11: =_xlfn.RRI(2+$DT$2,$DT$2*S11+(1-$DT$2)*T11,V11) -> 0.11850465 | EF11: =EG11-EE11 -> 0.12054217 | EG11: =_xlfn.RRI(2+$DT$2,$DT$2*(BC11*DC11)+(1-$DT$2)*(BD11*DD11),(BF11*DF11)) -> 0.23904682 | EH11: =EI11-EG11 -> 0.028682545 | EI11: =ER11+EQ11 -> 0.26772937 | EJ11: =EK11-EI11 -> #VALUE! | EK11: =DV11 -> #VALUE! | EL11: =_xlfn.RRI(3,AK11,AN11) -> 0.15931401 | EM11: =_xlfn.RRI(3,BC11,BF11) -> 0.27456184 | EN11: {=_xll.BDP(B11,"AVG_DAILY_VALUE_TRADED_3M")/10^6} -> 10871.718 | EQ11: =IFERROR(AVERAGE(DP11:DQ11)/H11,0) -> 0 | ER11: =_xlfn.RRI(2+$DT$2,$DT$2*(BC11)+(1-$DT$2)*(BD11),(BF11)) -> 0.26772937 | ES11: =ER11-EG11+EQ11 -> 0.028682545 | EU11: =_xlfn.RRI(2+$DT$2,($DT$2*BY11+(1-$DT$2)*BZ11),CF11) -> #VALUE! | EV11: =EJ11-EU11 -> #VALUE! | EX11: 7.3668545 | EY11: 9.541088 | EZ11: 11.93265 | FA11: 14.251233 | FB11: =BC11/EX11-1 -> 0.00016036555 | FC11: =BD11/EY11-1 -> -0.0030327757 | FD11: =BE11/EZ11-1 -> 0.026772975 | FE11: =BF11/FA11-1 -> 0.070488537 | FF11: 0.2 | FG11: -0.1 | FH11: =FF11-FG11 -> 0.3 | FI11: =FT11/CF11-1 -> 0.26923077 | FJ11: =FU11/CF11-1 -> -0.23076923 | FK11: =FI11-FJ11 -> 0.5 | FL11: =FF11+FG11 -> 0.1 | FM11: =FJ11+FI11 -> 0.038461538 | FN11: =EK11+FF11/3+FI11/3 -> #VALUE! | FO11: =EK11+FG11/3+FJ11/3 -> #VALUE! | FP11: =EK11+FL11/3+FM11/3 -> #VALUE! | FQ11: =EK11 -> #VALUE! | FR11: =FP11-FQ11 -> #VALUE! | FS11: =FN11-FO11 -> #VALUE! | FT11: 33 | FU11: 20
B12: 2330 TT EQUITY | D12: TSMC | F12: 46140 | H12: {=_xll.BQL($B12, "px_last", "dates=" & _xll.BQL.DATE($D$2))} -> #N/A Connection | I12: 25930 | J12: -3192142.3 | K12: 1036072.4 | M12: =K12+J12 -> -2156069.9 | N12: =I12*H12+M12+L12 -> #VALUE! | O12: 2263891.3 | P12: 2161735.8 | Q12: 2894307.7 | R12: 3809054.3 | S12: 5039894.5 | T12: 6594728.5 | U12: 8633128.7 | V12: 10355421 | W12: 12283063 | X12: =AG12/O12 -> 0.59559167 | Y12: =AH12/P12 -> 0.54359585 | Z12: =AI12/Q12 -> 0.56122352 | AA12: =AJ12/R12 -> 0.59891349 | AB12: =AK12/S12 -> 0.66920044 | AC12: =AL12/T12 -> 0.66322768 | AD12: =AM12/U12 -> 0.65343679 | AE12: =AN12/V12 -> 0.62939631 | AF12: =AO12/W12 -> 0.61454739 | AG12: 1348354.8 | AH12: 1175110.6 | AI12: 1624353.6 | AJ12: 2281294 | AK12: 3372699.6 | AL12: 4373806.4 | AM12: 5641203.9 | AN12: 6517663.5 | AO12: 7548524.5 | AP12: 39.204375 | AQ12: 32.338218 | AR12: 45.247501 | AS12: 66.248221 | AT12: 94.04858 | AU12: 122.02141 | AV12: 157.5557 | AW12: 182.32036 | AX12: 211.90932 | AY12: =AP12 -> 39.204375 | AZ12: =AQ12 -> 32.338218 | BA12: =AR12 -> 45.247501 | BB12: =AS12 -> 66.248221 | BC12: =AT12 -> 94.04858 | BD12: =AU12 -> 122.02141 | BE12: =AV12 -> 157.5557 | BF12: =AW12 -> 182.32036 | BG12: =AX12 -> 211.90932 | BH12: =$N12/Q12 -> #VALUE! | BI12: =$N12/R12 -> #VALUE! | BJ12: =$N12/S12 -> #VALUE! | BK12: =$N12/T12 -> #VALUE! | BL12: =$N12/U12 -> #VALUE! | BM12: =$N12/V12 -> #VALUE! | BN12: =$N12/W12 -> #VALUE! | BO12: =$N12/AK12 -> #VALUE! | BP12: =$N12/AL12 -> #VALUE! | BQ12: =$N12/AM12 -> #VALUE! | BR12: =$N12/AN12 -> #VALUE! | BS12: =$N12/AO12 -> #VALUE! | BT12: =$H12/AT12 -> #VALUE! | BU12: =$H12/AU12 -> #VALUE! | BV12: =$H12/AV12 -> #VALUE! | BW12: =$H12/AW12 -> #VALUE! | BX12: =$H12/AX12 -> #VALUE! | BY12: =$H12/BC12 -> #VALUE! | BZ12: =$H12/BD12 -> #VALUE! | CA12: =$H12/BE12 -> #VALUE! | CB12: =$H12/BF12 -> #VALUE! | CC12: =$H12/BG12 -> #VALUE! | CD12: 20 | CE12: 20 | CF12: 20 | CG12: 20 | CH12: 18 | CN12: =CD12*BD12+CS12 -> 2558.166 | CO12: =CE12*BE12+CT12 -> 3322.4769 | CP12: =CF12*BF12+CU12 -> 3888.5981 | CQ12: =CG12*BG12+CV12 -> 4566.6877 | CS12: 117.73782 | CT12: 171.36295 | CU12: 242.19095 | CV12: 328.50126 | CW12: 431.59469 | DC12: 25931 | DD12: 25931 | DE12: 25931 | DF12: 25931 | DG12: 25931 | DO12: 22.501022 | DP12: 28.126277 | DQ12: 35.157847 | DR12: 43.947308 | DS12: 54.934135 | DT12: =_xlfn.RRI(DT$2,$H12,CN12+$DO12*$DT$2) -> #VALUE! | DU12: =_xlfn.RRI(DU$2,$H12,CO12+$DO12*$DT$2+SUM($DP12:DP12)) -> #VALUE! | DV12: =_xlfn.RRI(DV$2,$H12,CP12+$DO12*$DT$2+SUM($DP12:DQ12)) -> #VALUE! | DW12: =_xlfn.RRI(DW$2,$H12,CQ12+$DO12*$DT$2+SUM($DP12:DR12)) -> #VALUE! | DX12: =SUM(CN12,$DO12:DO12)/$H12 -> #VALUE! | DY12: =SUM(CO12,$DO12:DP12)/$H12 -> #VALUE! | DZ12: =SUM(CP12,$DO12:DQ12)/$H12 -> #VALUE! | EA12: =SUM(CQ12,$DO12:DR12)/$H12 -> #VALUE! | EB12: {=_xll.BDP(""&$B12&"","CHG_PCT_1M")/100} -> 0.002183406 | EC12: {=_xll.BDP(""&$B12&"","CHG_PCT_3M")/100} -> 0.2142857 | ED12: {=_xll.BDP(""&$B12&"","CHG_PCT_6M")/100} -> 0.5351171 | EE12: =_xlfn.RRI(2+$DT$2,$DT$2*S12+(1-$DT$2)*T12,V12) -> 0.26056547 | EF12: =EG12-EE12 -> -0.02625594 | EG12: =_xlfn.RRI(2+$DT$2,$DT$2*(BC12*DC12)+(1-$DT$2)*(BD12*DD12),(BF12*DF12)) -> 0.23430953 | EH12: =EI12-EG12 -> #VALUE! | EI12: =ER12+EQ12 -> #VALUE! | EJ12: =EK12-EI12 -> #VALUE! | EK12: =DV12 -> #VALUE! | EL12: =_xlfn.RRI(3,AK12,AN12) -> 0.24557942 | EM12: =_xlfn.RRI(3,BC12,BF12) -> 0.24688856 | EN12: {=_xll.BDP(B12,"AVG_DAILY_VALUE_TRADED_3M")/10^6} -> 88790.61 | EQ12: =CU12/H12/$DV$2 -> #VALUE! | ER12: =_xlfn.RRI(2+$DT$2,$DT$2*(BC12)+(1-$DT$2)*(BD12),(BF12)) -> 0.23430953 | ES12: =ER12-EG12+EQ12 -> #VALUE! | EU12: =_xlfn.RRI(2+$DT$2,($DT$2*BY12+(1-$DT$2)*BZ12),CF12) -> #VALUE! | EV12: =EJ12-EU12 -> #VALUE! | FN12: x | FO12: x | FP12: x | FQ12: x | FR12: x | FS12: x
B13: GOOG US EQUITY | D13: GOOG | E13: 2 | F13: 46120 | H13: {=_xll.BQL($B13, "px_last", "dates=" & _xll.BQL.DATE($D$2))} -> #N/A Connection | I13: 12230 | J13: -126843 | K13: 66967 | M13: =K13+J13 -> -59876 | N13: =I13*H13+M13+L13 -> #VALUE! | O13: 282836 | P13: 307394 | Q13: 350018 | R13: 402836 | S13: 474201.19 | T13: 547000.07 | U13: 627861.63 | V13: 715818.21 | W13: 803490.68 | X13: =AG13/O13 -> 0.55379443 | Y13: =AH13/P13 -> 0.56625048 | Z13: =AI13/Q13 -> 0.58200435 | AA13: =AJ13/R13 -> 0.59652315 | AB13: =AK13/S13 -> 0.60130017 | AC13: =AL13/T13 -> 0.60309319 | AD13: =AM13/U13 -> 0.60681934 | AE13: =AN13/V13 -> 0.61614806 | AF13: =AO13/W13 -> 0.62285471 | AG13: 156633 | AH13: 174062 | AI13: 203712 | AJ13: 240301 | AK13: 285137.25 | AL13: 329892.01 | AM13: 380998.59 | AN13: 441050 | AO13: 500457.95 | AP13: 4.5574892 | AQ13: 5.8005817 | AR13: 8.0435446 | AS13: 10.807032 | AT13: 10.430843 | AU13: 12.047233 | AV13: 14.174341 | AW13: 17.360857 | AX13: 20.696308 | AY13: 4.9626111 | AZ13: 5.968244 | BA13: 7.7855708 | BB13: 8.6659035 | BC13: 10.430843 | BD13: 12.047233 | BE13: 14.174341 | BF13: 17.360857 | BG13: 20.696308 | BH13: =$N13/Q13 -> #VALUE! | BI13: =$N13/R13 -> #VALUE! | BJ13: =$N13/S13 -> #VALUE! | BK13: =$N13/T13 -> #VALUE! | BL13: =$N13/U13 -> #VALUE! | BM13: =$N13/V13 -> #VALUE! | BN13: =$N13/W13 -> #VALUE! | BO13: =$N13/AK13 -> #VALUE! | BP13: =$N13/AL13 -> #VALUE! | BQ13: =$N13/AM13 -> #VALUE! | BR13: =$N13/AN13 -> #VALUE! | BS13: =$N13/AO13 -> #VALUE! | BT13: =$H13/AT13 -> #VALUE! | BU13: =$H13/AU13 -> #VALUE! | BV13: =$H13/AV13 -> #VALUE! | BW13: =$H13/AW13 -> #VALUE! | BX13: =$H13/AX13 -> #VALUE! | BY13: =$H13/BC13 -> #VALUE! | BZ13: =$H13/BD13 -> #VALUE! | CA13: =$H13/BE13 -> #VALUE! | CB13: =$H13/BF13 -> #VALUE! | CC13: =$H13/BG13 -> #VALUE! | CD13: 24 | CE13: 24 | CF13: 24 | CG13: 24 | CH13: 24 | CN13: =CD13*BD13 -> 289.13359 | CO13: =CE13*BE13 -> 340.18418 | CP13: =CF13*BF13 -> 416.66057 | CQ13: =CG13*BG13 -> 496.71138 | DC13: 12230 | DD13: 12230 | DE13: 12155.112 | DF13: 11921.29 | DG13: 11635.202 | DO13: 0.83 | DP13: 0.83 | DQ13: 0.83 | DR13: 0.83 | DS13: 0.83 | DT13: =_xlfn.RRI(DT$2,$H13,CN13+$DO13*$DT$2) -> #VALUE! | DU13: =_xlfn.RRI(DU$2,$H13,CO13+$DO13*$DT$2+SUM($DP13:DP13)) -> #VALUE! | DV13: =_xlfn.RRI(DV$2,$H13,CP13+$DO13*$DT$2+SUM($DP13:DQ13)) -> #VALUE! | DW13: =_xlfn.RRI(DW$2,$H13,CQ13+$DO13*$DT$2+SUM($DP13:DR13)) -> #VALUE! | DX13: =SUM(CN13,$DO13:DO13)/$H13 -> #VALUE! | DY13: =SUM(CO13,$DO13:DP13)/$H13 -> #VALUE! | DZ13: =SUM(CP13,$DO13:DQ13)/$H13 -> #VALUE! | EA13: =SUM(CQ13,$DO13:DR13)/$H13 -> #VALUE! | EB13: {=_xll.BDP(""&$B13&"","CHG_PCT_1M")/100} -> -0.0941191 | EC13: {=_xll.BDP(""&$B13&"","CHG_PCT_3M")/100} -> 0.2057661 | ED13: {=_xll.BDP(""&$B13&"","CHG_PCT_6M")/100} -> 0.1438384 | EE13: =_xlfn.RRI(2+$DT$2,$DT$2*S13+(1-$DT$2)*T13,V13) -> 0.14490369 | EF13: =EG13-EE13 -> 0.032438938 | EG13: =_xlfn.RRI(2+$DT$2,$DT$2*(BC13*DC13)+(1-$DT$2)*(BD13*DD13),(BF13*DF13)) -> 0.17734262 | EH13: =EI13-EG13 -> 0.011821827 | EI13: =ER13+EQ13 -> 0.18916445 | EJ13: =EK13-EI13 -> #VALUE! | EK13: =DV13 -> #VALUE! | EL13: =_xlfn.RRI(3,AK13,AN13) -> 0.1564973 | EM13: =_xlfn.RRI(3,BC13,BF13) -> 0.18508797 | EN13: {=_xll.BDP(B13,"AVG_DAILY_VALUE_TRADED_3M")/10^6} -> 6855.36 | EQ13: =IFERROR(AVERAGE(DP13:DQ13)/H13,0) -> 0 | ER13: =_xlfn.RRI(2+$DT$2,$DT$2*(BC13)+(1-$DT$2)*(BD13),(BF13)) -> 0.18916445 | ES13: =ER13-EG13+EQ13 -> 0.011821827 | EU13: =_xlfn.RRI(2+$DT$2,($DT$2*BY13+(1-$DT$2)*BZ13),CF13) -> #VALUE! | EV13: =EJ13-EU13 -> #VALUE! | EX13: 11.031304 | EY13: 14.359029 | EZ13: 16.630616 | FA13: 18.821076 | FB13: =BC13/EX13-1 -> -0.054432497 | FC13: =BD13/EY13-1 -> -0.16099945 | FD13: =BE13/EZ13-1 -> -0.14769599 | FE13: =BF13/FA13-1 -> -0.077584258 | FF13: 0.2 | FG13: -0.25 | FH13: =FF13-FG13 -> 0.45 | FI13: =FT13/CF13-1 -> 0.25 | FJ13: =FU13/CF13-1 -> -0.25 | FK13: =FI13-FJ13 -> 0.5 | FL13: =FF13+FG13 -> -0.05 | FM13: =FJ13+FI13 -> 0 | FN13: =EK13+FF13/3+FI13/3 -> #VALUE! | FO13: =EK13+FG13/3+FJ13/3 -> #VALUE! | FP13: =EK13+FL13/3+FM13/3 -> #VALUE! | FQ13: =EK13 -> #VALUE! | FR13: =FP13-FQ13 -> #VALUE! | FS13: =FN13-FO13 -> #VALUE! | FT13: 30 | FU13: 18
B14: ORCL US EQUITY | D14: ORCL | E14: 2 | F14: 46176 | H14: {=_xll.BQL($B14, "px_last", "dates=" & _xll.BQL.DATE($D$2))} -> #N/A Connection | I14: 2922 | J14: -39132 | K14: 153117 | L14: 506 | M14: =K14+J14 -> 113985 | N14: =I14*H14+M14+L14 -> #VALUE! | O14: 45821.3 | P14: 51307.15 | Q14: 54958.1 | R14: 61719.45 | S14: 75204.625 | T14: 104489.41 | U14: 142360.79 | V14: 175595.92 | W14: 205597.03 | X14: =AG14/O14 -> 0 | Y14: =AH14/P14 -> 0 | Z14: =AI14/Q14 -> 0 | AA14: =AJ14/R14 -> 0 | AB14: =AK14/S14 -> 0 | AC14: =AL14/T14 -> 0 | AD14: =AM14/U14 -> 0 | AE14: =AN14/V14 -> 0 | AF14: =AO14/W14 -> 0 | AP14: 5.0031859 | AQ14: 5.3230505 | AR14: 5.7745681 | AS14: 6.454935 | AT14: 7.2746091 | AU14: 8.8268237 | AV14: 11.433058 | AW14: 14.568182 | AX14: 18.169251 | AY14: 4.0882316 | AZ14: 4.2208092 | BA14: 4.5594142 | BB14: 5.0951717 | BC14: 5.7413934 | BD14: 6.8261649 | BE14: 8.8185383 | BF14: 11.461698 | BG14: 14.573029 | BH14: =$N14/Q14 -> #VALUE! | BI14: =$N14/R14 -> #VALUE! | BJ14: =$N14/S14 -> #VALUE! | BK14: =$N14/T14 -> #VALUE! | BL14: =$N14/U14 -> #VALUE! | BM14: =$N14/V14 -> #VALUE! | BN14: =$N14/W14 -> #VALUE! | BO14: =IFERROR($N14/AK14,"n/a") -> n/a | BP14: =IFERROR($N14/AL14,"n/a") -> n/a | BQ14: =IFERROR($N14/AM14,"n/a") -> n/a | BR14: =IFERROR($N14/AN14,"n/a") -> n/a | BS14: =IFERROR($N14/AO14,"n/a") -> n/a | BT14: =$H14/AT14 -> #VALUE! | BU14: =$H14/AU14 -> #VALUE! | BV14: =$H14/AV14 -> #VALUE! | BW14: =$H14/AW14 -> #VALUE! | BX14: =$H14/AX14 -> #VALUE! | BY14: =$H14/BC14 -> #VALUE! | BZ14: =$H14/BD14 -> #VALUE! | CA14: =$H14/BE14 -> #VALUE! | CB14: =$H14/BF14 -> #VALUE! | CC14: =$H14/BG14 -> #VALUE! | CD14: 22 | CE14: 22 | CF14: 22 | CG14: 22 | CH14: 27 | CN14: =CD14*BD14 -> 150.17563 | CO14: =CE14*BE14 -> 194.00784 | CP14: =CF14*BF14 -> 252.15737 | CQ14: =CG14*BG14 -> 320.60664 | DC14: 2896.1304 | DD14: 2996.4985 | DE14: 3130.2032 | DF14: 3251.6731 | DG14: 3293.9439 | DO14: 2.1218486 | DP14: 2.2227497 | DQ14: 2.6178339 | DR14: 2.9650544 | DS14: 3.2721282 | DT14: =_xlfn.RRI(DT$2,$H14,CN14+$DO14*$DT$2) -> #VALUE! | DU14: =_xlfn.RRI(DU$2,$H14,CO14+$DO14*$DT$2+SUM($DP14:DP14)) -> #VALUE! | DV14: =_xlfn.RRI(DV$2,$H14,CP14+$DO14*$DT$2+SUM($DP14:DQ14)) -> #VALUE! | DW14: =_xlfn.RRI(DW$2,$H14,CQ14+$DO14*$DT$2+SUM($DP14:DR14)) -> #VALUE! | DX14: =SUM(CN14,$DO14:DO14)/$H14 -> #VALUE! | DY14: =SUM(CO14,$DO14:DP14)/$H14 -> #VALUE! | DZ14: =SUM(CP14,$DO14:DQ14)/$H14 -> #VALUE! | EA14: =SUM(CQ14,$DO14:DR14)/$H14 -> #VALUE! | EB14: {=_xll.BDP(""&$B14&"","CHG_PCT_1M")/100} -> 0.09282982 | EC14: {=_xll.BDP(""&$B14&"","CHG_PCT_3M")/100} -> 0.3999738 | ED14: {=_xll.BDP(""&$B14&"","CHG_PCT_6M")/100} -> -0.02901965 | EE14: =_xlfn.RRI(2+$DT$2,$DT$2*S14+(1-$DT$2)*T14,V14) -> 0.30922689 | EF14: =EG14-EE14 -> 0.010764702 | EG14: =_xlfn.RRI(2+$DT$2,$DT$2*(BC14*DC14)+(1-$DT$2)*(BD14*DD14),(BF14*DF14)) -> 0.3199916 | EH14: =EI14-EG14 -> -0.050170899 | EI14: =ER14+EQ14 -> 0.2698207 | EJ14: =EK14-EI14 -> #VALUE! | EK14: =DV14 -> #VALUE! | EL14: =_xlfn.RRI(3,AK14,AN14) -> 0 | EM14: =_xlfn.RRI(3,BC14,BF14) -> 0.25914929 | EN14: {=_xll.BDP(B14,"AVG_DAILY_VALUE_TRADED_3M")/10^6} -> 4774.8613 | EQ14: =IFERROR(AVERAGE(DP14:DQ14)/H14,0) -> 0 | ER14: =_xlfn.RRI(2+$DT$2,$DT$2*(BC14)+(1-$DT$2)*(BD14),(BF14)) -> 0.2698207 | ES14: =ER14-EG14+EQ14 -> -0.050170899 | EU14: =_xlfn.RRI(2+$DT$2,($DT$2*BY14+(1-$DT$2)*BZ14),CF14) -> #VALUE! | EV14: =EJ14-EU14 -> #VALUE! | FF14: 0.25 | FG14: -0.25 | FH14: =FF14-FG14 -> 0.5 | FI14: =FT14/CF14-1 -> 0.36363636 | FJ14: =FU14/CF14-1 -> -0.18181818 | FK14: =FI14-FJ14 -> 0.54545455 | FL14: =FF14+FG14 -> 0 | FM14: =FJ14+FI14 -> 0.18181818 | FN14: =EK14+FF14/3+FI14/3 -> #VALUE! | FO14: =EK14+FG14/3+FJ14/3 -> #VALUE! | FP14: =EK14+FL14/3+FM14/3 -> #VALUE! | FQ14: =EK14 -> #VALUE! | FR14: =FP14-FQ14 -> #VALUE! | FS14: =FN14-FO14 -> #VALUE! | FT14: 30 | FU14: 18
B15: NVDA US Equity | D15: NVDA | F15: 46119 | H15: {=_xll.BQL($B15, "px_last", "dates=" & _xll.BQL.DATE($D$2))} -> #N/A Connection | I15: 23949.959 | J15: -43210 | K15: 10270 | M15: =K15+J15 -> -32940 | N15: =I15*H15+M15+L15 -> #VALUE! | O15: 26974 | P15: 60922 | Q15: 130497 | R15: 215938 | S15: 354704.9 | T15: 400449.92 | U15: 409606.62 | V15: 430668.61 | W15: 452513.22 | AG15: =X15*O15 -> 0 | AH15: =Y15*P15 -> 0 | AI15: =Z15*Q15 -> 0 | AJ15: =AA15*R15 -> 0 | AK15: =AB15*S15 -> 0 | AL15: =AC15*T15 -> 0 | AM15: =AD15*U15 -> 0 | AN15: =AE15*V15 -> 0 | AO15: =AF15*W15 -> 0 | AP15: 0.33370562 | AQ15: 1.2955894 | AR15: 2.9940735 | AS15: 4.81 | AT15: 8.4278766 | AU15: 9.782115 | AV15: 10.22572 | AW15: 10.981352 | AX15: 11.757462 | AY15: =AP15 -> 0.33370562 | AZ15: =AQ15 -> 1.2955894 | BA15: =AR15 -> 2.9940735 | BB15: =AS15 -> 4.81 | BC15: =AT15 -> 8.4278766 | BD15: =AU15 -> 9.782115 | BE15: =AV15 -> 10.22572 | BF15: =AW15 -> 10.981352 | BG15: =AX15 -> 11.757462 | BH15: =$N15/Q15 -> #VALUE! | BI15: =$N15/R15 -> #VALUE! | BJ15: =$N15/S15 -> #VALUE! | BK15: =$N15/T15 -> #VALUE! | BL15: =$N15/U15 -> #VALUE! | BM15: =$N15/V15 -> #VALUE! | BN15: =$N15/W15 -> #VALUE! | BO15: n/a | BP15: n/a | BQ15: =$N15/AM15 -> #VALUE! | BR15: =$N15/AN15 -> #VALUE! | BS15: =$N15/AO15 -> #VALUE! | BT15: =$H15/AT15 -> #VALUE! | BU15: =$H15/AU15 -> #VALUE! | BV15: =$H15/AV15 -> #VALUE! | BW15: =$H15/AW15 -> #VALUE! | BX15: =$H15/AX15 -> #VALUE! | BY15: =$H15/BC15 -> #VALUE! | BZ15: =$H15/BD15 -> #VALUE! | CA15: =$H15/BE15 -> #VALUE! | CB15: =$H15/BF15 -> #VALUE! | CC15: =$H15/BG15 -> #VALUE! | CD15: 24 | CE15: 24 | CF15: 24 | CG15: 24 | CH15: 24 | CN15: =CD15*BD15+CS15 -> 234.77076 | CO15: =CE15*BE15+CT15 -> 245.41728 | CP15: =CF15*BF15+CU15 -> 263.55246 | CQ15: =CG15*BG15+CV15 -> 282.17909 | DC15: 22739.184 | DD15: 21525.915 | DE15: 20428.256 | DF15: 19409.325 | DG15: 18466.078 | DH15: -32940 | DI15: -32940 | DJ15: -32940 | DK15: -32940 | DL15: -32940 | DO15: 0.044 | DP15: 0.0484 | DQ15: 0.05324 | DR15: 0.058564 | DS15: 0.0644204 | DT15: =_xlfn.RRI(DT$2,$H15,CN15+$DO15*$DT$2) -> #VALUE! | DU15: =_xlfn.RRI(DU$2,$H15,CO15+$DO15*$DT$2+SUM($DP15:DP15)) -> #VALUE! | DV15: =_xlfn.RRI(DV$2,$H15,CP15+$DO15*$DT$2+SUM($DP15:DQ15)) -> #VALUE! | DW15: =_xlfn.RRI(DW$2,$H15,CQ15+$DO15*$DT$2+SUM($DP15:DR15)) -> #VALUE! | DX15: =SUM(CN15,$DO15:DO15)/$H15 -> #VALUE! | DY15: =SUM(CO15,$DO15:DP15)/$H15 -> #VALUE! | DZ15: =SUM(CP15,$DO15:DQ15)/$H15 -> #VALUE! | EA15: =SUM(CQ15,$DO15:DR15)/$H15 -> #VALUE! | EB15: {=_xll.BDP(""&$B15&"","CHG_PCT_1M")/100} -> -0.03094794 | EC15: {=_xll.BDP(""&$B15&"","CHG_PCT_3M")/100} -> 0.1727589 | ED15: {=_xll.BDP(""&$B15&"","CHG_PCT_6M")/100} -> 0.1239019 | EE15: =_xlfn.RRI(2+$DT$2,$DT$2*S15+(1-$DT$2)*T15,V15) -> 0.055709232 | EF15: =EG15-EE15 -> -0.030511792 | EG15: =_xlfn.RRI(2+$DT$2,$DT$2*(BC15*DC15)+(1-$DT$2)*(BD15*DD15),(BF15*DF15)) -> 0.02519744 | EH15: =EI15-EG15 -> 0.054481494 | EI15: =ER15+EQ15 -> 0.079678934 | EJ15: =EK15-EI15 -> #VALUE! | EK15: =DV15 -> #VALUE! | EL15: =_xlfn.RRI(3,AK15,AN15) -> 0 | EM15: =_xlfn.RRI(3,BC15,BF15) -> 0.092226106 | EN15: {=_xll.BDP(B15,"AVG_DAILY_VALUE_TRADED_3M")/10^6} -> 33095.848 | EQ15: =IFERROR(AVERAGE(DP15:DQ15)/H15,0) -> 0 | ER15: =_xlfn.RRI(2+$DT$2,$DT$2*(BC15)+(1-$DT$2)*(BD15),(BF15)) -> 0.079678934 | ES15: =ER15-EG15+EQ15 -> 0.054481494 | EU15: =_xlfn.RRI(2+$DT$2,($DT$2*BY15+(1-$DT$2)*BZ15),CF15) -> #VALUE! | EV15: =EJ15-EU15 -> #VALUE! | FF15: 0.25 | FG15: -0.25 | FH15: =FF15-FG15 -> 0.5 | FI15: =FT15/CF15-1 -> 0.25 | FJ15: =FU15/CF15-1 -> -0.25 | FK15: =FI15-FJ15 -> 0.5 | FL15: =FF15+FG15 -> 0 | FM15: =FJ15+FI15 -> 0 | FN15: =EK15+FF15/3+FI15/3 -> #VALUE! | FO15: =EK15+FG15/3+FJ15/3 -> #VALUE! | FP15: =EK15+FL15/3+FM15/3 -> #VALUE! | FQ15: =EK15 -> #VALUE! | FR15: =FP15-FQ15 -> #VALUE! | FS15: =FN15-FO15 -> #VALUE! | FT15: 30 | FU15: 18
D17: Info Svcs
B18: CSGP US EQUITY | D18: CSGP | E18: 1 | F18: 45689 | H18: {=_xll.BQL($B18, "px_last", "dates=" & _xll.BQL.DATE($D$2))} -> #N/A Connection | I18: 419.6 | J18: -1633 | K18: =992.5+800 -> 1792.5 | M18: =K18+J18 -> 159.5 | N18: =I18*H18+M18+L18 -> #VALUE! | O18: 2182.399 | P18: 2455 | Q18: 2736.2 | R18: 3247 | S18: 3843.75 | T18: 4442.3 | U18: 4976.173 | V18: 5551.398 | W18: 6162.0518 | X18: 0.8 | Y18: 0.8 | Z18: 0.8 | AA18: 0.8 | AB18: 0.8 | AC18: 0.8 | AD18: 0.8 | AE18: 0.8 | AF18: 0.8 | AG18: =X18*O18 -> 1745.9192 | AH18: =Y18*P18 -> 1964 | AI18: =Z18*Q18 -> 2188.96 | AJ18: =AA18*R18 -> 2597.6 | AK18: =AB18*S18 -> 3075 | AL18: =AC18*T18 -> 3553.84 | AM18: =AD18*U18 -> 3980.9384 | AN18: =AE18*V18 -> 4441.1184 | AO18: =AF18*W18 -> 4929.6415 | AP18: 1.132733 | AQ18: 1.0695484 | AR18: 0.56728908 | AS18: 0.69200325 | AT18: 1.1941425 | AU18: 1.8720325 | AV18: 2.6769596 | AW18: 3.6100842 | AX18: 4.6848994 | AY18: =AP18 -> 1.132733 | AZ18: =AQ18 -> 1.0695484 | BA18: =AR18 -> 0.56728908 | BB18: =AS18 -> 0.69200325 | BC18: =AT18 -> 1.1941425 | BD18: =AU18 -> 1.8720325 | BE18: =AV18 -> 2.6769596 | BF18: =AW18 -> 3.6100842 | BG18: =AX18 -> 4.6848994 | BH18: =$N18/Q18 -> #VALUE! | BI18: =$N18/R18 -> #VALUE! | BJ18: =$N18/S18 -> #VALUE! | BK18: =$N18/T18 -> #VALUE! | BL18: =$N18/U18 -> #VALUE! | BM18: =$N18/V18 -> #VALUE! | BN18: =$N18/W18 -> #VALUE! | BO18: =$N18/AK18 -> #VALUE! | BP18: =$N18/AL18 -> #VALUE! | BQ18: =$N18/AM18 -> #VALUE! | BR18: =$N18/AN18 -> #VALUE! | BS18: =$N18/AO18 -> #VALUE! | BT18: =$H18/AT18 -> #VALUE! | BU18: =$H18/AU18 -> #VALUE! | BV18: =$H18/AV18 -> #VALUE! | BW18: =$H18/AW18 -> #VALUE! | BX18: =$H18/AX18 -> #VALUE! | BY18: =$H18/BC18 -> #VALUE! | BZ18: =$H18/BD18 -> #VALUE! | CA18: =$H18/BE18 -> #VALUE! | CB18: =$H18/BF18 -> #VALUE! | CC18: =$H18/BG18 -> #VALUE! | CD18: 22 | CE18: 22 | CF18: 22 | CG18: 22 | CH18: 22 | CN18: =CD18*BD18 -> 41.184715 | CO18: =CE18*BE18 -> 58.893111 | CP18: =CF18*BF18 -> 79.421852 | CQ18: =CG18*BG18 -> 103.06779 | DC18: 414.18387 | DD18: 401.21459 | DE18: 388.58912 | DF18: 377.61046 | DG18: 368.06379 | DO18: 0 | DP18: 0 | DQ18: 0 | DR18: 0 | DS18: 0 | DT18: =_xlfn.RRI(DT$2,$H18,CN18+$DO18*$DT$2) -> #VALUE! | DU18: =_xlfn.RRI(DU$2,$H18,CO18+$DO18*$DT$2+SUM($DP18:DP18)) -> #VALUE! | DV18: =_xlfn.RRI(DV$2,$H18,CP18+$DO18*$DT$2+SUM($DP18:DQ18)) -> #VALUE! | DW18: =_xlfn.RRI(DW$2,$H18,CQ18+$DO18*$DT$2+SUM($DP18:DR18)) -> #VALUE! | DX18: =SUM(CN18,$DO18:DO18)/$H18 -> #VALUE! | DY18: =SUM(CO18,$DO18:DP18)/$H18 -> #VALUE! | DZ18: =SUM(CP18,$DO18:DQ18)/$H18 -> #VALUE! | EA18: =SUM(CQ18,$DO18:DR18)/$H18 -> #VALUE! | EB18: {=_xll.BDP(""&$B18&"","CHG_PCT_1M")/100} -> 0.03021054 | EC18: {=_xll.BDP(""&$B18&"","CHG_PCT_3M")/100} -> -0.302191 | ED18: {=_xll.BDP(""&$B18&"","CHG_PCT_6M")/100} -> -0.4910297 | EE18: =_xlfn.RRI(2+$DT$2,$DT$2*S18+(1-$DT$2)*T18,V18) -> 0.12490086 | EF18: =EG18-EE18 -> 0.24632538 | EG18: =_xlfn.RRI(2+$DT$2,$DT$2*(BC18*DC18)+(1-$DT$2)*(BD18*DD18),(BF18*DF18)) -> 0.37122624 | EH18: =EI18-EG18 -> 0.040772778 | EI18: =ER18+EQ18 -> 0.41199902 | EJ18: =EK18-EI18 -> #VALUE! | EK18: =DV18 -> #VALUE! | EL18: =_xlfn.RRI(3,AK18,AN18) -> 0.1303573 | EM18: =_xlfn.RRI(3,BC18,BF18) -> 0.44595148 | EN18: {=_xll.BDP(B18,"AVG_DAILY_VALUE_TRADED_3M")/10^6} -> 262.39074 | EQ18: =IFERROR(AVERAGE(DP18:DQ18)/H18,0) -> 0 | ER18: =_xlfn.RRI(2+$DT$2,$DT$2*(BC18)+(1-$DT$2)*(BD18),(BF18)) -> 0.41199902 | ES18: =ER18-EG18+EQ18 -> 0.040772778 | EU18: =_xlfn.RRI(2+$DT$2,($DT$2*BY18+(1-$DT$2)*BZ18),CF18) -> #VALUE! | EV18: =EJ18-EU18 -> #VALUE! | FF18: 0.05 | FG18: -0.25 | FH18: =FF18-FG18 -> 0.3 | FI18: =FT18/CF18-1 -> 0.36363636 | FJ18: =FU18/CF18-1 -> -0.18181818 | FK18: =FI18-FJ18 -> 0.54545455 | FL18: =FF18+FG18 -> -0.2 | FM18: =FJ18+FI18 -> 0.18181818 | FN18: =EK18+FF18/3+FI18/3 -> #VALUE! | FO18: =EK18+FG18/3+FJ18/3 -> #VALUE! | FP18: =EK18+FL18/3+FM18/3 -> #VALUE! | FQ18: =EK18 -> #VALUE! | FR18: =FP18-FQ18 -> #VALUE! | FS18: =FN18-FO18 -> #VALUE! | FT18: 30 | FU18: 18
B19: TRU US EQUITY | D19: TRU | E19: 1 | F19: 45810 | H19: {=_xll.BQL($B19, "px_last", "dates=" & _xll.BQL.DATE($D$2))} -> #N/A Connection | I19: 197.2 | J19: -853.6 | K19: 5103.8 | L19: 106.7 | M19: =K19+J19 -> 4250.2 | N19: =I19*H19+M19+L19 -> #VALUE! | O19: 3710 | P19: 3831.4 | Q19: 4183.8 | R19: 4576.2 | S19: 5129.4412 | T19: 5454.1426 | U19: 5789.8404 | V19: 6148.0729 | W19: 6528.9595 | X19: 0.6 | Y19: 0.6 | Z19: 0.6 | AA19: 0.6 | AB19: 0.6 | AC19: 0.6 | AD19: 0.6 | AE19: 0.6 | AF19: 0.6 | AG19: =X19*O19 -> 2226 | AH19: =Y19*P19 -> 2298.84 | AI19: =Z19*Q19 -> 2510.28 | AJ19: =AA19*R19 -> 2745.72 | AK19: =AB19*S19 -> 3077.6647 | AL19: =AC19*T19 -> 3272.4856 | AM19: =AD19*U19 -> 3473.9042 | AN19: =AE19*V19 -> 3688.8438 | AO19: =AF19*W19 -> 3917.3757 | AP19: 3.2912726 | AQ19: 2.9783798 | AR19: 3.4392731 | AS19: 3.7571823 | AT19: 4.2698664 | AU19: 4.9567662 | AV19: 5.7838143 | AW19: 6.7404567 | AX19: 7.8511706 | AY19: =AP19 -> 3.2912726 | AZ19: =AQ19 -> 2.9783798 | BA19: =AR19 -> 3.4392731 | BB19: =AS19 -> 3.7571823 | BC19: =AT19 -> 4.2698664 | BD19: =AU19 -> 4.9567662 | BE19: =AV19 -> 5.7838143 | BF19: =AW19 -> 6.7404567 | BG19: =AX19 -> 7.8511706 | BH19: =$N19/Q19 -> #VALUE! | BI19: =$N19/R19 -> #VALUE! | BJ19: =$N19/S19 -> #VALUE! | BK19: =$N19/T19 -> #VALUE! | BL19: =$N19/U19 -> #VALUE! | BM19: =$N19/V19 -> #VALUE! | BN19: =$N19/W19 -> #VALUE! | BO19: =$N19/AK19 -> #VALUE! | BP19: =$N19/AL19 -> #VALUE! | BQ19: =$N19/AM19 -> #VALUE! | BR19: =$N19/AN19 -> #VALUE! | BS19: =$N19/AO19 -> #VALUE! | BT19: =$H19/AT19 -> #VALUE! | BU19: =$H19/AU19 -> #VALUE! | BV19: =$H19/AV19 -> #VALUE! | BW19: =$H19/AW19 -> #VALUE! | BX19: =$H19/AX19 -> #VALUE! | BY19: =$H19/BC19 -> #VALUE! | BZ19: =$H19/BD19 -> #VALUE! | CA19: =$H19/BE19 -> #VALUE! | CB19: =$H19/BF19 -> #VALUE! | CC19: =$H19/BG19 -> #VALUE! | CD19: 20 | CE19: 20 | CF19: 20 | CG19: 20 | CH19: 20 | CI19: 103.9279 | CJ19: 130.01874 | CK19: 162.57321 | CL19: 192.09422 | CN19: =CD19*BD19 -> 99.135323 | CO19: =CE19*BE19 -> 115.67629 | CP19: =CF19*BF19 -> 134.80913 | CQ19: =CG19*BG19 -> 157.02341 | DC19: 190.1472 | DD19: 181.44159 | DE19: 172.73599 | DF19: 164.03039 | DG19: 155.32478 | DO19: 0.52590835 | DP19: 0.56767579 | DQ19: 0.61417426 | DR19: 0.66617351 | DS19: 0.72461637 | DT19: =_xlfn.RRI(DT$2,$H19,CN19+$DO19*$DT$2) -> #VALUE! | DU19: =_xlfn.RRI(DU$2,$H19,CO19+$DO19*$DT$2+SUM($DP19:DP19)) -> #VALUE! | DV19: =_xlfn.RRI(DV$2,$H19,CP19+$DO19*$DT$2+SUM($DP19:DQ19)) -> #VALUE! | DW19: =_xlfn.RRI(DW$2,$H19,CQ19+$DO19*$DT$2+SUM($DP19:DR19)) -> #VALUE! | DX19: =SUM(CN19,$DO19:DO19)/$H19 -> #VALUE! | DY19: =SUM(CO19,$DO19:DP19)/$H19 -> #VALUE! | DZ19: =SUM(CP19,$DO19:DQ19)/$H19 -> #VALUE! | EA19: =SUM(CQ19,$DO19:DR19)/$H19 -> #VALUE! | EB19: {=_xll.BDP(""&$B19&"","CHG_PCT_1M")/100} -> -0.02361111 | EC19: {=_xll.BDP(""&$B19&"","CHG_PCT_3M")/100} -> -0.09149648 | ED19: {=_xll.BDP(""&$B19&"","CHG_PCT_6M")/100} -> -0.1427875 | EE19: =_xlfn.RRI(2+$DT$2,$DT$2*S19+(1-$DT$2)*T19,V19) -> 0.061864924 | EF19: =EG19-EE19 -> 0.046110901 | EG19: =_xlfn.RRI(2+$DT$2,$DT$2*(BC19*DC19)+(1-$DT$2)*(BD19*DD19),(BF19*DF19)) -> 0.10797582 | EH19: =EI19-EG19 -> 0.055746156 | EI19: =ER19+EQ19 -> 0.16372198 | EJ19: =EK19-EI19 -> #VALUE! | EK19: =DV19 -> #VALUE! | EL19: =_xlfn.RRI(3,AK19,AN19) -> 0.062240815 | EM19: =_xlfn.RRI(3,BC19,BF19) -> 0.1643718 | EN19: {=_xll.BDP(B19,"AVG_DAILY_VALUE_TRADED_3M")/10^6} -> 160.06408 | EQ19: =IFERROR(AVERAGE(DP19:DQ19)/H19,0) -> 0 | ER19: =_xlfn.RRI(2+$DT$2,$DT$2*(BC19)+(1-$DT$2)*(BD19),(BF19)) -> 0.16372198 | ES19: =ER19-EG19+EQ19 -> 0.055746156 | EU19: =_xlfn.RRI(2+$DT$2,($DT$2*BY19+(1-$DT$2)*BZ19),CF19) -> #VALUE! | EV19: =EJ19-EU19 -> #VALUE! | FF19: 0.2 | FG19: -0.2 | FH19: =FF19-FG19 -> 0.4 | FI19: =FT19/CF19-1 -> 0.3 | FJ19: =FU19/CF19-1 -> -0.3 | FK19: =FI19-FJ19 -> 0.6 | FL19: =FF19+FG19 -> 0 | FM19: =FJ19+FI19 -> 0 | FN19: =EK19+FF19/3+FI19/3 -> #VALUE! | FO19: =EK19+FG19/3+FJ19/3 -> #VALUE! | FP19: =EK19+FL19/3+FM19/3 -> #VALUE! | FQ19: =EK19 -> #VALUE! | FR19: =FP19-FQ19 -> #VALUE! | FS19: =FN19-FO19 -> #VALUE! | FT19: 26 | FU19: 14
B20: EFX US EQUITY | D20: EFX | E20: 1 | F20: 45810 | H20: {=_xll.BQL($B20, "px_last", "dates=" & _xll.BQL.DATE($D$2))} -> #N/A Connection | I20: 124.1 | J20: -180.8 | K20: 5093.3 | L20: 17.5 | M20: =K20+J20 -> 4912.5 | N20: =I20*H20+M20+L20 -> #VALUE! | O20: 5122.2 | P20: 5265.2 | Q20: 5681.1 | R20: 6074.5 | S20: 6645.2564 | T20: 7203.17 | U20: 7801.8195 | V20: 8448.8615 | W20: 9146.5592 | X20: 0.6 | Y20: 0.6 | Z20: 0.6 | AA20: 0.6 | AB20: 0.6 | AC20: 0.6 | AD20: 0.6 | AE20: 0.6 | AF20: 0.6 | AG20: =X20*O20 -> 3073.32 | AH20: =Y20*P20 -> 3159.12 | AI20: =Z20*Q20 -> 3408.66 | AJ20: =AA20*R20 -> 3644.7 | AK20: =AB20*S20 -> 3987.1538 | AL20: =AC20*T20 -> 4321.902 | AM20: =AD20*U20 -> 4681.0917 | AN20: =AE20*V20 -> 5069.3169 | AO20: =AF20*W20 -> 5487.9355 | AP20: 7.5579886 | AQ20: 6.7110573 | AR20: 7.2946357 | AS20: 7.6526994 | AT20: 8.2610488 | AU20: 9.9529019 | AV20: 11.994757 | AW20: 14.410321 | AX20: 17.275352 | AY20: =AP20 -> 7.5579886 | AZ20: =AQ20 -> 6.7110573 | BA20: =AR20 -> 7.2946357 | BB20: =AS20 -> 7.6526994 | BC20: =AT20 -> 8.2610488 | BD20: =AU20 -> 9.9529019 | BE20: =AV20 -> 11.994757 | BF20: =AW20 -> 14.410321 | BG20: =AX20 -> 17.275352 | BH20: =$N20/Q20 -> #VALUE! | BI20: =$N20/R20 -> #VALUE! | BJ20: =$N20/S20 -> #VALUE! | BK20: =$N20/T20 -> #VALUE! | BL20: =$N20/U20 -> #VALUE! | BM20: =$N20/V20 -> #VALUE! | BN20: =$N20/W20 -> #VALUE! | BO20: =$N20/AK20 -> #VALUE! | BP20: =$N20/AL20 -> #VALUE! | BQ20: =$N20/AM20 -> #VALUE! | BR20: =$N20/AN20 -> #VALUE! | BS20: =$N20/AO20 -> #VALUE! | BT20: =$H20/AT20 -> #VALUE! | BU20: =$H20/AU20 -> #VALUE! | BV20: =$H20/AV20 -> #VALUE! | BW20: =$H20/AW20 -> #VALUE! | BX20: =$H20/AX20 -> #VALUE! | BY20: =$H20/BC20 -> #VALUE! | BZ20: =$H20/BD20 -> #VALUE! | CA20: =$H20/BE20 -> #VALUE! | CB20: =$H20/BF20 -> #VALUE! | CC20: =$H20/BG20 -> #VALUE! | CD20: 20 | CE20: 20 | CF20: 20 | CG20: 20 | CH20: 20 | CN20: =CD20*BD20 -> 199.05804 | CO20: =CE20*BE20 -> 239.89515 | CP20: =CF20*BF20 -> 288.20642 | CQ20: =CG20*BG20 -> 345.50705 | DC20: 121.30785 | DD20: 115.56797 | DE20: 109.43918 | DF20: 103.32806 | DG20: 97.333894 | DO20: 1.9766569 | DP20: 2.1370759 | DQ20: 2.3244586 | DR20: 2.5357917 | DS20: 2.7727135 | DT20: =_xlfn.RRI(DT$2,$H20,CN20+$DO20*$DT$2) -> #VALUE! | DU20: =_xlfn.RRI(DU$2,$H20,CO20+$DO20*$DT$2+SUM($DP20:DP20)) -> #VALUE! | DV20: =_xlfn.RRI(DV$2,$H20,CP20+$DO20*$DT$2+SUM($DP20:DQ20)) -> #VALUE! | DW20: =_xlfn.RRI(DW$2,$H20,CQ20+$DO20*$DT$2+SUM($DP20:DR20)) -> #VALUE! | DX20: =SUM(CN20,$DO20:DO20)/$H20 -> #VALUE! | DY20: =SUM(CO20,$DO20:DP20)/$H20 -> #VALUE! | DZ20: =SUM(CP20,$DO20:DQ20)/$H20 -> #VALUE! | EA20: =SUM(CQ20,$DO20:DR20)/$H20 -> #VALUE! | EB20: {=_xll.BDP(""&$B20&"","CHG_PCT_1M")/100} -> -0.03531822 | EC20: {=_xll.BDP(""&$B20&"","CHG_PCT_3M")/100} -> -0.1838522 | ED20: {=_xll.BDP(""&$B20&"","CHG_PCT_6M")/100} -> -0.1933996 | EE20: =_xlfn.RRI(2+$DT$2,$DT$2*S20+(1-$DT$2)*T20,V20) -> 0.082885985 | EF20: =EG20-EE20 -> 0.056013419 | EG20: =_xlfn.RRI(2+$DT$2,$DT$2*(BC20*DC20)+(1-$DT$2)*(BD20*DD20),(BF20*DF20)) -> 0.1388994 | EH20: =EI20-EG20 -> 0.062679137 | EI20: =ER20+EQ20 -> 0.20157854 | EJ20: =EK20-EI20 -> #VALUE! | EK20: =DV20 -> #VALUE! | EL20: =_xlfn.RRI(3,AK20,AN20) -> 0.083333443 | EM20: =_xlfn.RRI(3,BC20,BF20) -> 0.20377731 | EN20: {=_xll.BDP(B20,"AVG_DAILY_VALUE_TRADED_3M")/10^6} -> 294.55366 | EQ20: =IFERROR(AVERAGE(DP20:DQ20)/H20,0) -> 0 | ER20: =_xlfn.RRI(2+$DT$2,$DT$2*(BC20)+(1-$DT$2)*(BD20),(BF20)) -> 0.20157854 | ES20: =ER20-EG20+EQ20 -> 0.062679137 | EU20: =_xlfn.RRI(2+$DT$2,($DT$2*BY20+(1-$DT$2)*BZ20),CF20) -> #VALUE! | EV20: =EJ20-EU20 -> #VALUE! | FF20: 0.2 | FG20: -0.2 | FH20: =FF20-FG20 -> 0.4 | FI20: =FT20/CF20-1 -> 0.3 | FJ20: =FU20/CF20-1 -> -0.3 | FK20: =FI20-FJ20 -> 0.6 | FL20: =FF20+FG20 -> 0 | FM20: =FJ20+FI20 -> 0 | FN20: =EK20+FF20/3+FI20/3 -> #VALUE! | FO20: =EK20+FG20/3+FJ20/3 -> #VALUE! | FP20: =EK20+FL20/3+FM20/3 -> #VALUE! | FQ20: =EK20 -> #VALUE! | FR20: =FP20-FQ20 -> #VALUE! | FS20: =FN20-FO20 -> #VALUE! | FT20: 26 | FU20: 14
B21: LSEG LN EQUITY | D21: LSEG | E21: 1 | F21: 45994 | H21: {=_xll.BQL($B21, "px_last", "dates=" & _xll.BQL.DATE($D$2))/100} -> #VALUE! | I21: 527 | J21: -3949 | K21: 11804 | M21: =K21+J21 -> 7855 | N21: =I21*H21+M21+L21 -> #VALUE! | O21: 7428 | P21: 8009 | Q21: 8494 | R21: 8986 | S21: 9659.1735 | T21: 10357.271 | U21: 11113.277 | V21: 11932.295 | W21: 12819.889 | X21: 0.87 | Y21: 0.87 | Z21: 0.87 | AA21: 0.87 | AB21: 0.87 | AC21: 0.87 | AD21: 0.87 | AE21: 0.87 | AF21: 0.87 | AG21: =X21*O21 -> 6462.36 | AH21: =Y21*P21 -> 6967.83 | AI21: =Z21*Q21 -> 7389.78 | AJ21: =AA21*R21 -> 7817.82 | AK21: =AB21*S21 -> 8403.4809 | AL21: =AC21*T21 -> 9010.8255 | AM21: =AD21*U21 -> 9668.5511 | AN21: =AE21*V21 -> 10381.096 | AO21: =AF21*W21 -> 11153.304 | AP21: 3.178 | AQ21: 3.239 | AR21: 3.635 | AS21: 4.206 | AT21: 4.6016562 | AU21: 5.1498971 | AV21: 5.9086919 | AW21: 6.7569185 | AX21: 7.707095 | AY21: =AP21 -> 3.178 | AZ21: =AQ21 -> 3.239 | BA21: =AR21 -> 3.635 | BB21: =AS21 -> 4.206 | BC21: =AT21 -> 4.6016562 | BD21: =AU21 -> 5.1498971 | BE21: =AV21 -> 5.9086919 | BF21: =AW21 -> 6.7569185 | BG21: =AX21 -> 7.707095 | BH21: =$N21/Q21 -> #VALUE! | BI21: =$N21/R21 -> #VALUE! | BJ21: =$N21/S21 -> #VALUE! | BK21: =$N21/T21 -> #VALUE! | BL21: =$N21/U21 -> #VALUE! | BM21: =$N21/V21 -> #VALUE! | BN21: =$N21/W21 -> #VALUE! | BO21: =$N21/AK21 -> #VALUE! | BP21: =$N21/AL21 -> #VALUE! | BQ21: =$N21/AM21 -> #VALUE! | BR21: =$N21/AN21 -> #VALUE! | BS21: =$N21/AO21 -> #VALUE! | BT21: =$H21/AT21 -> #VALUE! | BU21: =$H21/AU21 -> #VALUE! | BV21: =$H21/AV21 -> #VALUE! | BW21: =$H21/AW21 -> #VALUE! | BX21: =$H21/AX21 -> #VALUE! | BY21: =$H21/BC21 -> #VALUE! | BZ21: =$H21/BD21 -> #VALUE! | CA21: =$H21/BE21 -> #VALUE! | CB21: =$H21/BF21 -> #VALUE! | CC21: =$H21/BG21 -> #VALUE! | CD21: 22 | CE21: 22 | CF21: 22 | CG21: 22 | CH21: 24 | CN21: =CD21*BD21 -> 113.29774 | CO21: =CE21*BE21 -> 129.99122 | CP21: =CF21*BF21 -> 148.65221 | CQ21: =CG21*BG21 -> 169.55609 | DC21: 509.24246 | DD21: 477.56505 | DE21: 452.12572 | DF21: 429.72617 | DG21: 408.66851 | DO21: 1.6763268 | DP21: 1.9279933 | DQ21: 2.2094085 | DR21: 2.5236533 | DS21: 2.8745861 | DT21: =_xlfn.RRI(DT$2,$H21,CN21+$DO21*$DT$2) -> #VALUE! | DU21: =_xlfn.RRI(DU$2,$H21,CO21+$DO21*$DT$2+SUM($DP21:DP21)) -> #VALUE! | DV21: =_xlfn.RRI(DV$2,$H21,CP21+$DO21*$DT$2+SUM($DP21:DQ21)) -> #VALUE! | DW21: =_xlfn.RRI(DW$2,$H21,CQ21+$DO21*$DT$2+SUM($DP21:DR21)) -> #VALUE! | DX21: =SUM(CN21,$DO21:DO21)/$H21 -> #VALUE! | DY21: =SUM(CO21,$DO21:DP21)/$H21 -> #VALUE! | DZ21: =SUM(CP21,$DO21:DQ21)/$H21 -> #VALUE! | EA21: =SUM(CQ21,$DO21:DR21)/$H21 -> #VALUE! | EB21: {=_xll.BDP(""&$B21&"","CHG_PCT_1M")/100} -> 0.0219075 | EC21: {=_xll.BDP(""&$B21&"","CHG_PCT_3M")/100} -> 0.05050045 | ED21: {=_xll.BDP(""&$B21&"","CHG_PCT_6M")/100} -> 0.08658824 | EE21: =_xlfn.RRI(2+$DT$2,$DT$2*S21+(1-$DT$2)*T21,V21) -> 0.072858405 | EF21: =EG21-EE21 -> 0.0053826734 | EG21: =_xlfn.RRI(2+$DT$2,$DT$2*(BC21*DC21)+(1-$DT$2)*(BD21*DD21),(BF21*DF21)) -> 0.078241079 | EH21: =EI21-EG21 -> 0.060709843 | EI21: =ER21+EQ21 -> 0.13895092 | EJ21: =EK21-EI21 -> #VALUE! | EK21: =DV21 -> #VALUE! | EL21: =_xlfn.RRI(3,AK21,AN21) -> 0.072987509 | EM21: =_xlfn.RRI(3,BC21,BF21) -> 0.13661009 | EN21: {=_xll.BDP(B21,"AVG_DAILY_VALUE_TRADED_3M")/10^6} -> 10396.47 | EQ21: =IFERROR(AVERAGE(DP21:DQ21)/H21,0) -> 0 | ER21: =_xlfn.RRI(2+$DT$2,$DT$2*(BC21)+(1-$DT$2)*(BD21),(BF21)) -> 0.13895092 | ES21: =ER21-EG21+EQ21 -> 0.060709843 | EU21: =_xlfn.RRI(2+$DT$2,($DT$2*BY21+(1-$DT$2)*BZ21),CF21) -> #VALUE! | EV21: =EJ21-EU21 -> #VALUE! | FF21: 0.15 | FG21: -0.15 | FH21: =FF21-FG21 -> 0.3 | FI21: =FT21/CF21-1 -> 0.18181818 | FJ21: =FU21/CF21-1 -> -0.22727273 | FK21: =FI21-FJ21 -> 0.40909091 | FL21: =FF21+FG21 -> 0 | FM21: =FJ21+FI21 -> -0.045454545 | FN21: =EK21+FF21/3+FI21/3 -> #VALUE! | FO21: =EK21+FG21/3+FJ21/3 -> #VALUE! | FP21: =EK21+FL21/3+FM21/3 -> #VALUE! | FQ21: =EK21 -> #VALUE! | FR21: =FP21-FQ21 -> #VALUE! | FS21: =FN21-FO21 -> #VALUE! | FT21: 26 | FU21: 17 | FV21: Set Mendo EPS = adj EPS (SBC <2% revs)
B22: SPGI US EQUITY | D22: SPGI | E22: 1 | F22: 46057 | H22: {=_xll.BQL($B22, "px_last", "dates=" & _xll.BQL.DATE($D$2))} -> #N/A Connection | I22: 304.1025 | J22: -1847 | K22: 11388 | M22: =K22+J22 -> 9541 | N22: =I22*H22+M22+L22 -> #VALUE! | O22: 11843 | P22: 12497 | Q22: 14208 | R22: 15336 | S22: 16719.285 | T22: 18035.782 | U22: 19461.908 | V22: 21007.252 | W22: 22682.276 | X22: 0.7 | Y22: 0.7 | Z22: 0.7 | AA22: 0.7 | AB22: 0.7 | AC22: 0.7 | AD22: 0.7 | AE22: 0.7 | AF22: 0.7 | AG22: =X22*O22 -> 8290.1 | AH22: =Y22*P22 -> 8747.9 | AI22: =Z22*Q22 -> 9945.6 | AJ22: =AA22*R22 -> 10735.2 | AK22: =AB22*S22 -> 11703.5 | AL22: =AC22*T22 -> 12625.048 | AM22: =AD22*U22 -> 13623.336 | AN22: =AE22*V22 -> 14705.077 | AO22: =AF22*W22 -> 15877.593 | AP22: 11.77394 | AQ22: 12.599561 | AR22: 15.703751 | AS22: 18.021314 | AT22: 20.193227 | AU22: 22.779021 | AV22: 25.648626 | AW22: 28.872377 | AX22: 32.492214 | AY22: =AP22 -> 11.77394 | AZ22: =AQ22 -> 12.599561 | BA22: =AR22 -> 15.703751 | BB22: =AS22 -> 18.021314 | BC22: =AT22 -> 20.193227 | BD22: =AU22 -> 22.779021 | BE22: =AV22 -> 25.648626 | BF22: =AW22 -> 28.872377 | BG22: =AX22 -> 32.492214 | BH22: =$N22/Q22 -> #VALUE! | BI22: =$N22/R22 -> #VALUE! | BJ22: =$N22/S22 -> #VALUE! | BK22: =$N22/T22 -> #VALUE! | BL22: =$N22/U22 -> #VALUE! | BM22: =$N22/V22 -> #VALUE! | BN22: =$N22/W22 -> #VALUE! | BO22: =$N22/AK22*0.9 -> #VALUE! | BP22: =$N22/AL22*0.9 -> #VALUE! | BQ22: =$N22/AM22*0.9 -> #VALUE! | BR22: =$N22/AN22*0.9 -> #VALUE! | BS22: =$N22/AO22*0.9 -> #VALUE! | BT22: =$H22/AT22 -> #VALUE! | BU22: =$H22/AU22 -> #VALUE! | BV22: =$H22/AV22 -> #VALUE! | BW22: =$H22/AW22 -> #VALUE! | BX22: =$H22/AX22 -> #VALUE! | BY22: =$H22/BC22 -> #VALUE! | BZ22: =$H22/BD22 -> #VALUE! | CA22: =$H22/BE22 -> #VALUE! | CB22: =$H22/BF22 -> #VALUE! | CC22: =$H22/BG22 -> #VALUE! | CD22: 22 | CE22: 22 | CF22: 22 | CG22: 22 | CH22: 24.5 | CN22: =CD22*BD22 -> 501.13845 | CO22: =CE22*BE22 -> 564.26976 | CP22: =CF22*BF22 -> 635.19228 | CQ22: =CG22*BG22 -> 714.82871 | DC22: 293.77509 | DD22: 283.34014 | DE22: 273.34107 | DF22: 263.77859 | DG22: 254.64132 | DO22: 4.0704 | DP22: 4.314624 | DQ22: 4.5735014 | DR22: 4.8479115 | DS22: 5.1387862 | DT22: =_xlfn.RRI(DT$2,$H22,CN22+$DO22*$DT$2) -> #VALUE! | DU22: =_xlfn.RRI(DU$2,$H22,CO22+$DO22*$DT$2+SUM($DP22:DP22)) -> #VALUE! | DV22: =_xlfn.RRI(DV$2,$H22,CP22+$DO22*$DT$2+SUM($DP22:DQ22)) -> #VALUE! | DW22: =_xlfn.RRI(DW$2,$H22,CQ22+$DO22*$DT$2+SUM($DP22:DR22)) -> #VALUE! | DX22: =SUM(CN22,$DO22:DO22)/$H22 -> #VALUE! | DY22: =SUM(CO22,$DO22:DP22)/$H22 -> #VALUE! | DZ22: =SUM(CP22,$DO22:DQ22)/$H22 -> #VALUE! | EA22: =SUM(CQ22,$DO22:DR22)/$H22 -> #VALUE! | EB22: {=_xll.BDP(""&$B22&"","CHG_PCT_1M")/100} -> 0.005355624 | EC22: {=_xll.BDP(""&$B22&"","CHG_PCT_3M")/100} -> -0.06629672 | ED22: {=_xll.BDP(""&$B22&"","CHG_PCT_6M")/100} -> -0.1416989 | EE22: =_xlfn.RRI(2+$DT$2,$DT$2*S22+(1-$DT$2)*T22,V22) -> 0.078829876 | EF22: =EG22-EE22 -> 0.007444219 | EG22: =_xlfn.RRI(2+$DT$2,$DT$2*(BC22*DC22)+(1-$DT$2)*(BD22*DD22),(BF22*DF22)) -> 0.086274095 | EH22: =EI22-EG22 -> 0.039252141 | EI22: =ER22+EQ22 -> 0.12552624 | EJ22: =EK22-EI22 -> #VALUE! | EK22: =DV22 -> #VALUE! | EL22: =_xlfn.RRI(3,AK22,AN22) -> 0.079072223 | EM22: =_xlfn.RRI(3,BC22,BF22) -> 0.12657196 | EN22: {=_xll.BDP(B22,"AVG_DAILY_VALUE_TRADED_3M")/10^6} -> 849.00768 | EQ22: =IFERROR(AVERAGE(DP22:DQ22)/H22,0) -> 0 | ER22: =_xlfn.RRI(2+$DT$2,$DT$2*(BC22)+(1-$DT$2)*(BD22),(BF22)) -> 0.12552624 | ES22: =ER22-EG22+EQ22 -> 0.039252141 | EU22: =_xlfn.RRI(2+$DT$2,($DT$2*BY22+(1-$DT$2)*BZ22),CF22) -> #VALUE! | EV22: =EJ22-EU22 -> #VALUE! | FF22: 0.15 | FG22: -0.15 | FH22: =FF22-FG22 -> 0.3 | FI22: =FT22/CF22-1 -> 0.18181818 | FJ22: =FU22/CF22-1 -> -0.22727273 | FK22: =FI22-FJ22 -> 0.40909091 | FL22: =FF22+FG22 -> 0 | FM22: =FJ22+FI22 -> -0.045454545 | FN22: =EK22+FF22/3+FI22/3 -> #VALUE! | FO22: =EK22+FG22/3+FJ22/3 -> #VALUE! | FP22: =EK22+FL22/3+FM22/3 -> #VALUE! | FQ22: =EK22 -> #VALUE! | FR22: =FP22-FQ22 -> #VALUE! | FS22: =FN22-FO22 -> #VALUE! | FT22: 26 | FU22: 17
